Workbook

Sheet Compile
B2: DATA RINGKASAN DUN (10 JUN 2026)
B4: Kod | C4: DUN | D4: Pengundi (DPI Dec 2025) | E4: Majoriti PRU15 | F4: Ranking PRU15 | G4: Peratus Pengundi Melayu | H4: Markah SLU
B5: N25 | C5: =INDEX('(2) Pengundi & % Melayu'!$C$5:$C$40,MATCH($B5,'(2) Pengundi & % Melayu'!$B$5:$B$40,0)) -> Paroi | D5: =INDEX('(2) Pengundi & % Melayu'!$D$5:$D$40,MATCH($B5,'(2) Pengundi & % Melayu'!$B$5:$B$40,0)) -> 64582 | E5: =INDEX('(1) Majoriti'!$I$4:$I$39,MATCH($B5,'(1) Majoriti'!$B$4:$B$39,0)) -> 5539 | F5: =INDEX('(1) Majoriti'!$J$4:$J$39,MATCH($B5,'(1) Majoriti'!$B$4:$B$39,0)) -> 1 | G5: =INDEX('(2) Pengundi & % Melayu'!$M$5:$M$40,MATCH($B5,'(2) Pengundi & % Melayu'!$B$5:$B$40,0)) -> 0.79901521 | H5: NA
B6: N31 | C6: =INDEX('(2) Pengundi & % Melayu'!$C$5:$C$40,MATCH($B6,'(2) Pengundi & % Melayu'!$B$5:$B$40,0)) -> Bagan Pinang | D6: =INDEX('(2) Pengundi & % Melayu'!$D$5:$D$40,MATCH($B6,'(2) Pengundi & % Melayu'!$B$5:$B$40,0)) -> 27926 | E6: =INDEX('(1) Majoriti'!$I$4:$I$39,MATCH($B6,'(1) Majoriti'!$B$4:$B$39,0)) -> 3426 | F6: =INDEX('(1) Majoriti'!$J$4:$J$39,MATCH($B6,'(1) Majoriti'!$B$4:$B$39,0)) -> 2 | G6: =INDEX('(2) Pengundi & % Melayu'!$M$5:$M$40,MATCH($B6,'(2) Pengundi & % Melayu'!$B$5:$B$40,0)) -> 0.79008809 | H6: 77% (P)
B7: N34 | C7: =INDEX('(2) Pengundi & % Melayu'!$C$5:$C$40,MATCH($B7,'(2) Pengundi & % Melayu'!$B$5:$B$40,0)) -> Gemas | D7: =INDEX('(2) Pengundi & % Melayu'!$D$5:$D$40,MATCH($B7,'(2) Pengundi & % Melayu'!$B$5:$B$40,0)) -> 29235 | E7: =INDEX('(1) Majoriti'!$I$4:$I$39,MATCH($B7,'(1) Majoriti'!$B$4:$B$39,0)) -> 3120 | F7: =INDEX('(1) Majoriti'!$J$4:$J$39,MATCH($B7,'(1) Majoriti'!$B$4:$B$39,0)) -> 3 | G7: =INDEX('(2) Pengundi & % Melayu'!$M$5:$M$40,MATCH($B7,'(2) Pengundi & % Melayu'!$B$5:$B$40,0)) -> 0.85004276 | H7: 0.5385
B8: N20 | C8: =INDEX('(2) Pengundi & % Melayu'!$C$5:$C$40,MATCH($B8,'(2) Pengundi & % Melayu'!$B$5:$B$40,0)) -> Labu | D8: =INDEX('(2) Pengundi & % Melayu'!$D$5:$D$40,MATCH($B8,'(2) Pengundi & % Melayu'!$B$5:$B$40,0)) -> 32575 | E8: =INDEX('(1) Majoriti'!$I$4:$I$39,MATCH($B8,'(1) Majoriti'!$B$4:$B$39,0)) -> 1640 | F8: =INDEX('(1) Majoriti'!$J$4:$J$39,MATCH($B8,'(1) Majoriti'!$B$4:$B$39,0)) -> 4 | G8: =INDEX('(2) Pengundi & % Melayu'!$M$5:$M$40,MATCH($B8,'(2) Pengundi & % Melayu'!$B$5:$B$40,0)) -> 0.79214121 | H8: 0.6923
B9: N05 | C9: =INDEX('(2) Pengundi & % Melayu'!$C$5:$C$40,MATCH($B9,'(2) Pengundi & % Melayu'!$B$5:$B$40,0)) -> Serting | D9: =INDEX('(2) Pengundi & % Melayu'!$D$5:$D$40,MATCH($B9,'(2) Pengundi & % Melayu'!$B$5:$B$40,0)) -> 30593 | E9: =INDEX('(1) Majoriti'!$I$4:$I$39,MATCH($B9,'(1) Majoriti'!$B$4:$B$39,0)) -> 843 | F9: =INDEX('(1) Majoriti'!$J$4:$J$39,MATCH($B9,'(1) Majoriti'!$B$4:$B$39,0)) -> 5 | G9: =INDEX('(2) Pengundi & % Melayu'!$M$5:$M$40,MATCH($B9,'(2) Pengundi & % Melayu'!$B$5:$B$40,0)) -> 0.79501847 | H9: 38.46% (P)
B10: N15 | C10: =INDEX('(2) Pengundi & % Melayu'!$C$5:$C$40,MATCH($B10,'(2) Pengundi & % Melayu'!$B$5:$B$40,0)) -> Juasseh | D10: =INDEX('(2) Pengundi & % Melayu'!$D$5:$D$40,MATCH($B10,'(2) Pengundi & % Melayu'!$B$5:$B$40,0)) -> 13669 | E10: =INDEX('(1) Majoriti'!$I$4:$I$39,MATCH($B10,'(1) Majoriti'!$B$4:$B$39,0)) -> -78 | F10: =INDEX('(1) Majoriti'!$J$4:$J$39,MATCH($B10,'(1) Majoriti'!$B$4:$B$39,0)) -> 6 | G10: =INDEX('(2) Pengundi & % Melayu'!$M$5:$M$40,MATCH($B10,'(2) Pengundi & % Melayu'!$B$5:$B$40,0)) -> 0.82741971 | H10: 61.54% (P)
B11: N28 | C11: =INDEX('(2) Pengundi & % Melayu'!$C$5:$C$40,MATCH($B11,'(2) Pengundi & % Melayu'!$B$5:$B$40,0)) -> Kota | D11: =INDEX('(2) Pengundi & % Melayu'!$D$5:$D$40,MATCH($B11,'(2) Pengundi & % Melayu'!$B$5:$B$40,0)) -> 16730 | E11: =INDEX('(1) Majoriti'!$I$4:$I$39,MATCH($B11,'(1) Majoriti'!$B$4:$B$39,0)) -> -135 | F11: =INDEX('(1) Majoriti'!$J$4:$J$39,MATCH($B11,'(1) Majoriti'!$B$4:$B$39,0)) -> 7 | G11: =INDEX('(2) Pengundi & % Melayu'!$M$5:$M$40,MATCH($B11,'(2) Pengundi & % Melayu'!$B$5:$B$40,0)) -> 0.8858936 | H11: NA
B12: N14 | C12: =INDEX('(2) Pengundi & % Melayu'!$C$5:$C$40,MATCH($B12,'(2) Pengundi & % Melayu'!$B$5:$B$40,0)) -> Ampangan | D12: =INDEX('(2) Pengundi & % Melayu'!$D$5:$D$40,MATCH($B12,'(2) Pengundi & % Melayu'!$B$5:$B$40,0)) -> 21338 | E12: =INDEX('(1) Majoriti'!$I$4:$I$39,MATCH($B12,'(1) Majoriti'!$B$4:$B$39,0)) -> -329 | F12: =INDEX('(1) Majoriti'!$J$4:$J$39,MATCH($B12,'(1) Majoriti'!$B$4:$B$39,0)) -> 8 | G12: =INDEX('(2) Pengundi & % Melayu'!$M$5:$M$40,MATCH($B12,'(2) Pengundi & % Melayu'!$B$5:$B$40,0)) -> 0.7645515 | H12: 77% (P)
B13: N16 | C13: =INDEX('(2) Pengundi & % Melayu'!$C$5:$C$40,MATCH($B13,'(2) Pengundi & % Melayu'!$B$5:$B$40,0)) -> Seri Menanti | D13: =INDEX('(2) Pengundi & % Melayu'!$D$5:$D$40,MATCH($B13,'(2) Pengundi & % Melayu'!$B$5:$B$40,0)) -> 10100 | E13: =INDEX('(1) Majoriti'!$I$4:$I$39,MATCH($B13,'(1) Majoriti'!$B$4:$B$39,0)) -> -370 | F13: =INDEX('(1) Majoriti'!$J$4:$J$39,MATCH($B13,'(1) Majoriti'!$B$4:$B$39,0)) -> 9 | G13: =INDEX('(2) Pengundi & % Melayu'!$M$5:$M$40,MATCH($B13,'(2) Pengundi & % Melayu'!$B$5:$B$40,0)) -> 0.95693069 | H13: 61.54% (P)
B14: N03 | C14: =INDEX('(2) Pengundi & % Melayu'!$C$5:$C$40,MATCH($B14,'(2) Pengundi & % Melayu'!$B$5:$B$40,0)) -> Sungai Lui | D14: =INDEX('(2) Pengundi & % Melayu'!$D$5:$D$40,MATCH($B14,'(2) Pengundi & % Melayu'!$B$5:$B$40,0)) -> 19711 | E14: =INDEX('(1) Majoriti'!$I$4:$I$39,MATCH($B14,'(1) Majoriti'!$B$4:$B$39,0)) -> -535 | F14: =INDEX('(1) Majoriti'!$J$4:$J$39,MATCH($B14,'(1) Majoriti'!$B$4:$B$39,0)) -> 10 | G14: =INDEX('(2) Pengundi & % Melayu'!$M$5:$M$40,MATCH($B14,'(2) Pengundi & % Melayu'!$B$5:$B$40,0)) -> 0.84830805 | H14: 0.885
B15: N06 | C15: =INDEX('(2) Pengundi & % Melayu'!$C$5:$C$40,MATCH($B15,'(2) Pengundi & % Melayu'!$B$5:$B$40,0)) -> Palong | D15: =INDEX('(2) Pengundi & % Melayu'!$D$5:$D$40,MATCH($B15,'(2) Pengundi & % Melayu'!$B$5:$B$40,0)) -> 23548 | E15: =INDEX('(1) Majoriti'!$I$4:$I$39,MATCH($B15,'(1) Majoriti'!$B$4:$B$39,0)) -> -564 | F15: =INDEX('(1) Majoriti'!$J$4:$J$39,MATCH($B15,'(1) Majoriti'!$B$4:$B$39,0)) -> 11 | G15: =INDEX('(2) Pengundi & % Melayu'!$M$5:$M$40,MATCH($B15,'(2) Pengundi & % Melayu'!$B$5:$B$40,0)) -> 0.92963309 | H15: 38.46% (P)
B16: N04 | C16: =INDEX('(2) Pengundi & % Melayu'!$C$5:$C$40,MATCH($B16,'(2) Pengundi & % Melayu'!$B$5:$B$40,0)) -> Klawang | D16: =INDEX('(2) Pengundi & % Melayu'!$D$5:$D$40,MATCH($B16,'(2) Pengundi & % Melayu'!$B$5:$B$40,0)) -> 13329 | E16: =INDEX('(1) Majoriti'!$I$4:$I$39,MATCH($B16,'(1) Majoriti'!$B$4:$B$39,0)) -> -577 | F16: =INDEX('(1) Majoriti'!$J$4:$J$39,MATCH($B16,'(1) Majoriti'!$B$4:$B$39,0)) -> 12 | G16: =INDEX('(2) Pengundi & % Melayu'!$M$5:$M$40,MATCH($B16,'(2) Pengundi & % Melayu'!$B$5:$B$40,0)) -> 0.67852052 | H16: NA
B17: N17 | C17: =INDEX('(2) Pengundi & % Melayu'!$C$5:$C$40,MATCH($B17,'(2) Pengundi & % Melayu'!$B$5:$B$40,0)) -> Senaling | D17: =INDEX('(2) Pengundi & % Melayu'!$D$5:$D$40,MATCH($B17,'(2) Pengundi & % Melayu'!$B$5:$B$40,0)) -> 9914 | E17: =INDEX('(1) Majoriti'!$I$4:$I$39,MATCH($B17,'(1) Majoriti'!$B$4:$B$39,0)) -> -662 | F17: =INDEX('(1) Majoriti'!$J$4:$J$39,MATCH($B17,'(1) Majoriti'!$B$4:$B$39,0)) -> 13 | G17: =INDEX('(2) Pengundi & % Melayu'!$M$5:$M$40,MATCH($B17,'(2) Pengundi & % Melayu'!$B$5:$B$40,0)) -> 0.81874117 | H17: 61.54% (P)
B18: N09 | C18: =INDEX('(2) Pengundi & % Melayu'!$C$5:$C$40,MATCH($B18,'(2) Pengundi & % Melayu'!$B$5:$B$40,0)) -> Lenggeng | D18: =INDEX('(2) Pengundi & % Melayu'!$D$5:$D$40,MATCH($B18,'(2) Pengundi & % Melayu'!$B$5:$B$40,0)) -> 28671 | E18: =INDEX('(1) Majoriti'!$I$4:$I$39,MATCH($B18,'(1) Majoriti'!$B$4:$B$39,0)) -> -685 | F18: =INDEX('(1) Majoriti'!$J$4:$J$39,MATCH($B18,'(1) Majoriti'!$B$4:$B$39,0)) -> 14 | G18: =INDEX('(2) Pengundi & % Melayu'!$M$5:$M$40,MATCH($B18,'(2) Pengundi & % Melayu'!$B$5:$B$40,0)) -> 0.79571693 | H18: 77% (P)
B19: N07 | C19: =INDEX('(2) Pengundi & % Melayu'!$C$5:$C$40,MATCH($B19,'(2) Pengundi & % Melayu'!$B$5:$B$40,0)) -> Jeram Padang | D19: =INDEX('(2) Pengundi & % Melayu'!$D$5:$D$40,MATCH($B19,'(2) Pengundi & % Melayu'!$B$5:$B$40,0)) -> 16539 | E19: =INDEX('(1) Majoriti'!$I$4:$I$39,MATCH($B19,'(1) Majoriti'!$B$4:$B$39,0)) -> -693 | F19: =INDEX('(1) Majoriti'!$J$4:$J$39,MATCH($B19,'(1) Majoriti'!$B$4:$B$39,0)) -> 15 | G19: =INDEX('(2) Pengundi & % Melayu'!$M$5:$M$40,MATCH($B19,'(2) Pengundi & % Melayu'!$B$5:$B$40,0)) -> 0.57548824 | H19: 38.46% (P)
B20: N18 | C20: =INDEX('(2) Pengundi & % Melayu'!$C$5:$C$40,MATCH($B20,'(2) Pengundi & % Melayu'!$B$5:$B$40,0)) -> Pilah | D20: =INDEX('(2) Pengundi & % Melayu'!$D$5:$D$40,MATCH($B20,'(2) Pengundi & % Melayu'!$B$5:$B$40,0)) -> 17963 | E20: =INDEX('(1) Majoriti'!$I$4:$I$39,MATCH($B20,'(1) Majoriti'!$B$4:$B$39,0)) -> -1079 | F20: =INDEX('(1) Majoriti'!$J$4:$J$39,MATCH($B20,'(1) Majoriti'!$B$4:$B$39,0)) -> 16 | G20: =INDEX('(2) Pengundi & % Melayu'!$M$5:$M$40,MATCH($B20,'(2) Pengundi & % Melayu'!$B$5:$B$40,0)) -> 0.66659244 | H20: 61.54% (P)
B21: N32 | C21: =INDEX('(2) Pengundi & % Melayu'!$C$5:$C$40,MATCH($B21,'(2) Pengundi & % Melayu'!$B$5:$B$40,0)) -> Linggi | D21: =INDEX('(2) Pengundi & % Melayu'!$D$5:$D$40,MATCH($B21,'(2) Pengundi & % Melayu'!$B$5:$B$40,0)) -> 20768 | E21: =INDEX('(1) Majoriti'!$I$4:$I$39,MATCH($B21,'(1) Majoriti'!$B$4:$B$39,0)) -> -1461 | F21: =INDEX('(1) Majoriti'!$J$4:$J$39,MATCH($B21,'(1) Majoriti'!$B$4:$B$39,0)) -> 17 | G21: =INDEX('(2) Pengundi & % Melayu'!$M$5:$M$40,MATCH($B21,'(2) Pengundi & % Melayu'!$B$5:$B$40,0)) -> 0.65182011 | H21: 0.77
B22: N19 | C22: =INDEX('(2) Pengundi & % Melayu'!$C$5:$C$40,MATCH($B22,'(2) Pengundi & % Melayu'!$B$5:$B$40,0)) -> Johol | D22: =INDEX('(2) Pengundi & % Melayu'!$D$5:$D$40,MATCH($B22,'(2) Pengundi & % Melayu'!$B$5:$B$40,0)) -> 12359 | E22: =INDEX('(1) Majoriti'!$I$4:$I$39,MATCH($B22,'(1) Majoriti'!$B$4:$B$39,0)) -> -2117 | F22: =INDEX('(1) Majoriti'!$J$4:$J$39,MATCH($B22,'(1) Majoriti'!$B$4:$B$39,0)) -> 18 | G22: =INDEX('(2) Pengundi & % Melayu'!$M$5:$M$40,MATCH($B22,'(2) Pengundi & % Melayu'!$B$5:$B$40,0)) -> 0.78566227 | H22: 61.54% (P)
B23: N01 | C23: =INDEX('(2) Pengundi & % Melayu'!$C$5:$C$40,MATCH($B23,'(2) Pengundi & % Melayu'!$B$5:$B$40,0)) -> Chennah | D23: =INDEX('(2) Pengundi & % Melayu'!$D$5:$D$40,MATCH($B23,'(2) Pengundi & % Melayu'!$B$5:$B$40,0)) -> 14427 | E23: =INDEX('(1) Majoriti'!$I$4:$I$39,MATCH($B23,'(1) Majoriti'!$B$4:$B$39,0)) -> -2200 | F23: =INDEX('(1) Majoriti'!$J$4:$J$39,MATCH($B23,'(1) Majoriti'!$B$4:$B$39,0)) -> 19 | G23: =INDEX('(2) Pengundi & % Melayu'!$M$5:$M$40,MATCH($B23,'(2) Pengundi & % Melayu'!$B$5:$B$40,0)) -> 0.51840299 | H23: NA
B24: N35 | C24: =INDEX('(2) Pengundi & % Melayu'!$C$5:$C$40,MATCH($B24,'(2) Pengundi & % Melayu'!$B$5:$B$40,0)) -> Gemencheh | D24: =INDEX('(2) Pengundi & % Melayu'!$D$5:$D$40,MATCH($B24,'(2) Pengundi & % Melayu'!$B$5:$B$40,0)) -> 24878 | E24: =INDEX('(1) Majoriti'!$I$4:$I$39,MATCH($B24,'(1) Majoriti'!$B$4:$B$39,0)) -> -2434 | F24: =INDEX('(1) Majoriti'!$J$4:$J$39,MATCH($B24,'(1) Majoriti'!$B$4:$B$39,0)) -> 20 | G24: =INDEX('(2) Pengundi & % Melayu'!$M$5:$M$40,MATCH($B24,'(2) Pengundi & % Melayu'!$B$5:$B$40,0)) -> 0.63381301 | H24: 0.5385
B25: N13 | C25: =INDEX('(2) Pengundi & % Melayu'!$C$5:$C$40,MATCH($B25,'(2) Pengundi & % Melayu'!$B$5:$B$40,0)) -> Sikamat | D25: =INDEX('(2) Pengundi & % Melayu'!$D$5:$D$40,MATCH($B25,'(2) Pengundi & % Melayu'!$B$5:$B$40,0)) -> 33885 | E25: =INDEX('(1) Majoriti'!$I$4:$I$39,MATCH($B25,'(1) Majoriti'!$B$4:$B$39,0)) -> -2662 | F25: =INDEX('(1) Majoriti'!$J$4:$J$39,MATCH($B25,'(1) Majoriti'!$B$4:$B$39,0)) -> 21 | G25: =INDEX('(2) Pengundi & % Melayu'!$M$5:$M$40,MATCH($B25,'(2) Pengundi & % Melayu'!$B$5:$B$40,0)) -> 0.73230043 | H25: 77% (P)
B26: N02 | C26: =INDEX('(2) Pengundi & % Melayu'!$C$5:$C$40,MATCH($B26,'(2) Pengundi & % Melayu'!$B$5:$B$40,0)) -> Pertang | D26: =INDEX('(2) Pengundi & % Melayu'!$D$5:$D$40,MATCH($B26,'(2) Pengundi & % Melayu'!$B$5:$B$40,0)) -> 12880 | E26: =INDEX('(1) Majoriti'!$I$4:$I$39,MATCH($B26,'(1) Majoriti'!$B$4:$B$39,0)) -> -2790 | F26: =INDEX('(1) Majoriti'!$J$4:$J$39,MATCH($B26,'(1) Majoriti'!$B$4:$B$39,0)) -> 22 | G26: =INDEX('(2) Pengundi & % Melayu'!$M$5:$M$40,MATCH($B26,'(2) Pengundi & % Melayu'!$B$5:$B$40,0)) -> 0.71436335 | H26: 0.115
B27: N12 | C27: =INDEX('(2) Pengundi & % Melayu'!$C$5:$C$40,MATCH($B27,'(2) Pengundi & % Melayu'!$B$5:$B$40,0)) -> Temiang | D27: =INDEX('(2) Pengundi & % Melayu'!$D$5:$D$40,MATCH($B27,'(2) Pengundi & % Melayu'!$B$5:$B$40,0)) -> 12975 | E27: =INDEX('(1) Majoriti'!$I$4:$I$39,MATCH($B27,'(1) Majoriti'!$B$4:$B$39,0)) -> -3068 | F27: =INDEX('(1) Majoriti'!$J$4:$J$39,MATCH($B27,'(1) Majoriti'!$B$4:$B$39,0)) -> 23 | G27: =INDEX('(2) Pengundi & % Melayu'!$M$5:$M$40,MATCH($B27,'(2) Pengundi & % Melayu'!$B$5:$B$40,0)) -> 0.42181118 | H27: 77% (P)
B28: N33 | C28: =INDEX('(2) Pengundi & % Melayu'!$C$5:$C$40,MATCH($B28,'(2) Pengundi & % Melayu'!$B$5:$B$40,0)) -> Sri Tanjung | D28: =INDEX('(2) Pengundi & % Melayu'!$D$5:$D$40,MATCH($B28,'(2) Pengundi & % Melayu'!$B$5:$B$40,0)) -> 19585 | E28: =INDEX('(1) Majoriti'!$I$4:$I$39,MATCH($B28,'(1) Majoriti'!$B$4:$B$39,0)) -> -3996 | F28: =INDEX('(1) Majoriti'!$J$4:$J$39,MATCH($B28,'(1) Majoriti'!$B$4:$B$39,0)) -> 24 | G28: =INDEX('(2) Pengundi & % Melayu'!$M$5:$M$40,MATCH($B28,'(2) Pengundi & % Melayu'!$B$5:$B$40,0)) -> 0.42461067 | H28: NA
B29: N26 | C29: =INDEX('(2) Pengundi & % Melayu'!$C$5:$C$40,MATCH($B29,'(2) Pengundi & % Melayu'!$B$5:$B$40,0)) -> Chembong | D29: =INDEX('(2) Pengundi & % Melayu'!$D$5:$D$40,MATCH($B29,'(2) Pengundi & % Melayu'!$B$5:$B$40,0)) -> 26440 | E29: =INDEX('(1) Majoriti'!$I$4:$I$39,MATCH($B29,'(1) Majoriti'!$B$4:$B$39,0)) -> -4335 | F29: =INDEX('(1) Majoriti'!$J$4:$J$39,MATCH($B29,'(1) Majoriti'!$B$4:$B$39,0)) -> 25 | G29: =INDEX('(2) Pengundi & % Melayu'!$M$5:$M$40,MATCH($B29,'(2) Pengundi & % Melayu'!$B$5:$B$40,0)) -> 0.83801059 | H29: NA
B30: N36 | C30: =INDEX('(2) Pengundi & % Melayu'!$C$5:$C$40,MATCH($B30,'(2) Pengundi & % Melayu'!$B$5:$B$40,0)) -> Repah | D30: =INDEX('(2) Pengundi & % Melayu'!$D$5:$D$40,MATCH($B30,'(2) Pengundi & % Melayu'!$B$5:$B$40,0)) -> 27830 | E30: =INDEX('(1) Majoriti'!$I$4:$I$39,MATCH($B30,'(1) Majoriti'!$B$4:$B$39,0)) -> -5950 | F30: =INDEX('(1) Majoriti'!$J$4:$J$39,MATCH($B30,'(1) Majoriti'!$B$4:$B$39,0)) -> 26 | G30: =INDEX('(2) Pengundi & % Melayu'!$M$5:$M$40,MATCH($B30,'(2) Pengundi & % Melayu'!$B$5:$B$40,0)) -> 0.41789436 | H30: 0.5385
B31: N29 | C31: =INDEX('(2) Pengundi & % Melayu'!$C$5:$C$40,MATCH($B31,'(2) Pengundi & % Melayu'!$B$5:$B$40,0)) -> Chuah | D31: =INDEX('(2) Pengundi & % Melayu'!$D$5:$D$40,MATCH($B31,'(2) Pengundi & % Melayu'!$B$5:$B$40,0)) -> 15141 | E31: =INDEX('(1) Majoriti'!$I$4:$I$39,MATCH($B31,'(1) Majoriti'!$B$4:$B$39,0)) -> -6298 | F31: =INDEX('(1) Majoriti'!$J$4:$J$39,MATCH($B31,'(1) Majoriti'!$B$4:$B$39,0)) -> 27 | G31: =INDEX('(2) Pengundi & % Melayu'!$M$5:$M$40,MATCH($B31,'(2) Pengundi & % Melayu'!$B$5:$B$40,0)) -> 0.2530216 | H31: NA
B32: N22 | C32: =INDEX('(2) Pengundi & % Melayu'!$C$5:$C$40,MATCH($B32,'(2) Pengundi & % Melayu'!$B$5:$B$40,0)) -> Rahang | D32: =INDEX('(2) Pengundi & % Melayu'!$D$5:$D$40,MATCH($B32,'(2) Pengundi & % Melayu'!$B$5:$B$40,0)) -> 19608 | E32: =INDEX('(1) Majoriti'!$I$4:$I$39,MATCH($B32,'(1) Majoriti'!$B$4:$B$39,0)) -> -6432 | F32: =INDEX('(1) Majoriti'!$J$4:$J$39,MATCH($B32,'(1) Majoriti'!$B$4:$B$39,0)) -> 28 | G32: =INDEX('(2) Pengundi & % Melayu'!$M$5:$M$40,MATCH($B32,'(2) Pengundi & % Melayu'!$B$5:$B$40,0)) -> 0.33027336 | H32: 0.5769
B33: N08 | C33: =INDEX('(2) Pengundi & % Melayu'!$C$5:$C$40,MATCH($B33,'(2) Pengundi & % Melayu'!$B$5:$B$40,0)) -> Bahau | D33: =INDEX('(2) Pengundi & % Melayu'!$D$5:$D$40,MATCH($B33,'(2) Pengundi & % Melayu'!$B$5:$B$40,0)) -> 25951 | E33: =INDEX('(1) Majoriti'!$I$4:$I$39,MATCH($B33,'(1) Majoriti'!$B$4:$B$39,0)) -> -8408 | F33: =INDEX('(1) Majoriti'!$J$4:$J$39,MATCH($B33,'(1) Majoriti'!$B$4:$B$39,0)) -> 29 | G33: =INDEX('(2) Pengundi & % Melayu'!$M$5:$M$40,MATCH($B33,'(2) Pengundi & % Melayu'!$B$5:$B$40,0)) -> 0.31632692 | H33: 38.46% (P)
B34: N30 | C34: =INDEX('(2) Pengundi & % Melayu'!$C$5:$C$40,MATCH($B34,'(2) Pengundi & % Melayu'!$B$5:$B$40,0)) -> Lukut | D34: =INDEX('(2) Pengundi & % Melayu'!$D$5:$D$40,MATCH($B34,'(2) Pengundi & % Melayu'!$B$5:$B$40,0)) -> 28010 | E34: =INDEX('(1) Majoriti'!$I$4:$I$39,MATCH($B34,'(1) Majoriti'!$B$4:$B$39,0)) -> -10135 | F34: =INDEX('(1) Majoriti'!$J$4:$J$39,MATCH($B34,'(1) Majoriti'!$B$4:$B$39,0)) -> 30 | G34: =INDEX('(2) Pengundi & % Melayu'!$M$5:$M$40,MATCH($B34,'(2) Pengundi & % Melayu'!$B$5:$B$40,0)) -> 0.26033559 | H34: NA
B35: N27 | C35: =INDEX('(2) Pengundi & % Melayu'!$C$5:$C$40,MATCH($B35,'(2) Pengundi & % Melayu'!$B$5:$B$40,0)) -> Rantau | D35: =INDEX('(2) Pengundi & % Melayu'!$D$5:$D$40,MATCH($B35,'(2) Pengundi & % Melayu'!$B$5:$B$40,0)) -> 34636 | E35: =INDEX('(1) Majoriti'!$I$4:$I$39,MATCH($B35,'(1) Majoriti'!$B$4:$B$39,0)) -> -10280 | F35: =INDEX('(1) Majoriti'!$J$4:$J$39,MATCH($B35,'(1) Majoriti'!$B$4:$B$39,0)) -> 31 | G35: =INDEX('(2) Pengundi & % Melayu'!$M$5:$M$40,MATCH($B35,'(2) Pengundi & % Melayu'!$B$5:$B$40,0)) -> 0.57991685 | H35: NA
B36: N10 | C36: =INDEX('(2) Pengundi & % Melayu'!$C$5:$C$40,MATCH($B36,'(2) Pengundi & % Melayu'!$B$5:$B$40,0)) -> Nilai | D36: =INDEX('(2) Pengundi & % Melayu'!$D$5:$D$40,MATCH($B36,'(2) Pengundi & % Melayu'!$B$5:$B$40,0)) -> 45487 | E36: =INDEX('(1) Majoriti'!$I$4:$I$39,MATCH($B36,'(1) Majoriti'!$B$4:$B$39,0)) -> -10889 | F36: =INDEX('(1) Majoriti'!$J$4:$J$39,MATCH($B36,'(1) Majoriti'!$B$4:$B$39,0)) -> 32 | G36: =INDEX('(2) Pengundi & % Melayu'!$M$5:$M$40,MATCH($B36,'(2) Pengundi & % Melayu'!$B$5:$B$40,0)) -> 0.48833733 | H36: 77% (P)
B37: N24 | C37: =INDEX('(2) Pengundi & % Melayu'!$C$5:$C$40,MATCH($B37,'(2) Pengundi & % Melayu'!$B$5:$B$40,0)) -> Seremban Jaya | D37: =INDEX('(2) Pengundi & % Melayu'!$D$5:$D$40,MATCH($B37,'(2) Pengundi & % Melayu'!$B$5:$B$40,0)) -> 32899 | E37: =INDEX('(1) Majoriti'!$I$4:$I$39,MATCH($B37,'(1) Majoriti'!$B$4:$B$39,0)) -> -12703 | F37: =INDEX('(1) Majoriti'!$J$4:$J$39,MATCH($B37,'(1) Majoriti'!$B$4:$B$39,0)) -> 33 | G37: =INDEX('(2) Pengundi & % Melayu'!$M$5:$M$40,MATCH($B37,'(2) Pengundi & % Melayu'!$B$5:$B$40,0)) -> 0.26690781 | H37: NA
B38: N11 | C38: =INDEX('(2) Pengundi & % Melayu'!$C$5:$C$40,MATCH($B38,'(2) Pengundi & % Melayu'!$B$5:$B$40,0)) -> Lobak | D38: =INDEX('(2) Pengundi & % Melayu'!$D$5:$D$40,MATCH($B38,'(2) Pengundi & % Melayu'!$B$5:$B$40,0)) -> 23141 | E38: =INDEX('(1) Majoriti'!$I$4:$I$39,MATCH($B38,'(1) Majoriti'!$B$4:$B$39,0)) -> -13504 | F38: =INDEX('(1) Majoriti'!$J$4:$J$39,MATCH($B38,'(1) Majoriti'!$B$4:$B$39,0)) -> 34 | G38: =INDEX('(2) Pengundi & % Melayu'!$M$5:$M$40,MATCH($B38,'(2) Pengundi & % Melayu'!$B$5:$B$40,0)) -> 0.06719675 | H38: 77% (P)
B39: N23 | C39: =INDEX('(2) Pengundi & % Melayu'!$C$5:$C$40,MATCH($B39,'(2) Pengundi & % Melayu'!$B$5:$B$40,0)) -> Mambau | D39: =INDEX('(2) Pengundi & % Melayu'!$D$5:$D$40,MATCH($B39,'(2) Pengundi & % Melayu'!$B$5:$B$40,0)) -> 30316 | E39: =INDEX('(1) Majoriti'!$I$4:$I$39,MATCH($B39,'(1) Majoriti'!$B$4:$B$39,0)) -> -14940 | F39: =INDEX('(1) Majoriti'!$J$4:$J$39,MATCH($B39,'(1) Majoriti'!$B$4:$B$39,0)) -> 35 | G39: =INDEX('(2) Pengundi & % Melayu'!$M$5:$M$40,MATCH($B39,'(2) Pengundi & % Melayu'!$B$5:$B$40,0)) -> 0.15110833 | H39: NA
B40: N21 | C40: =INDEX('(2) Pengundi & % Melayu'!$C$5:$C$40,MATCH($B40,'(2) Pengundi & % Melayu'!$B$5:$B$40,0)) -> Bukit Kepayang | D40: =INDEX('(2) Pengundi & % Melayu'!$D$5:$D$40,MATCH($B40,'(2) Pengundi & % Melayu'!$B$5:$B$40,0)) -> 49248 | E40: =INDEX('(1) Majoriti'!$I$4:$I$39,MATCH($B40,'(1) Majoriti'!$B$4:$B$39,0)) -> -19684 | F40: =INDEX('(1) Majoriti'!$J$4:$J$39,MATCH($B40,'(1) Majoriti'!$B$4:$B$39,0)) -> 36 | G40: =INDEX('(2) Pengundi & % Melayu'!$M$5:$M$40,MATCH($B40,'(2) Pengundi & % Melayu'!$B$5:$B$40,0)) -> 0.29757554 | H40: 0.5769

Sheet (1) Majoriti
B2: RANKING MAJORITI UNDI PN MENGIKUT KERUSI DUN PADA PRU15 (N9)
B3: Kod | C3: DUN | D3: Jumlah Pengundi (PRU15) | E3: Bil Turun mengundi | F3: % turun mengundi | G3: Undi Perikatan Nasional (PN) | H3: % Perikatan Nasional (PN) | I3: Majoriti | J3: Ranking
B4: N25 | C4: Paroi | D4: 60704 | E4: 43085 | F4: =E4/D4 -> 0.70975554 | G4: 23840 | H4: =G4/E4 -> 0.55332482 | I4: 5539 | J4: 1
B5: N31 | C5: Bagan Pinang | D5: 27790 | E5: 18416 | F5: =E5/D5 -> 0.66268442 | G5: 10921 | H5: =G5/E5 -> 0.59301694 | I5: 3426 | J5: 2
B6: N34 | C6: Gemas | D6: 29648 | E6: 20186 | F6: =E6/D6 -> 0.68085537 | G6: 11653 | H6: =G6/E6 -> 0.57728128 | I6: 3120 | J6: 3
B7: N20 | C7: Labu | D7: 30478 | E7: 21682 | F7: =E7/D7 -> 0.71139839 | G7: 11661 | H7: =G7/E7 -> 0.53781939 | I7: 1640 | J7: 4
B8: N05 | C8: Serting | D8: 30287 | E8: 19781 | F8: =E8/D8 -> 0.6531185 | G8: 10312 | H8: =G8/E8 -> 0.52130833 | I8: 843 | J8: 5
B9: N15 | C9: Juasseh | D9: 13408 | E9: 9020 | F9: =E9/D9 -> 0.6727327 | G9: 4471 | H9: =G9/E9 -> 0.49567627 | I9: -78 | J9: 6
B10: N28 | C10: Kota | D10: 16510 | E10: 11603 | F10: =E10/D10 -> 0.70278619 | G10: 5734 | H10: =G10/E10 -> 0.49418254 | I10: -135 | J10: 7
B11: N14 | C11: Ampangan | D11: 20992 | E11: 14858 | F11: =E11/D11 -> 0.70779345 | G11: 5725 | H11: =G11/E11 -> 0.38531431 | I11: -329 | J11: 8
B12: N16 | C12: Seri Menanti | D12: 10045 | E12: 7052 | F12: =E12/D12 -> 0.70204082 | G12: 3341 | H12: =G12/E12 -> 0.47376631 | I12: -370 | J12: 9
B13: N03 | C13: Sungai Lui | D13: 20206 | E13: 13343 | F13: =E13/D13 -> 0.66034841 | G13: 6404 | H13: =G13/E13 -> 0.47995203 | I13: -535 | J13: 10
B14: N06 | C14: Palong | D14: 23494 | E14: 15316 | F14: =E14/D14 -> 0.65191113 | G14: 7376 | H14: =G14/E14 -> 0.48158788 | I14: -564 | J14: 11
B15: N04 | C15: Klawang | D15: 13163 | E15: 8983 | F15: =E15/D15 -> 0.68244321 | G15: 4021 | H15: =G15/E15 -> 0.44762329 | I15: -577 | J15: 12
... B39: N21 | C39: Bukit Kepayang | D39: 46229 | E39: 30489 | F39: =E39/D39 -> 0.65952108 | G39: 4942 | H39: =G39/E39 -> 0.16209125 | I39: -19684 | J39: 36
C41: Petunjuk: | D41: PN Menang | E41: BN Menang | F41: PH Menang

Sheet (2) Pengundi & % Melayu
B2: RANKING PENGUNDI MELAYU MENGIKUT KERUSI DUN (DPI DISEMBER 2025)
B4: Kod | C4: DUN | D4: Jumlah Pengundi (DPI Dis 2025) | E4: Ranking bik pengundi | F4: Bil Pengundi Cina | G4: % Pengundi Cina | H4: Bil Pengundi India | I4: % Pengundi India | J4: Bil Pengundi Lain-Lain | K4: % Pengundi Lain-lain | L4: Bil Pengundi Melayu | M4: % Pengundi Melayu | N4: Ranking % pengundi melayu
B5: N01 | C5: Chennah | D5: 14427 | E5: =RANK(D5,$D$5:$D$40) -> 29 | F5: 6630 | G5: =F5/$D5 -> 0.459555 | H5: 318 | I5: =H5/$D5 -> 0.022042005 | J5: 0 | K5: =J5/$D5 -> 0 | L5: 7479 | M5: =L5/$D5 -> 0.51840299 | N5: =RANK(M5,$M$5:$M$40) -> 24
B6: N02 | C6: Pertang | D6: 12880 | E6: =RANK(D6,$D$5:$D$40) -> 33 | F6: 2842 | G6: =F6/$D6 -> 0.22065217 | H6: 837 | I6: =H6/$D6 -> 0.064984472 | J6: 0 | K6: =J6/$D6 -> 0 | L6: 9201 | M6: =L6/$D6 -> 0.71436335 | N6: =RANK(M6,$M$5:$M$40) -> 17
B7: N03 | C7: Sungai Lui | D7: 19711 | E7: =RANK(D7,$D$5:$D$40) -> 22 | F7: 1417 | G7: =F7/$D7 -> 0.071888793 | H7: 1573 | I7: =H7/$D7 -> 0.079803156 | J7: 0 | K7: =J7/$D7 -> 0 | L7: 16721 | M7: =L7/$D7 -> 0.84830805 | N7: =RANK(M7,$M$5:$M$40) -> 5
B8: N04 | C8: Klawang | D8: 13329 | E8: =RANK(D8,$D$5:$D$40) -> 31 | F8: 3818 | G8: =F8/$D8 -> 0.28644309 | H8: 465 | I8: =H8/$D8 -> 0.034886338 | J8: 2 | K8: =J8/$D8 -> 0.00015004877 | L8: 9044 | M8: =L8/$D8 -> 0.67852052 | N8: =RANK(M8,$M$5:$M$40) -> 18
B9: N05 | C9: Serting | D9: 30593 | E9: =RANK(D9,$D$5:$D$40) -> 8 | F9: 3845 | G9: =F9/$D9 -> 0.12568235 | H9: 2426 | I9: =H9/$D9 -> 0.079299186 | J9: 0 | K9: =J9/$D9 -> 0 | L9: 24322 | M9: =L9/$D9 -> 0.79501847 | N9: =RANK(M9,$M$5:$M$40) -> 11
B10: N06 | C10: Palong | D10: 23548 | E10: =RANK(D10,$D$5:$D$40) -> 18 | F10: 453 | G10: =F10/$D10 -> 0.019237303 | H10: 1204 | I10: =H10/$D10 -> 0.051129608 | J10: 0 | K10: =J10/$D10 -> 0 | L10: 21891 | M10: =L10/$D10 -> 0.92963309 | N10: =RANK(M10,$M$5:$M$40) -> 2
B11: N07 | C11: Jeram Padang | D11: 16539 | E11: =RANK(D11,$D$5:$D$40) -> 27 | F11: 1696 | G11: =F11/$D11 -> 0.1025455 | H11: 5324 | I11: =H11/$D11 -> 0.3219058 | J11: 1 | K11: =J11/$D11 -> 6.0463148e-05 | L11: 9518 | M11: =L11/$D11 -> 0.57548824 | N11: =RANK(M11,$M$5:$M$40) -> 23
B12: N08 | C12: Bahau | D12: 25951 | E12: =RANK(D12,$D$5:$D$40) -> 16 | F12: 15122 | G12: =F12/$D12 -> 0.58271358 | H12: 2620 | I12: =H12/$D12 -> 0.1009595 | J12: 0 | K12: =J12/$D12 -> 0 | L12: 8209 | M12: =L12/$D12 -> 0.31632692 | N12: =RANK(M12,$M$5:$M$40) -> 30
B13: N09 | C13: Lenggeng | D13: 28671 | E13: =RANK(D13,$D$5:$D$40) -> 11 | F13: 4457 | G13: =F13/$D13 -> 0.15545325 | H13: 1400 | I13: =H13/$D13 -> 0.048829828 | J13: 0 | K13: =J13/$D13 -> 0 | L13: 22814 | M13: =L13/$D13 -> 0.79571693 | N13: =RANK(M13,$M$5:$M$40) -> 10
B14: N10 | C14: Nilai | D14: 45487 | E14: =RANK(D14,$D$5:$D$40) -> 3 | F14: 14350 | G14: =F14/$D14 -> 0.31547475 | H14: 8918 | I14: =H14/$D14 -> 0.19605602 | J14: 6 | K14: =J14/$D14 -> 0.00013190582 | L14: 22213 | M14: =L14/$D14 -> 0.48833733 | N14: =RANK(M14,$M$5:$M$40) -> 25
B15: N11 | C15: Lobak | D15: 23141 | E15: =RANK(D15,$D$5:$D$40) -> 19 | F15: 16793 | G15: =F15/$D15 -> 0.72568169 | H15: 4789 | I15: =H15/$D15 -> 0.20694871 | J15: 4 | K15: =J15/$D15 -> 0.00017285338 | L15: 1555 | M15: =L15/$D15 -> 0.06719675 | N15: =RANK(M15,$M$5:$M$40) -> 36
B16: N12 | C16: Temiang | D16: 12975 | E16: =RANK(D16,$D$5:$D$40) -> 32 | F16: 5800 | G16: =F16/$D16 -> 0.44701349 | H16: 1695 | I16: =H16/$D16 -> 0.13063584 | J16: 7 | K16: =J16/$D16 -> 0.00053949904 | L16: 5473 | M16: =L16/$D16 -> 0.42181118 | N16: =RANK(M16,$M$5:$M$40) -> 27
... B40: N36 | C40: Repah | D40: 27830 | E40: =RANK(D40,$D$5:$D$40) -> 14 | F40: 11633 | G40: =F40/$D40 -> 0.41800216 | H40: 4560 | I40: =H40/$D40 -> 0.16385196 | J40: 7 | K40: =J40/$D40 -> 0.00025152713 | L40: 11630 | M40: =L40/$D40 -> 0.41789436 | N40: =RANK(M40,$M$5:$M$40) -> 28

Sheet (3) SKT 51%
B2: RANKING SKT 51% MENGIKUT KERUSI DUN (DPI DISEMBER 2025)
B4: Kod | C4: DUN | D4: Jumlah Pengundi (DPI Dis 2025) | E4: Anggaran TOC 68% | F4: SKT 51% | G4: Ranking SKT 51%
B5: N01 | C5: Chennah | D5: 14427 | E5: =ROUND(D5*0.68,0) -> 9810 | F5: =ROUND(E5*0.51,0) -> 5003 | G5: =RANK(F5,$F$5:$F$40) -> 29
B6: N02 | C6: Pertang | D6: 12880 | E6: =ROUND(D6*0.68,0) -> 8758 | F6: =ROUND(E6*0.51,0) -> 4467 | G6: =RANK(F6,$F$5:$F$40) -> 33
B7: N03 | C7: Sungai Lui | D7: 19711 | E7: =ROUND(D7*0.68,0) -> 13403 | F7: =ROUND(E7*0.51,0) -> 6836 | G7: =RANK(F7,$F$5:$F$40) -> 22
B8: N04 | C8: Klawang | D8: 13329 | E8: =ROUND(D8*0.68,0) -> 9064 | F8: =ROUND(E8*0.51,0) -> 4623 | G8: =RANK(F8,$F$5:$F$40) -> 31
B9: N05 | C9: Serting | D9: 30593 | E9: =ROUND(D9*0.68,0) -> 20803 | F9: =ROUND(E9*0.51,0) -> 10610 | G9: =RANK(F9,$F$5:$F$40) -> 8
B10: N06 | C10: Palong | D10: 23548 | E10: =ROUND(D10*0.68,0) -> 16013 | F10: =ROUND(E10*0.51,0) -> 8167 | G10: =RANK(F10,$F$5:$F$40) -> 18
B11: N07 | C11: Jeram Padang | D11: 16539 | E11: =ROUND(D11*0.68,0) -> 11247 | F11: =ROUND(E11*0.51,0) -> 5736 | G11: =RANK(F11,$F$5:$F$40) -> 27
B12: N08 | C12: Bahau | D12: 25951 | E12: =ROUND(D12*0.68,0) -> 17647 | F12: =ROUND(E12*0.51,0) -> 9000 | G12: =RANK(F12,$F$5:$F$40) -> 16
B13: N09 | C13: Lenggeng | D13: 28671 | E13: =ROUND(D13*0.68,0) -> 19496 | F13: =ROUND(E13*0.51,0) -> 9943 | G13: =RANK(F13,$F$5:$F$40) -> 11
B14: N10 | C14: Nilai | D14: 45487 | E14: =ROUND(D14*0.68,0) -> 30931 | F14: =ROUND(E14*0.51,0) -> 15775 | G14: =RANK(F14,$F$5:$F$40) -> 3
B15: N11 | C15: Lobak | D15: 23141 | E15: =ROUND(D15*0.68,0) -> 15736 | F15: =ROUND(E15*0.51,0) -> 8025 | G15: =RANK(F15,$F$5:$F$40) -> 19
B16: N12 | C16: Temiang | D16: 12975 | E16: =ROUND(D16*0.68,0) -> 8823 | F16: =ROUND(E16*0.51,0) -> 4500 | G16: =RANK(F16,$F$5:$F$40) -> 32
... B40: N36 | C40: Repah | D40: 27830 | E40: =ROUND(D40*0.68,0) -> 18924 | F40: =ROUND(E40*0.51,0) -> 9651 | G40: =RANK(F40,$F$5:$F$40) -> 14

Sheet (4) BKC vs modal PRU15
B2: RANKING BAKI KENA CARI (BKC) MENGIKUT KERUSI DUN (DPI DISEMBER 2025)
B4: Kod | C4: DUN | D4: Undi PN PRU15 | E4: SKT 51% | F4: BKC | G4: Ranking
B5: N01 | C5: Chennah | D5: =_xlfn.XLOOKUP($B5,'(1) Majoriti'!$B$4:$B$39,'(1) Majoriti'!$G$4:$G$39) -> 3688 | E5: =_xlfn.XLOOKUP($B5,'(3) SKT 51%'!$B$5:$B$40,'(3) SKT 51%'!$F$5:$F$40) -> 5003 | F5: =D5-E5 -> -1315 | G5: =RANK(F5,$F$5:$F$40) -> 18
B6: N02 | C6: Pertang | D6: =_xlfn.XLOOKUP($B6,'(1) Majoriti'!$B$4:$B$39,'(1) Majoriti'!$G$4:$G$39) -> 2844 | E6: =_xlfn.XLOOKUP($B6,'(3) SKT 51%'!$B$5:$B$40,'(3) SKT 51%'!$F$5:$F$40) -> 4467 | F6: =D6-E6 -> -1623 | G6: =RANK(F6,$F$5:$F$40) -> 19
B7: N03 | C7: Sungai Lui | D7: =_xlfn.XLOOKUP($B7,'(1) Majoriti'!$B$4:$B$39,'(1) Majoriti'!$G$4:$G$39) -> 6404 | E7: =_xlfn.XLOOKUP($B7,'(3) SKT 51%'!$B$5:$B$40,'(3) SKT 51%'!$F$5:$F$40) -> 6836 | F7: =D7-E7 -> -432 | G7: =RANK(F7,$F$5:$F$40) -> 10
B8: N04 | C8: Klawang | D8: =_xlfn.XLOOKUP($B8,'(1) Majoriti'!$B$4:$B$39,'(1) Majoriti'!$G$4:$G$39) -> 4021 | E8: =_xlfn.XLOOKUP($B8,'(3) SKT 51%'!$B$5:$B$40,'(3) SKT 51%'!$F$5:$F$40) -> 4623 | F8: =D8-E8 -> -602 | G8: =RANK(F8,$F$5:$F$40) -> 12
B9: N05 | C9: Serting | D9: =_xlfn.XLOOKUP($B9,'(1) Majoriti'!$B$4:$B$39,'(1) Majoriti'!$G$4:$G$39) -> 10312 | E9: =_xlfn.XLOOKUP($B9,'(3) SKT 51%'!$B$5:$B$40,'(3) SKT 51%'!$F$5:$F$40) -> 10610 | F9: =D9-E9 -> -298 | G9: =RANK(F9,$F$5:$F$40) -> 8
B10: N06 | C10: Palong | D10: =_xlfn.XLOOKUP($B10,'(1) Majoriti'!$B$4:$B$39,'(1) Majoriti'!$G$4:$G$39) -> 7376 | E10: =_xlfn.XLOOKUP($B10,'(3) SKT 51%'!$B$5:$B$40,'(3) SKT 51%'!$F$5:$F$40) -> 8167 | F10: =D10-E10 -> -791 | G10: =RANK(F10,$F$5:$F$40) -> 13
B11: N07 | C11: Jeram Padang | D11: =_xlfn.XLOOKUP($B11,'(1) Majoriti'!$B$4:$B$39,'(1) Majoriti'!$G$4:$G$39) -> 4769 | E11: =_xlfn.XLOOKUP($B11,'(3) SKT 51%'!$B$5:$B$40,'(3) SKT 51%'!$F$5:$F$40) -> 5736 | F11: =D11-E11 -> -967 | G11: =RANK(F11,$F$5:$F$40) -> 15
B12: N08 | C12: Bahau | D12: =_xlfn.XLOOKUP($B12,'(1) Majoriti'!$B$4:$B$39,'(1) Majoriti'!$G$4:$G$39) -> 3531 | E12: =_xlfn.XLOOKUP($B12,'(3) SKT 51%'!$B$5:$B$40,'(3) SKT 51%'!$F$5:$F$40) -> 9000 | F12: =D12-E12 -> -5469 | G12: =RANK(F12,$F$5:$F$40) -> 30
B13: N09 | C13: Lenggeng | D13: =_xlfn.XLOOKUP($B13,'(1) Majoriti'!$B$4:$B$39,'(1) Majoriti'!$G$4:$G$39) -> 9355 | E13: =_xlfn.XLOOKUP($B13,'(3) SKT 51%'!$B$5:$B$40,'(3) SKT 51%'!$F$5:$F$40) -> 9943 | F13: =D13-E13 -> -588 | G13: =RANK(F13,$F$5:$F$40) -> 11
B14: N10 | C14: Nilai | D14: =_xlfn.XLOOKUP($B14,'(1) Majoriti'!$B$4:$B$39,'(1) Majoriti'!$G$4:$G$39) -> 8244 | E14: =_xlfn.XLOOKUP($B14,'(3) SKT 51%'!$B$5:$B$40,'(3) SKT 51%'!$F$5:$F$40) -> 15775 | F14: =D14-E14 -> -7531 | G14: =RANK(F14,$F$5:$F$40) -> 34
B15: N11 | C15: Lobak | D15: =_xlfn.XLOOKUP($B15,'(1) Majoriti'!$B$4:$B$39,'(1) Majoriti'!$G$4:$G$39) -> 853 | E15: =_xlfn.XLOOKUP($B15,'(3) SKT 51%'!$B$5:$B$40,'(3) SKT 51%'!$F$5:$F$40) -> 8025 | F15: =D15-E15 -> -7172 | G15: =RANK(F15,$F$5:$F$40) -> 33
B16: N12 | C16: Temiang | D16: =_xlfn.XLOOKUP($B16,'(1) Majoriti'!$B$4:$B$39,'(1) Majoriti'!$G$4:$G$39) -> 2642 | E16: =_xlfn.XLOOKUP($B16,'(3) SKT 51%'!$B$5:$B$40,'(3) SKT 51%'!$F$5:$F$40) -> 4500 | F16: =D16-E16 -> -1858 | G16: =RANK(F16,$F$5:$F$40) -> 22
... B40: N36 | C40: Repah | D40: =_xlfn.XLOOKUP($B40,'(1) Majoriti'!$B$4:$B$39,'(1) Majoriti'!$G$4:$G$39) -> 5557 | E40: =_xlfn.XLOOKUP($B40,'(3) SKT 51%'!$B$5:$B$40,'(3) SKT 51%'!$F$5:$F$40) -> 9651 | F40: =D40-E40 -> -4094 | G40: =RANK(F40,$F$5:$F$40) -> 28

Sheet (5) Cula
B2: RANKING PERATUS CULA PAS MENGIKUT KERUSI DUN (DPI DISEMBER 2025)
B4: Kod | C4: DUN | D4: Jumlah Pengundi (DPI Dis 2025) | E4: A - ATAS PAGAR | F4: B - BULAN | G4: C - CONDONG BULAN | H4: D - DACING | I4: E - CONDONG DACING | J4: F - GAGAL DIKESAN | K4: G - MATI | L4: H - BULAN LUAR KAWASAN | M4: ? - TIADA CULAAN | N4: Jumlah Pengundi PAS (B+C+H) | O4: % cula pengundi PAS | P4: Ranking % cula | R4: Parlimen | S4: : | T4: 126 - JELEBU | X4: Parlimen | Y4: : | Z4: 127 - JEMPOL | AD4: Parlimen | AE4: : | AF4: 128 - SEREMBAN | AJ4: Parlimen | AK4: : | AL4: 129 - KUALA PILAH | AP4: Parlimen | AQ4: : | AR4: 130 - RASAH | AV4: Parlimen | AW4: : | AX4: 131 - REMBAU | BB4: Parlimen | BC4: : | BD4: 132 - PORT DICKSON | BH4: Parlimen | BI4: : | BJ4: 133 - TAMPIN
B5: N01 | C5: Chennah | D5: =_xlfn.XLOOKUP($B5,'(3) SKT 51%'!$B$5:$B$40,'(3) SKT 51%'!$D$5:$D$40) -> 14427 | E5: 1846 | F5: 142 | G5: 779 | H5: 2371 | I5: 0 | J5: 1 | K5: 0 | L5: 2 | M5: 9286 | N5: =F5+G5+L5 -> 923 | O5: =N5/D5 -> 0.063977265 | P5: =RANK(O5,$O$5:$O$40) -> 8
B6: N02 | C6: Pertang | D6: =_xlfn.XLOOKUP($B6,'(3) SKT 51%'!$B$5:$B$40,'(3) SKT 51%'!$D$5:$D$40) -> 12880 | E6: 2361 | F6: 278 | G6: 1143 | H6: 2826 | I6: 0 | J6: 0 | K6: 6 | L6: 0 | M6: 6266 | N6: =F6+G6+L6 -> 1421 | O6: =N6/D6 -> 0.11032609 | P6: =RANK(O6,$O$5:$O$40) -> 3 | R6: Bil. | S6: DUN | T6: Status Culaan | U6: Jumlah | V6: % | X6: Bil. | Y6: DUN | Z6: Status Culaan | AA6: Jumlah | AB6: % | AD6: Bil. | AE6: DUN | AF6: Status Culaan | AG6: Jumlah | AH6: % | AJ6: Bil. | AK6: DUN | AL6: Status Culaan | AM6: Jumlah | AN6: % | AP6: Bil. | AQ6: DUN | AR6: Status Culaan | AS6: Jumlah | AT6: % | AV6: Bil. | AW6: DUN | AX6: Status Culaan | AY6: Jumlah | AZ6: % | BB6: Bil. | BC6: DUN | BD6: Status Culaan | BE6: Jumlah | BF6: % | BH6: Bil. | BI6: DUN | BJ6: Status Culaan | BK6: Jumlah | BL6: %
B7: N03 | C7: Sungai Lui | D7: =_xlfn.XLOOKUP($B7,'(3) SKT 51%'!$B$5:$B$40,'(3) SKT 51%'!$D$5:$D$40) -> 19711 | E7: 3153 | F7: 505 | G7: 4375 | H7: 2393 | I7: 2 | J7: 1 | K7: 1 | L7: 0 | M7: 9281 | N7: =F7+G7+L7 -> 4880 | O7: =N7/D7 -> 0.24757749 | P7: =RANK(O7,$O$5:$O$40) -> 1 | R7: 1 | S7: 01 - CHENNAH | T7: A - ATAS PAGAR | U7: 1846 | V7: 12.8 | X7: 1 | Y7: 05 - SERTING | Z7: A - ATAS PAGAR | AA7: 1900 | AB7: 6.21 | AD7: 1 | AE7: 09 - LENGGENG | AF7: A - ATAS PAGAR | AG7: 469 | AH7: 1.64 | AJ7: 1 | AK7: 15 - JUASSEH | AL7: A - ATAS PAGAR | AM7: 31 | AN7: 0.23 | AP7: 1 | AQ7: 20 - LABU | AR7: A - ATAS PAGAR | AS7: 2861 | AT7: 8.78 | AV7: 1 | AW7: 25 - PAROI | AX7: A - ATAS PAGAR | AY7: 561 | AZ7: 0.87 | BB7: 1 | BC7: 29 - CHUAH | BD7: A - ATAS PAGAR | BE7: 584 | BF7: 3.86 | BH7: 1 | BI7: 34 - GEMAS | BJ7: A - ATAS PAGAR | BK7: 43 | BL7: 0.15
B8: N04 | C8: Klawang | D8: =_xlfn.XLOOKUP($B8,'(3) SKT 51%'!$B$5:$B$40,'(3) SKT 51%'!$D$5:$D$40) -> 13329 | E8: 2494 | F8: 24 | G8: 2322 | H8: 2050 | I8: 0 | J8: 0 | K8: 0 | L8: 0 | M8: 6439 | N8: =F8+G8+L8 -> 2346 | O8: =N8/D8 -> 0.1760072 | P8: =RANK(O8,$O$5:$O$40) -> 2 | T8: B - BULAN | U8: 142 | V8: 0.98 | Z8: B - BULAN | AA8: 678 | AB8: 2.22 | AF8: B - BULAN | AG8: 472 | AH8: 1.65 | AL8: B - BULAN | AM8: 251 | AN8: 1.84 | AR8: B - BULAN | AS8: 697 | AT8: 2.14 | AX8: B - BULAN | AY8: 1089 | AZ8: 1.69 | BD8: B - BULAN | BE8: 72 | BF8: 0.48 | BJ8: B - BULAN | BK8: 270 | BL8: 0.92
B9: N05 | C9: Serting | D9: =_xlfn.XLOOKUP($B9,'(3) SKT 51%'!$B$5:$B$40,'(3) SKT 51%'!$D$5:$D$40) -> 30593 | E9: 1900 | F9: 678 | G9: 2594 | H9: 6262 | I9: 60 | J9: 43 | K9: 1 | L9: 1 | M9: 19054 | N9: =F9+G9+L9 -> 3273 | O9: =N9/D9 -> 0.10698526 | P9: =RANK(O9,$O$5:$O$40) -> 5 | T9: C - CONDONG BULAN | U9: 779 | V9: 5.4 | Z9: C - CONDONG BULAN | AA9: 2594 | AB9: 8.48 | AF9: C - CONDONG BULAN | AG9: 536 | AH9: 1.87 | AL9: C - CONDONG BULAN | AM9: 79 | AN9: 0.58 | AR9: C - CONDONG BULAN | AS9: 958 | AT9: 2.94 | AX9: C - CONDONG BULAN | AY9: 2179 | AZ9: 3.37 | BD9: C - CONDONG BULAN | BE9: 31 | BF9: 0.2 | BJ9: C - CONDONG BULAN | BK9: 80 | BL9: 0.27
B10: N06 | C10: Palong | D10: =_xlfn.XLOOKUP($B10,'(3) SKT 51%'!$B$5:$B$40,'(3) SKT 51%'!$D$5:$D$40) -> 23548 | E10: 2264 | F10: 203 | G10: 2348 | H10: 7086 | I10: 0 | J10: 0 | K10: 0 | L10: 0 | M10: 11647 | N10: =F10+G10+L10 -> 2551 | O10: =N10/D10 -> 0.10833192 | P10: =RANK(O10,$O$5:$O$40) -> 4 | T10: D - DACING | U10: 2371 | V10: 16.43 | Z10: D - DACING | AA10: 6262 | AB10: 20.47 | AF10: D - DACING | AG10: 641 | AH10: 2.24 | AL10: D - DACING | AM10: 101 | AN10: 0.74 | AR10: D - DACING | AS10: 2828 | AT10: 8.68 | AX10: D - DACING | AY10: 2393 | AZ10: 3.71 | BD10: D - DACING | BE10: 465 | BF10: 3.07 | BJ10: D - DACING | BK10: 40 | BL10: 0.14
B11: N07 | C11: Jeram Padang | D11: =_xlfn.XLOOKUP($B11,'(3) SKT 51%'!$B$5:$B$40,'(3) SKT 51%'!$D$5:$D$40) -> 16539 | E11: 1036 | F11: 93 | G11: 975 | H11: 2536 | I11: 0 | J11: 0 | K11: 0 | L11: 0 | M11: 11899 | N11: =F11+G11+L11 -> 1068 | O11: =N11/D11 -> 0.064574642 | P11: =RANK(O11,$O$5:$O$40) -> 7 | T11: E - CONDONG DACING | U11: 0 | V11: 0 | Z11: E - CONDONG DACING | AA11: 60 | AB11: 0.2 | AF11: E - CONDONG DACING | AG11: 21 | AH11: 0.07 | AL11: E - CONDONG DACING | AM11: 0 | AN11: 0 | AR11: E - CONDONG DACING | AS11: 3 | AT11: 0.01 | AX11: E - CONDONG DACING | AY11: 26 | AZ11: 0.04 | BD11: E - CONDONG DACING | BE11: 1 | BF11: 0.01 | BJ11: E - CONDONG DACING | BK11: 7 | BL11: 0.02
B12: N08 | C12: Bahau | D12: =_xlfn.XLOOKUP($B12,'(3) SKT 51%'!$B$5:$B$40,'(3) SKT 51%'!$D$5:$D$40) -> 25951 | E12: 767 | F12: 201 | G12: 838 | H12: 2014 | I12: 1 | J12: 0 | K12: 0 | L12: 0 | M12: 22130 | N12: =F12+G12+L12 -> 1039 | O12: =N12/D12 -> 0.040036993 | P12: =RANK(O12,$O$5:$O$40) -> 14 | T12: F - GAGAL DIKESAN | U12: 1 | V12: 0.01 | Z12: F - GAGAL DIKESAN | AA12: 43 | AB12: 0.14 | AF12: F - GAGAL DIKESAN | AG12: 0 | AH12: 0 | AL12: F - GAGAL DIKESAN | AM12: 0 | AN12: 0 | AR12: F - GAGAL DIKESAN | AS12: 41 | AT12: 0.13 | AX12: F - GAGAL DIKESAN | AY12: 23 | AZ12: 0.04 | BD12: F - GAGAL DIKESAN | BE12: 3 | BF12: 0.02 | BJ12: F - GAGAL DIKESAN | BK12: 0 | BL12: 0
B13: N09 | C13: Lenggeng | D13: =_xlfn.XLOOKUP($B13,'(3) SKT 51%'!$B$5:$B$40,'(3) SKT 51%'!$D$5:$D$40) -> 28671 | E13: 469 | F13: 472 | G13: 536 | H13: 641 | I13: 21 | J13: 0 | K13: 1 | L13: 2 | M13: 26529 | N13: =F13+G13+L13 -> 1010 | O13: =N13/D13 -> 0.035227233 | P13: =RANK(O13,$O$5:$O$40) -> 16 | T13: G - MATI | U13: 0 | V13: 0 | Z13: G - MATI | AA13: 1 | AB13: 0 | AF13: G - MATI | AG13: 1 | AH13: 0 | AL13: G - MATI | AM13: 2 | AN13: 0.01 | AR13: G - MATI | AS13: 5 | AT13: 0.02 | AX13: G - MATI | AY13: 0 | AZ13: 0 | BD13: G - MATI | BE13: 3 | BF13: 0.02 | BJ13: G - MATI | BK13: 0 | BL13: 0
B14: N10 | C14: Nilai | D14: =_xlfn.XLOOKUP($B14,'(3) SKT 51%'!$B$5:$B$40,'(3) SKT 51%'!$D$5:$D$40) -> 45487 | E14: 145 | F14: 218 | G14: 655 | H14: 141 | I14: 37 | J14: 27 | K14: 0 | L14: 0 | M14: 44264 | N14: =F14+G14+L14 -> 873 | O14: =N14/D14 -> 0.019192297 | P14: =RANK(O14,$O$5:$O$40) -> 25 | T14: H - BULAN LUAR KAWASAN | U14: 2 | V14: 0.01 | Z14: H - BULAN LUAR KAWASAN | AA14: 1 | AB14: 0 | AF14: H - BULAN LUAR KAWASAN | AG14: 2 | AH14: 0.01 | AL14: H - BULAN LUAR KAWASAN | AM14: 0 | AN14: 0 | AR14: H - BULAN LUAR KAWASAN | AS14: 2 | AT14: 0.01 | AX14: H - BULAN LUAR KAWASAN | AY14: 0 | AZ14: 0 | BD14: H - BULAN LUAR KAWASAN | BE14: 0 | BF14: 0 | BJ14: H - BULAN LUAR KAWASAN | BK14: 0 | BL14: 0
B15: N11 | C15: Lobak | D15: =_xlfn.XLOOKUP($B15,'(3) SKT 51%'!$B$5:$B$40,'(3) SKT 51%'!$D$5:$D$40) -> 23141 | E15: 1 | F15: 8 | G15: 23 | H15: 1 | I15: 0 | J15: 0 | K15: 0 | L15: 0 | M15: 23108 | N15: =F15+G15+L15 -> 31 | O15: =N15/D15 -> 0.0013396137 | P15: =RANK(O15,$O$5:$O$40) -> 36 | T15: ? - TIADA CULAAN | U15: 9286 | V15: 64.37 | Z15: ? - TIADA CULAAN | AA15: 19054 | AB15: 62.28 | AF15: ? - TIADA CULAAN | AG15: 26529 | AH15: 92.53 | AL15: ? - TIADA CULAAN | AM15: 13205 | AN15: 96.61 | AR15: ? - TIADA CULAAN | AS15: 25180 | AT15: 77.3 | AX15: ? - TIADA CULAAN | AY15: 58311 | AZ15: 90.29 | BD15: ? - TIADA CULAAN | BE15: 13982 | BF15: 92.35 | BJ15: ? - TIADA CULAAN | BK15: 28795 | BL15: 98.49
B16: N12 | C16: Temiang | D16: =_xlfn.XLOOKUP($B16,'(3) SKT 51%'!$B$5:$B$40,'(3) SKT 51%'!$D$5:$D$40) -> 12975 | E16: 9 | F16: 64 | G16: 159 | H16: 284 | I16: 0 | J16: 17 | K16: 3 | L16: 0 | M16: 12439 | N16: =F16+G16+L16 -> 223 | O16: =N16/D16 -> 0.017186898 | P16: =RANK(O16,$O$5:$O$40) -> 27 | T16: JUMLAH KECIL | U16: 14427 | Z16: JUMLAH KECIL | AA16: 30593 | AF16: JUMLAH KECIL | AG16: 28671 | AL16: JUMLAH KECIL | AM16: 13669 | AR16: JUMLAH KECIL | AS16: 32575 | AX16: JUMLAH KECIL | AY16: 64582 | BD16: JUMLAH KECIL | BE16: 15141 | BJ16: JUMLAH KECIL | BK16: 29235
B17: N13 | C17: Sikamat | D17: =_xlfn.XLOOKUP($B17,'(3) SKT 51%'!$B$5:$B$40,'(3) SKT 51%'!$D$5:$D$40) -> 33885 | E17: 3998 | F17: 588 | G17: 1661 | H17: 2385 | I17: 5 | J17: 1 | K17: 0 | L17: 0 | M17: 25247 | N17: =F17+G17+L17 -> 2249 | O17: =N17/D17 -> 0.066371551 | P17: =RANK(O17,$O$5:$O$40) -> 6 | R17: 2 | S17: 02 - PERTANG | T17: A - ATAS PAGAR | U17: 2361 | V17: 18.33 | X17: 2 | Y17: 06 - PALONG | Z17: A - ATAS PAGAR | AA17: 2264 | AB17: 9.61 | AD17: 2 | AE17: 10 - NILAI | AF17: A - ATAS PAGAR | AG17: 145 | AH17: 0.32 | AJ17: 2 | AK17: 16 - SERI MENANTI | AL17: A - ATAS PAGAR | AM17: 7 | AN17: 0.07 | AP17: 2 | AQ17: 21 - BUKIT KEPAYANG | AR17: A - ATAS PAGAR | AS17: 23 | AT17: 0.05 | AV17: 2 | AW17: 26 - CHEMBONG | AX17: A - ATAS PAGAR | AY17: 30 | AZ17: 0.11 | BB17: 2 | BC17: 30 - LUKUT | BD17: A - ATAS PAGAR | BE17: 1242 | BF17: 4.43 | BH17: 2 | BI17: 35 - GEMENCHEH | BJ17: A - ATAS PAGAR | BK17: 381 | BL17: 1.53
B18: N14 | C18: Ampangan | D18: =_xlfn.XLOOKUP($B18,'(3) SKT 51%'!$B$5:$B$40,'(3) SKT 51%'!$D$5:$D$40) -> 21338 | E18: 208 | F18: 397 | G18: 408 | H18: 141 | I18: 1 | J18: 0 | K18: 3 | L18: 0 | M18: 20180 | N18: =F18+G18+L18 -> 805 | O18: =N18/D18 -> 0.037726122 | P18: =RANK(O18,$O$5:$O$40) -> 15 | T18: B - BULAN | U18: 278 | V18: 2.16 | Z18: B - BULAN | AA18: 203 | AB18: 0.86 | AF18: B - BULAN | AG18: 218 | AH18: 0.48 | AL18: B - BULAN | AM18: 176 | AN18: 1.74 | AR18: B - BULAN | AS18: 55 | AT18: 0.11 | AX18: B - BULAN | AY18: 382 | AZ18: 1.44 | BD18: B - BULAN | BE18: 172 | BF18: 0.61 | BJ18: B - BULAN | BK18: 410 | BL18: 1.65
B19: N15 | C19: Juasseh | D19: =_xlfn.XLOOKUP($B19,'(3) SKT 51%'!$B$5:$B$40,'(3) SKT 51%'!$D$5:$D$40) -> 13669 | E19: 31 | F19: 251 | G19: 79 | H19: 101 | I19: 0 | J19: 0 | K19: 2 | L19: 0 | M19: 13205 | N19: =F19+G19+L19 -> 330 | O19: =N19/D19 -> 0.02414222 | P19: =RANK(O19,$O$5:$O$40) -> 21 | T19: C - CONDONG BULAN | U19: 1143 | V19: 8.87 | Z19: C - CONDONG BULAN | AA19: 2348 | AB19: 9.97 | AF19: C - CONDONG BULAN | AG19: 655 | AH19: 1.44 | AL19: C - CONDONG BULAN | AM19: 53 | AN19: 0.52 | AR19: C - CONDONG BULAN | AS19: 67 | AT19: 0.14 | AX19: C - CONDONG BULAN | AY19: 151 | AZ19: 0.57 | BD19: C - CONDONG BULAN | BE19: 314 | BF19: 1.12 | BJ19: C - CONDONG BULAN | BK19: 253 | BL19: 1.02
B20: N16 | C20: Seri Menanti | D20: =_xlfn.XLOOKUP($B20,'(3) SKT 51%'!$B$5:$B$40,'(3) SKT 51%'!$D$5:$D$40) -> 10100 | E20: 7 | F20: 176 | G20: 53 | H20: 30 | I20: 2 | J20: 2 | K20: 0 | L20: 0 | M20: 9830 | N20: =F20+G20+L20 -> 229 | O20: =N20/D20 -> 0.022673267 | P20: =RANK(O20,$O$5:$O$40) -> 22 | T20: D - DACING | U20: 2826 | V20: 21.94 | Z20: D - DACING | AA20: 7086 | AB20: 30.09 | AF20: D - DACING | AG20: 141 | AH20: 0.31 | AL20: D - DACING | AM20: 30 | AN20: 0.3 | AR20: D - DACING | AS20: 14 | AT20: 0.03 | AX20: D - DACING | AY20: 548 | AZ20: 2.07 | BD20: D - DACING | BE20: 210 | BF20: 0.75 | BJ20: D - DACING | BK20: 78 | BL20: 0.31
B21: N17 | C21: Senaling | D21: =_xlfn.XLOOKUP($B21,'(3) SKT 51%'!$B$5:$B$40,'(3) SKT 51%'!$D$5:$D$40) -> 9914 | E21: 22 | F21: 208 | G21: 54 | H21: 43 | I21: 2 | J21: 4 | K21: 1 | L21: 1 | M21: 9579 | N21: =F21+G21+L21 -> 263 | O21: =N21/D21 -> 0.026528142 | P21: =RANK(O21,$O$5:$O$40) -> 18 | T21: E - CONDONG DACING | U21: 0 | V21: 0 | Z21: E - CONDONG DACING | AA21: 0 | AB21: 0 | AF21: E - CONDONG DACING | AG21: 37 | AH21: 0.08 | AL21: E - CONDONG DACING | AM21: 2 | AN21: 0.02 | AR21: E - CONDONG DACING | AS21: 0 | AT21: 0 | AX21: E - CONDONG DACING | AY21: 0 | AZ21: 0 | BD21: E - CONDONG DACING | BE21: 115 | BF21: 0.41 | BJ21: E - CONDONG DACING | BK21: 77 | BL21: 0.31
B22: N18 | C22: Pilah | D22: =_xlfn.XLOOKUP($B22,'(3) SKT 51%'!$B$5:$B$40,'(3) SKT 51%'!$D$5:$D$40) -> 17963 | E22: 429 | F22: 258 | G22: 89 | H22: 142 | I22: 8 | J22: 20 | K22: 0 | L22: 0 | M22: 17017 | N22: =F22+G22+L22 -> 347 | O22: =N22/D22 -> 0.019317486 | P22: =RANK(O22,$O$5:$O$40) -> 24 | T22: F - GAGAL DIKESAN | U22: 0 | V22: 0 | Z22: F - GAGAL DIKESAN | AA22: 0 | AB22: 0 | AF22: F - GAGAL DIKESAN | AG22: 27 | AH22: 0.06 | AL22: F - GAGAL DIKESAN | AM22: 2 | AN22: 0.02 | AR22: F - GAGAL DIKESAN | AS22: 0 | AT22: 0 | AX22: F - GAGAL DIKESAN | AY22: 0 | AZ22: 0 | BD22: F - GAGAL DIKESAN | BE22: 17 | BF22: 0.06 | BJ22: F - GAGAL DIKESAN | BK22: 7 | BL22: 0.03
B23: N19 | C23: Johol | D23: =_xlfn.XLOOKUP($B23,'(3) SKT 51%'!$B$5:$B$40,'(3) SKT 51%'!$D$5:$D$40) -> 12359 | E23: 453 | F23: 472 | G23: 240 | H23: 540 | I23: 212 | J23: 1 | K23: 20 | L23: 1 | M23: 10420 | N23: =F23+G23+L23 -> 713 | O23: =N23/D23 -> 0.057690752 | P23: =RANK(O23,$O$5:$O$40) -> 9 | T23: G - MATI | U23: 6 | V23: 0.05 | Z23: G - MATI | AA23: 0 | AB23: 0 | AF23: G - MATI | AG23: 0 | AH23: 0 | AL23: G - MATI | AM23: 0 | AN23: 0 | AR23: G - MATI | AS23: 0 | AT23: 0 | AX23: G - MATI | AY23: 0 | AZ23: 0 | BD23: G - MATI | BE23: 0 | BF23: 0 | BJ23: G - MATI | BK23: 5 | BL23: 0.02
B24: N20 | C24: Labu | D24: =_xlfn.XLOOKUP($B24,'(3) SKT 51%'!$B$5:$B$40,'(3) SKT 51%'!$D$5:$D$40) -> 32575 | E24: 2861 | F24: 697 | G24: 958 | H24: 2828 | I24: 3 | J24: 41 | K24: 5 | L24: 2 | M24: 25180 | N24: =F24+G24+L24 -> 1657 | O24: =N24/D24 -> 0.050867229 | P24: =RANK(O24,$O$5:$O$40) -> 11 | T24: H - BULAN LUAR KAWASAN | U24: 0 | V24: 0 | Z24: H - BULAN LUAR KAWASAN | AA24: 0 | AB24: 0 | AF24: H - BULAN LUAR KAWASAN | AG24: 0 | AH24: 0 | AL24: H - BULAN LUAR KAWASAN | AM24: 0 | AN24: 0 | AR24: H - BULAN LUAR KAWASAN | AS24: 0 | AT24: 0 | AX24: H - BULAN LUAR KAWASAN | AY24: 1 | AZ24: 0 | BD24: H - BULAN LUAR KAWASAN | BE24: 0 | BF24: 0 | BJ24: H - BULAN LUAR KAWASAN | BK24: 1 | BL24: 0
B25: N21 | C25: Bukit Kepayang | D25: =_xlfn.XLOOKUP($B25,'(3) SKT 51%'!$B$5:$B$40,'(3) SKT 51%'!$D$5:$D$40) -> 49248 | E25: 23 | F25: 55 | G25: 67 | H25: 14 | I25: 0 | J25: 0 | K25: 0 | L25: 0 | M25: 49089 | N25: =F25+G25+L25 -> 122 | O25: =N25/D25 -> 0.002477258 | P25: =RANK(O25,$O$5:$O$40) -> 34 | T25: ? - TIADA CULAAN | U25: 6266 | V25: 48.65 | Z25: ? - TIADA CULAAN | AA25: 11647 | AB25: 49.46 | AF25: ? - TIADA CULAAN | AG25: 44264 | AH25: 97.31 | AL25: ? - TIADA CULAAN | AM25: 9830 | AN25: 97.33 | AR25: ? - TIADA CULAAN | AS25: 49089 | AT25: 99.68 | AX25: ? - TIADA CULAAN | AY25: 25328 | AZ25: 95.79 | BD25: ? - TIADA CULAAN | BE25: 25940 | BF25: 92.61 | BJ25: ? - TIADA CULAAN | BK25: 23666 | BL25: 95.13
B26: N22 | C26: Rahang | D26: =_xlfn.XLOOKUP($B26,'(3) SKT 51%'!$B$5:$B$40,'(3) SKT 51%'!$D$5:$D$40) -> 19608 | E26: 29 | F26: 66 | G26: 92 | H26: 10 | I26: 0 | J26: 0 | K26: 0 | L26: 0 | M26: 19411 | N26: =F26+G26+L26 -> 158 | O26: =N26/D26 -> 0.0080579355 | P26: =RANK(O26,$O$5:$O$40) -> 31 | T26: JUMLAH KECIL | U26: 12880 | Z26: JUMLAH KECIL | AA26: 23548 | AF26: JUMLAH KECIL | AG26: 45487 | AL26: JUMLAH KECIL | AM26: 10100 | AR26: JUMLAH KECIL | AS26: 49248 | AX26: JUMLAH KECIL | AY26: 26440 | BD26: JUMLAH KECIL | BE26: 28010 | BJ26: JUMLAH KECIL | BK26: 24878
B27: N23 | C27: Mambau | D27: =_xlfn.XLOOKUP($B27,'(3) SKT 51%'!$B$5:$B$40,'(3) SKT 51%'!$D$5:$D$40) -> 30316 | E27: 3 | F27: 34 | G27: 32 | H27: 1 | I27: 0 | J27: 0 | K27: 0 | L27: 0 | M27: 30246 | N27: =F27+G27+L27 -> 66 | O27: =N27/D27 -> 0.0021770682 | P27: =RANK(O27,$O$5:$O$40) -> 35 | R27: 3 | S27: 03 - SUNGAI LUI | T27: A - ATAS PAGAR | U27: 3153 | V27: 16 | X27: 3 | Y27: 07 - JERAM PADANG | Z27: A - ATAS PAGAR | AA27: 1036 | AB27: 6.26 | AD27: 3 | AE27: 11 - LOBAK | AF27: A - ATAS PAGAR | AG27: 1 | AH27: 0 | AJ27: 3 | AK27: 17 - SENALING | AL27: A - ATAS PAGAR | AM27: 22 | AN27: 0.22 | AP27: 3 | AQ27: 22 - RAHANG | AR27: A - ATAS PAGAR | AS27: 29 | AT27: 0.15 | AV27: 3 | AW27: 27 - RANTAU | AX27: A - ATAS PAGAR | AY27: 163 | AZ27: 0.47 | BB27: 3 | BC27: 31 - BAGAN PINANG | BD27: A - ATAS PAGAR | BE27: 9805 | BF27: 35.11 | BH27: 3 | BI27: 36 - REPAH | BJ27: A - ATAS PAGAR | BK27: 120 | BL27: 0.43
B28: N24 | C28: Seremban Jaya | D28: =_xlfn.XLOOKUP($B28,'(3) SKT 51%'!$B$5:$B$40,'(3) SKT 51%'!$D$5:$D$40) -> 32899 | E28: 9 | F28: 56 | G28: 74 | H28: 12 | I28: 0 | J28: 0 | K28: 0 | L28: 0 | M28: 32748 | N28: =F28+G28+L28 -> 130 | O28: =N28/D28 -> 0.0039514879 | P28: =RANK(O28,$O$5:$O$40) -> 33 | T28: B - BULAN | U28: 505 | V28: 2.56 | Z28: B - BULAN | AA28: 93 | AB28: 0.56 | AF28: B - BULAN | AG28: 8 | AH28: 0.03 | AL28: B - BULAN | AM28: 208 | AN28: 2.1 | AR28: B - BULAN | AS28: 66 | AT28: 0.34 | AX28: B - BULAN | AY28: 211 | AZ28: 0.61 | BD28: B - BULAN | BE28: 405 | BF28: 1.45 | BJ28: B - BULAN | BK28: 162 | BL28: 0.58
B29: N25 | C29: Paroi | D29: =_xlfn.XLOOKUP($B29,'(3) SKT 51%'!$B$5:$B$40,'(3) SKT 51%'!$D$5:$D$40) -> 64582 | E29: 561 | F29: 1089 | G29: 2179 | H29: 2393 | I29: 26 | J29: 23 | K29: 0 | L29: 0 | M29: 58311 | N29: =F29+G29+L29 -> 3268 | O29: =N29/D29 -> 0.050602335 | P29: =RANK(O29,$O$5:$O$40) -> 12 | T29: C - CONDONG BULAN | U29: 4375 | V29: 22.2 | Z29: C - CONDONG BULAN | AA29: 975 | AB29: 5.9 | AF29: C - CONDONG BULAN | AG29: 23 | AH29: 0.1 | AL29: C - CONDONG BULAN | AM29: 54 | AN29: 0.54 | AR29: C - CONDONG BULAN | AS29: 92 | AT29: 0.47 | AX29: C - CONDONG BULAN | AY29: 208 | AZ29: 0.6 | BD29: C - CONDONG BULAN | BE29: 268 | BF29: 0.96 | BJ29: C - CONDONG BULAN | BK29: 76 | BL29: 0.27
B30: N26 | C30: Chembong | D30: =_xlfn.XLOOKUP($B30,'(3) SKT 51%'!$B$5:$B$40,'(3) SKT 51%'!$D$5:$D$40) -> 26440 | E30: 30 | F30: 382 | G30: 151 | H30: 548 | I30: 0 | J30: 0 | K30: 0 | L30: 1 | M30: 25328 | N30: =F30+G30+L30 -> 534 | O30: =N30/D30 -> 0.020196672 | P30: =RANK(O30,$O$5:$O$40) -> 23 | T30: D - DACING | U30: 2393 | V30: 12.14 | Z30: D - DACING | AA30: 2536 | AB30: 15.33 | AF30: D - DACING | AG30: 1 | AH30: 0 | AL30: D - DACING | AM30: 43 | AN30: 0.43 | AR30: D - DACING | AS30: 10 | AT30: 0.05 | AX30: D - DACING | AY30: 88 | AZ30: 0.25 | BD30: D - DACING | BE30: 526 | BF30: 1.88 | BJ30: D - DACING | BK30: 229 | BL30: 0.82
B31: N27 | C31: Rantau | D31: =_xlfn.XLOOKUP($B31,'(3) SKT 51%'!$B$5:$B$40,'(3) SKT 51%'!$D$5:$D$40) -> 34636 | E31: 163 | F31: 211 | G31: 208 | H31: 88 | I31: 0 | J31: 27 | K31: 0 | L31: 0 | M31: 33939 | N31: =F31+G31+L31 -> 419 | O31: =N31/D31 -> 0.01209724 | P31: =RANK(O31,$O$5:$O$40) -> 28 | T31: E - CONDONG DACING | U31: 2 | V31: 0.01 | Z31: E - CONDONG DACING | AA31: 0 | AB31: 0 | AF31: E - CONDONG DACING | AG31: 0 | AH31: 0 | AL31: E - CONDONG DACING | AM31: 2 | AN31: 0.02 | AR31: E - CONDONG DACING | AS31: 0 | AT31: 0 | AX31: E - CONDONG DACING | AY31: 0 | AZ31: 0 | BD31: E - CONDONG DACING | BE31: 31 | BF31: 0.11 | BJ31: E - CONDONG DACING | BK31: 5 | BL31: 0.02
B32: N28 | C32: Kota | D32: =_xlfn.XLOOKUP($B32,'(3) SKT 51%'!$B$5:$B$40,'(3) SKT 51%'!$D$5:$D$40) -> 16730 | E32: 92 | F32: 247 | G32: 187 | H32: 566 | I32: 0 | J32: 17 | K32: 4 | L32: 1 | M32: 15616 | N32: =F32+G32+L32 -> 435 | O32: =N32/D32 -> 0.026001195 | P32: =RANK(O32,$O$5:$O$40) -> 19 | T32: F - GAGAL DIKESAN | U32: 1 | V32: 0.01 | Z32: F - GAGAL DIKESAN | AA32: 0 | AB32: 0 | AF32: F - GAGAL DIKESAN | AG32: 0 | AH32: 0 | AL32: F - GAGAL DIKESAN | AM32: 4 | AN32: 0.04 | AR32: F - GAGAL DIKESAN | AS32: 0 | AT32: 0 | AX32: F - GAGAL DIKESAN | AY32: 27 | AZ32: 0.08 | BD32: F - GAGAL DIKESAN | BE32: 3 | BF32: 0.01 | BJ32: F - GAGAL DIKESAN | BK32: 6 | BL32: 0.02
B33: N29 | C33: Chuah | D33: =_xlfn.XLOOKUP($B33,'(3) SKT 51%'!$B$5:$B$40,'(3) SKT 51%'!$D$5:$D$40) -> 15141 | E33: 584 | F33: 72 | G33: 31 | H33: 465 | I33: 1 | J33: 3 | K33: 3 | L33: 0 | M33: 13982 | N33: =F33+G33+L33 -> 103 | O33: =N33/D33 -> 0.0068027211 | P33: =RANK(O33,$O$5:$O$40) -> 32 | T33: G - MATI | U33: 1 | V33: 0.01 | Z33: G - MATI | AA33: 0 | AB33: 0 | AF33: G - MATI | AG33: 0 | AH33: 0 | AL33: G - MATI | AM33: 1 | AN33: 0.01 | AR33: G - MATI | AS33: 0 | AT33: 0 | AX33: G - MATI | AY33: 0 | AZ33: 0 | BD33: G - MATI | BE33: 2 | BF33: 0.01 | BJ33: G - MATI | BK33: 1 | BL33: 0
B34: N30 | C34: Lukut | D34: =_xlfn.XLOOKUP($B34,'(3) SKT 51%'!$B$5:$B$40,'(3) SKT 51%'!$D$5:$D$40) -> 28010 | E34: 1242 | F34: 172 | G34: 314 | H34: 210 | I34: 115 | J34: 17 | K34: 0 | L34: 0 | M34: 25940 | N34: =F34+G34+L34 -> 486 | O34: =N34/D34 -> 0.017350946 | P34: =RANK(O34,$O$5:$O$40) -> 26 | T34: H - BULAN LUAR KAWASAN | U34: 0 | V34: 0 | Z34: H - BULAN LUAR KAWASAN | AA34: 0 | AB34: 0 | AF34: H - BULAN LUAR KAWASAN | AG34: 0 | AH34: 0 | AL34: H - BULAN LUAR KAWASAN | AM34: 1 | AN34: 0.01 | AR34: H - BULAN LUAR KAWASAN | AS34: 0 | AT34: 0 | AX34: H - BULAN LUAR KAWASAN | AY34: 0 | AZ34: 0 | BD34: H - BULAN LUAR KAWASAN | BE34: 4 | BF34: 0.01 | BJ34: H - BULAN LUAR KAWASAN | BK34: 1 | BL34: 0
B35: N31 | C35: Bagan Pinang | D35: =_xlfn.XLOOKUP($B35,'(3) SKT 51%'!$B$5:$B$40,'(3) SKT 51%'!$D$5:$D$40) -> 27926 | E35: 9805 | F35: 405 | G35: 268 | H35: 526 | I35: 31 | J35: 3 | K35: 2 | L35: 4 | M35: 16882 | N35: =F35+G35+L35 -> 677 | O35: =N35/D35 -> 0.024242641 | P35: =RANK(O35,$O$5:$O$40) -> 20 | T35: ? - TIADA CULAAN | U35: 9281 | V35: 47.09 | Z35: ? - TIADA CULAAN | AA35: 11899 | AB35: 71.95 | AF35: ? - TIADA CULAAN | AG35: 23108 | AH35: 99.86 | AL35: ? - TIADA CULAAN | AM35: 9579 | AN35: 96.62 | AR35: ? - TIADA CULAAN | AS35: 19411 | AT35: 99 | AX35: ? - TIADA CULAAN | AY35: 33939 | AZ35: 97.99 | BD35: ? - TIADA CULAAN | BE35: 16882 | BF35: 60.45 | BJ35: ? - TIADA CULAAN | BK35: 27230 | BL35: 97.84
B36: N32 | C36: Linggi | D36: =_xlfn.XLOOKUP($B36,'(3) SKT 51%'!$B$5:$B$40,'(3) SKT 51%'!$D$5:$D$40) -> 20768 | E36: 2375 | F36: 946 | G36: 180 | H36: 1143 | I36: 0 | J36: 1 | K36: 0 | L36: 2 | M36: 16121 | N36: =F36+G36+L36 -> 1128 | O36: =N36/D36 -> 0.05431433 | P36: =RANK(O36,$O$5:$O$40) -> 10 | T36: JUMLAH KECIL | U36: 19711 | Z36: JUMLAH KECIL | AA36: 16539 | AF36: JUMLAH KECIL | AG36: 23141 | AL36: JUMLAH KECIL | AM36: 9914 | AR36: JUMLAH KECIL | AS36: 19608 | AX36: JUMLAH KECIL | AY36: 34636 | BD36: JUMLAH KECIL | BE36: 27926 | BJ36: JUMLAH KECIL | BK36: 27830
B37: N33 | C37: Sri Tanjung | D37: =_xlfn.XLOOKUP($B37,'(3) SKT 51%'!$B$5:$B$40,'(3) SKT 51%'!$D$5:$D$40) -> 19585 | E37: 1335 | F37: 681 | G37: 121 | H37: 632 | I37: 30 | J37: 0 | K37: 0 | L37: 0 | M37: 16786 | N37: =F37+G37+L37 -> 802 | O37: =N37/D37 -> 0.040949706 | P37: =RANK(O37,$O$5:$O$40) -> 13 | R37: 4 | S37: 04 - KLAWANG | T37: A - ATAS PAGAR | U37: 2494 | V37: 18.71 | X37: 4 | Y37: 08 - BAHAU | Z37: A - ATAS PAGAR | AA37: 767 | AB37: 2.96 | AD37: 4 | AE37: 12 - TEMIANG | AF37: A - ATAS PAGAR | AG37: 9 | AH37: 0.07 | AJ37: 4 | AK37: 18 - PILAH | AL37: A - ATAS PAGAR | AM37: 429 | AN37: 2.39 | AP37: 4 | AQ37: 23 - MAMBAU | AR37: A - ATAS PAGAR | AS37: 3 | AT37: 0.01 | AV37: 4 | AW37: 28 - KOTA | AX37: A - ATAS PAGAR | AY37: 92 | AZ37: 0.55 | BB37: 4 | BC37: 32 - LINGGI | BD37: A - ATAS PAGAR | BE37: 2375 | BF37: 11.44 | BJ37: JUMLAH BESAR | BK37: 81943
B38: N34 | C38: Gemas | D38: =_xlfn.XLOOKUP($B38,'(3) SKT 51%'!$B$5:$B$40,'(3) SKT 51%'!$D$5:$D$40) -> 29235 | E38: 43 | F38: 270 | G38: 80 | H38: 40 | I38: 7 | J38: 0 | K38: 0 | L38: 0 | M38: 28795 | N38: =F38+G38+L38 -> 350 | O38: =N38/D38 -> 0.011971951 | P38: =RANK(O38,$O$5:$O$40) -> 29 | T38: B - BULAN | U38: 24 | V38: 0.18 | Z38: B - BULAN | AA38: 201 | AB38: 0.77 | AF38: B - BULAN | AG38: 64 | AH38: 0.49 | AL38: B - BULAN | AM38: 258 | AN38: 1.44 | AR38: B - BULAN | AS38: 34 | AT38: 0.11 | AX38: B - BULAN | AY38: 247 | AZ38: 1.48 | BD38: B - BULAN | BE38: 946 | BF38: 4.56
B39: N35 | C39: Gemencheh | D39: =_xlfn.XLOOKUP($B39,'(3) SKT 51%'!$B$5:$B$40,'(3) SKT 51%'!$D$5:$D$40) -> 24878 | E39: 381 | F39: 410 | G39: 253 | H39: 78 | I39: 77 | J39: 7 | K39: 5 | L39: 1 | M39: 23666 | N39: =F39+G39+L39 -> 664 | O39: =N39/D39 -> 0.026690248 | P39: =RANK(O39,$O$5:$O$40) -> 17 | T39: C - CONDONG BULAN | U39: 2322 | V39: 17.42 | Z39: C - CONDONG BULAN | AA39: 838 | AB39: 3.23 | AF39: C - CONDONG BULAN | AG39: 159 | AH39: 1.23 | AL39: C - CONDONG BULAN | AM39: 89 | AN39: 0.5 | AR39: C - CONDONG BULAN | AS39: 32 | AT39: 0.11 | AX39: C - CONDONG BULAN | AY39: 187 | AZ39: 1.12 | BD39: C - CONDONG BULAN | BE39: 180 | BF39: 0.87
B40: N36 | C40: Repah | D40: =_xlfn.XLOOKUP($B40,'(3) SKT 51%'!$B$5:$B$40,'(3) SKT 51%'!$D$5:$D$40) -> 27830 | E40: 120 | F40: 162 | G40: 76 | H40: 229 | I40: 5 | J40: 6 | K40: 1 | L40: 1 | M40: 27230 | N40: =F40+G40+L40 -> 239 | O40: =N40/D40 -> 0.0085878548 | P40: =RANK(O40,$O$5:$O$40) -> 30 | T40: D - DACING | U40: 2050 | V40: 15.38 | Z40: D - DACING | AA40: 2014 | AB40: 7.76 | AF40: D - DACING | AG40: 284 | AH40: 2.19 | AL40: D - DACING | AM40: 142 | AN40: 0.79 | AR40: D - DACING | AS40: 1 | AT40: 0 | AX40: D - DACING | AY40: 566 | AZ40: 3.38 | BD40: D - DACING | BE40: 1143 | BF40: 5.5
T41: E - CONDONG DACING | U41: 0 | V41: 0 | Z41: E - CONDONG DACING | AA41: 1 | AB41: 0 | AF41: E - CONDONG DACING | AG41: 0 | AH41: 0 | AL41: E - CONDONG DACING | AM41: 8 | AN41: 0.04 | AR41: E - CONDONG DACING | AS41: 0 | AT41: 0 | AX41: E - CONDONG DACING | AY41: 0 | AZ41: 0 | BD41: E - CONDONG DACING | BE41: 0 | BF41: 0
T42: F - GAGAL DIKESAN | U42: 0 | V42: 0 | Z42: F - GAGAL DIKESAN | AA42: 0 | AB42: 0 | AF42: F - GAGAL DIKESAN | AG42: 17 | AH42: 0.13 | AL42: F - GAGAL DIKESAN | AM42: 20 | AN42: 0.11 | AR42: F - GAGAL DIKESAN | AS42: 0 | AT42: 0 | AX42: F - GAGAL DIKESAN | AY42: 17 | AZ42: 0.1 | BD42: F - GAGAL DIKESAN | BE42: 1 | BF42: 0
...

Sheet (6) Perbezaan pengundi
B2: RANKING PENINGKATAN BILANGAN PENGUNDI MENGIKUT KERUSI DUN N9
B4: Kod | C4: DUN | D4: Jumlah Pengundi (PRU15) | E4: Jumlah Pengundi (DPI Dis 2025) | F4: Perbezaan | G4: Ranking Perbezaan
B5: N25 | C5: Paroi | D5: 60704 | E5: 64582 | F5: 3878 | G5: =RANK(F5,$F$5:$F$40) -> 1
B6: N10 | C6: Nilai | D6: 42168 | E6: 45487 | F6: 3319 | G6: =RANK(F6,$F$5:$F$40) -> 2
B7: N21 | C7: Bukit Kepayang | D7: 46229 | E7: 49248 | F7: 3019 | G7: =RANK(F7,$F$5:$F$40) -> 3
B8: N20 | C8: Labu | D8: 30478 | E8: 32575 | F8: 2097 | G8: =RANK(F8,$F$5:$F$40) -> 4
B9: N27 | C9: Rantau | D9: 32890 | E9: 34636 | F9: 1746 | G9: =RANK(F9,$F$5:$F$40) -> 5
B10: N13 | C10: Sikamat | D10: 32343 | E10: 33885 | F10: 1542 | G10: =RANK(F10,$F$5:$F$40) -> 6
B11: N23 | C11: Mambau | D11: 28952 | E11: 30316 | F11: 1364 | G11: =RANK(F11,$F$5:$F$40) -> 7
B12: N09 | C12: Lenggeng | D12: 27386 | E12: 28671 | F12: 1285 | G12: =RANK(F12,$F$5:$F$40) -> 8
B13: N30 | C13: Lukut | D13: 26806 | E13: 28010 | F13: 1204 | G13: =RANK(F13,$F$5:$F$40) -> 9
B14: N26 | C14: Chembong | D14: 25625 | E14: 26440 | F14: 815 | G14: =RANK(F14,$F$5:$F$40) -> 10
B15: N24 | C15: Seremban Jaya | D15: 32290 | E15: 32899 | F15: 609 | G15: =RANK(F15,$F$5:$F$40) -> 11
B16: N36 | C16: Repah | D16: 27284 | E16: 27830 | F16: 546 | G16: =RANK(F16,$F$5:$F$40) -> 12
... B40: N22 | C40: Rahang | D40: 20182 | E40: 19608 | F40: -574 | G40: =RANK(F40,$F$5:$F$40) -> 36

Sheet (7) Cula vs SKT
B1: Kod | C1: DUN | D1: Jumlah Pengundi PAS (cula) | E1: SKT 51% | F1: Baki Kena Cari (BKC) | G1: Ranking
B2: N03 | C2: N03 Sungai Lui | D2: =INDEX('(5) Cula'!$N$5:$N$40,MATCH($B2,'(5) Cula'!$B$5:$B$40,0)) -> 4880 | E2: 6836 | F2: =D2-E2 -> -1956 | G2: 1
B3: N04 | C3: N04 Klawang | D3: =INDEX('(5) Cula'!$N$5:$N$40,MATCH($B3,'(5) Cula'!$B$5:$B$40,0)) -> 2346 | E3: 4623 | F3: =D3-E3 -> -2277 | G3: 2
B4: N02 | C4: N02 Pertang | D4: =INDEX('(5) Cula'!$N$5:$N$40,MATCH($B4,'(5) Cula'!$B$5:$B$40,0)) -> 1421 | E4: 4467 | F4: =D4-E4 -> -3046 | G4: 3
B5: N17 | C5: N17 Senaling | D5: =INDEX('(5) Cula'!$N$5:$N$40,MATCH($B5,'(5) Cula'!$B$5:$B$40,0)) -> 263 | E5: 3438 | F5: =D5-E5 -> -3175 | G5: 4
B6: N16 | C6: N16 Seri Menanti | D6: =INDEX('(5) Cula'!$N$5:$N$40,MATCH($B6,'(5) Cula'!$B$5:$B$40,0)) -> 229 | E6: 3503 | F6: =D6-E6 -> -3274 | G6: 5
B7: N19 | C7: N19 Johol | D7: =INDEX('(5) Cula'!$N$5:$N$40,MATCH($B7,'(5) Cula'!$B$5:$B$40,0)) -> 713 | E7: 4286 | F7: =D7-E7 -> -3573 | G7: 6
B8: N01 | C8: N01 Chennah | D8: =INDEX('(5) Cula'!$N$5:$N$40,MATCH($B8,'(5) Cula'!$B$5:$B$40,0)) -> 923 | E8: 5003 | F8: =D8-E8 -> -4080 | G8: 7
B9: N12 | C9: N12 Temiang | D9: =INDEX('(5) Cula'!$N$5:$N$40,MATCH($B9,'(5) Cula'!$B$5:$B$40,0)) -> 223 | E9: 4500 | F9: =D9-E9 -> -4277 | G9: 8
B10: N15 | C10: N15 Juasseh | D10: =INDEX('(5) Cula'!$N$5:$N$40,MATCH($B10,'(5) Cula'!$B$5:$B$40,0)) -> 330 | E10: 4740 | F10: =D10-E10 -> -4410 | G10: 9
B11: N07 | C11: N07 Jeram Padang | D11: =INDEX('(5) Cula'!$N$5:$N$40,MATCH($B11,'(5) Cula'!$B$5:$B$40,0)) -> 1068 | E11: 5736 | F11: =D11-E11 -> -4668 | G11: 10
B12: N29 | C12: N29 Chuah | D12: =INDEX('(5) Cula'!$N$5:$N$40,MATCH($B12,'(5) Cula'!$B$5:$B$40,0)) -> 103 | E12: 5251 | F12: =D12-E12 -> -5148 | G12: 11
