Workbook

Sheet Demogradi semua DUN
B1: Kod | C1: DUN | D1: Pengundi (DPI Dec 2025) | E1: Majoriti PRU15 | F1: Jantina | H1: Umur (Umur pada 11/6/2026) | N1: Bangsa
F2: Lelaki | G2: Perempuan | H2: 18-20 Thn | I2: 21-25 Thn | J2: 26-40 Thn | K2: 41-60 Thn | L2: 61-999 Thn | M2: Tak Diketahui | N2: MELAYU | O2: CINA | P2: INDIA | Q2: LAIN-LAIN
B3: N01 | C3: =INDEX('[1](2) Pengundi & % Melayu'!$C$5:$C$40,MATCH($D3,'[1](2) Pengundi & % Melayu'!$B$5:$B$40,0)) -> Chennah | D3: =INDEX('[1](2) Pengundi & % Melayu'!$D$5:$D$40,MATCH($D3,'[1](2) Pengundi & % Melayu'!$B$5:$B$40,0)) -> 14427 | E3: =INDEX('[1](1) Majoriti'!$I$4:$I$39,MATCH($D3,'[1](1) Majoriti'!$B$4:$B$39,0)) -> -2200 | F3: =Jelebu!D13+Jelebu!J13+Jelebu!P13+Jelebu!V13+Jelebu!AB13+Jelebu!AH13 -> 7422 | G3: =Jelebu!F13+Jelebu!L13+Jelebu!R13+Jelebu!X13+Jelebu!AD13+Jelebu!AJ13 -> 7005 | H3: =Jelebu!H13 -> 572 | I3: =Jelebu!N13 -> 1105 | J3: =Jelebu!T13 -> 4040 | K3: =Jelebu!Z13 -> 4987 | L3: =Jelebu!AF13 -> 3723 | M3: =Jelebu!AL13 -> 0 | N3: =Jelebu!AN9 -> 7479 | O3: =Jelebu!AN10 -> 6630 | P3: =Jelebu!AN11 -> 318 | Q3: =Jelebu!AN12 -> 0
B4: N02 | C4: =INDEX('[1](2) Pengundi & % Melayu'!$C$5:$C$40,MATCH($D4,'[1](2) Pengundi & % Melayu'!$B$5:$B$40,0)) -> Pertang | D4: =INDEX('[1](2) Pengundi & % Melayu'!$D$5:$D$40,MATCH($D4,'[1](2) Pengundi & % Melayu'!$B$5:$B$40,0)) -> 12880 | E4: =INDEX('[1](1) Majoriti'!$I$4:$I$39,MATCH($D4,'[1](1) Majoriti'!$B$4:$B$39,0)) -> -2790 | F4: =Jelebu!D27+Jelebu!J27+Jelebu!P27+Jelebu!V27+Jelebu!AB27+Jelebu!AH27 -> 6523 | G4: =Jelebu!F27+Jelebu!L27+Jelebu!R27+Jelebu!X27+Jelebu!AD27+Jelebu!AJ27 -> 6357 | H4: =Jelebu!H27 -> 503 | I4: =Jelebu!N27 -> 1035 | J4: =Jelebu!T27 -> 3834 | K4: =Jelebu!Z27 -> 4767 | L4: =Jelebu!AF27 -> 2741 | M4: =Jelebu!AL27 -> 0 | N4: =Jelebu!AN23 -> 9201 | O4: =Jelebu!AN24 -> 2842 | P4: =Jelebu!AN25 -> 837 | Q4: =Jelebu!AN26 -> 0
B5: N03 | C5: =INDEX('[1](2) Pengundi & % Melayu'!$C$5:$C$40,MATCH($D5,'[1](2) Pengundi & % Melayu'!$B$5:$B$40,0)) -> Sungai Lui | D5: =INDEX('[1](2) Pengundi & % Melayu'!$D$5:$D$40,MATCH($D5,'[1](2) Pengundi & % Melayu'!$B$5:$B$40,0)) -> 19711 | E5: =INDEX('[1](1) Majoriti'!$I$4:$I$39,MATCH($D5,'[1](1) Majoriti'!$B$4:$B$39,0)) -> -535 | F5: =Jelebu!D41+Jelebu!J41+Jelebu!P41+Jelebu!V41+Jelebu!AB41+Jelebu!AH41 -> 9851 | G5: =Jelebu!F41+Jelebu!L41+Jelebu!R41+Jelebu!X41+Jelebu!AD41+Jelebu!AJ41 -> 9860 | H5: =Jelebu!H41 -> 864 | I5: =Jelebu!N41 -> 1646 | J5: =Jelebu!T41 -> 6919 | K5: =Jelebu!Z41 -> 6566 | L5: =Jelebu!AF41 -> 3716 | M5: =Jelebu!AL41 -> 0 | N5: =Jelebu!AN37 -> 16721 | O5: =Jelebu!AN38 -> 1417 | P5: =Jelebu!AN39 -> 1573 | Q5: =Jelebu!AN40 -> 0
B6: N04 | C6: =INDEX('[1](2) Pengundi & % Melayu'!$C$5:$C$40,MATCH($D6,'[1](2) Pengundi & % Melayu'!$B$5:$B$40,0)) -> Klawang | D6: =INDEX('[1](2) Pengundi & % Melayu'!$D$5:$D$40,MATCH($D6,'[1](2) Pengundi & % Melayu'!$B$5:$B$40,0)) -> 13329 | E6: =INDEX('[1](1) Majoriti'!$I$4:$I$39,MATCH($D6,'[1](1) Majoriti'!$B$4:$B$39,0)) -> -577 | F6: =Jelebu!D55+Jelebu!J55+Jelebu!P55+Jelebu!V55+Jelebu!AB55+Jelebu!AH55 -> 6676 | G6: =Jelebu!F55+Jelebu!L55+Jelebu!R55+Jelebu!X55+Jelebu!AD55+Jelebu!AJ55 -> 6653 | H6: =Jelebu!H55 -> 639 | I6: =Jelebu!N55 -> 1221 | J6: =Jelebu!T55 -> 4067 | K6: =Jelebu!Z55 -> 4232 | L6: =Jelebu!AF55 -> 3170 | M6: =Jelebu!AL55 -> 0 | N6: =Jelebu!AN51 -> 9044 | O6: =Jelebu!AN52 -> 3818 | P6: =Jelebu!AN53 -> 465 | Q6: =Jelebu!AN54 -> 2
B7: N05 | C7: =INDEX('[1](2) Pengundi & % Melayu'!$C$5:$C$40,MATCH($D7,'[1](2) Pengundi & % Melayu'!$B$5:$B$40,0)) -> Serting | D7: =INDEX('[1](2) Pengundi & % Melayu'!$D$5:$D$40,MATCH($D7,'[1](2) Pengundi & % Melayu'!$B$5:$B$40,0)) -> 30593 | E7: =INDEX('[1](1) Majoriti'!$I$4:$I$39,MATCH($D7,'[1](1) Majoriti'!$B$4:$B$39,0)) -> 843 | F7: =Jempol!D13+Jempol!J13+Jempol!P13+Jempol!V13+Jempol!AB13+Jempol!AH13 -> 14949 | G7: =Jempol!F13+Jempol!L13+Jempol!R13+Jempol!X13+Jempol!AD13+Jempol!AJ13 -> 15644 | H7: =Jempol!H13 -> 1251 | I7: =Jempol!N13 -> 2626 | J7: =Jempol!T13 -> 12688 | K7: =Jempol!Z13 -> 8083 | L7: =Jempol!AF13 -> 5945 | M7: =Jempol!AL13 -> 0 | N7: =Jempol!AN9 -> 24322 | O7: =Jempol!AN10 -> 3845 | P7: =Jempol!AN11 -> 2426 | Q7: =Jempol!AN12 -> 0
B8: N06 | C8: =INDEX('[1](2) Pengundi & % Melayu'!$C$5:$C$40,MATCH($D8,'[1](2) Pengundi & % Melayu'!$B$5:$B$40,0)) -> Palong | D8: =INDEX('[1](2) Pengundi & % Melayu'!$D$5:$D$40,MATCH($D8,'[1](2) Pengundi & % Melayu'!$B$5:$B$40,0)) -> 23548 | E8: =INDEX('[1](1) Majoriti'!$I$4:$I$39,MATCH($D8,'[1](1) Majoriti'!$B$4:$B$39,0)) -> -564 | F8: =Jempol!D27+Jempol!J27+Jempol!P27+Jempol!V27+Jempol!AB27+Jempol!AH27 -> 11396 | G8: =Jempol!F27+Jempol!L27+Jempol!R27+Jempol!X27+Jempol!AD27+Jempol!AJ27 -> 12152 | H8: =Jempol!H27 -> 912 | I8: =Jempol!N27 -> 1594 | J8: =Jempol!T27 -> 8813 | K8: =Jempol!Z27 -> 7140 | L8: =Jempol!AF27 -> 5089 | M8: =Jempol!AL27 -> 0 | N8: =Jempol!AN23 -> 21891 | O8: =Jempol!AN24 -> 453 | P8: =Jempol!AN25 -> 1204 | Q8: =Jempol!AN26 -> 0
B9: N07 | C9: =INDEX('[1](2) Pengundi & % Melayu'!$C$5:$C$40,MATCH($D9,'[1](2) Pengundi & % Melayu'!$B$5:$B$40,0)) -> Jeram Padang | D9: =INDEX('[1](2) Pengundi & % Melayu'!$D$5:$D$40,MATCH($D9,'[1](2) Pengundi & % Melayu'!$B$5:$B$40,0)) -> 16539 | E9: =INDEX('[1](1) Majoriti'!$I$4:$I$39,MATCH($D9,'[1](1) Majoriti'!$B$4:$B$39,0)) -> -693 | F9: =Jempol!D41+Jempol!J41+Jempol!P41+Jempol!V41+Jempol!AB41+Jempol!AH41 -> 7938 | G9: =Jempol!F41+Jempol!L41+Jempol!R41+Jempol!X41+Jempol!AD41+Jempol!AJ41 -> 8601 | H9: =Jempol!H41 -> 884 | I9: =Jempol!N41 -> 1677 | J9: =Jempol!T41 -> 5278 | K9: =Jempol!Z41 -> 5534 | L9: =Jempol!AF41 -> 3166 | M9: =Jempol!AL41 -> 0 | N9: =Jempol!AN37 -> 9518 | O9: =Jempol!AN38 -> 1696 | P9: =Jempol!AN39 -> 5324 | Q9: =Jempol!AN40 -> 1
B10: N08 | C10: =INDEX('[1](2) Pengundi & % Melayu'!$C$5:$C$40,MATCH($D10,'[1](2) Pengundi & % Melayu'!$B$5:$B$40,0)) -> Bahau | D10: =INDEX('[1](2) Pengundi & % Melayu'!$D$5:$D$40,MATCH($D10,'[1](2) Pengundi & % Melayu'!$B$5:$B$40,0)) -> 25951 | E10: =INDEX('[1](1) Majoriti'!$I$4:$I$39,MATCH($D10,'[1](1) Majoriti'!$B$4:$B$39,0)) -> -8408 | F10: =Jempol!D55+Jempol!J55+Jempol!P55+Jempol!V55+Jempol!AB55+Jempol!AH55 -> 12840 | G10: =Jempol!F55+Jempol!L55+Jempol!R55+Jempol!X55+Jempol!AD55+Jempol!AJ55 -> 13111 | H10: =Jempol!H55 -> 1173 | I10: =Jempol!N55 -> 2353 | J10: =Jempol!T55 -> 7978 | K10: =Jempol!Z55 -> 8244 | L10: =Jempol!AF55 -> 6203 | M10: =Jempol!AL55 -> 0 | N10: =Jempol!AN51 -> 8209 | O10: =Jempol!AN52 -> 15122 | P10: =Jempol!AN53 -> 2620 | Q10: =Jempol!AN54 -> 0
B11: N09 | C11: =INDEX('[1](2) Pengundi & % Melayu'!$C$5:$C$40,MATCH($D11,'[1](2) Pengundi & % Melayu'!$B$5:$B$40,0)) -> Lenggeng | D11: =INDEX('[1](2) Pengundi & % Melayu'!$D$5:$D$40,MATCH($D11,'[1](2) Pengundi & % Melayu'!$B$5:$B$40,0)) -> 28671 | E11: =INDEX('[1](1) Majoriti'!$I$4:$I$39,MATCH($D11,'[1](1) Majoriti'!$B$4:$B$39,0)) -> -685 | F11: =Seremban!D13+Seremban!J13+Seremban!P13+Seremban!V13+Seremban!AB13+Seremban!AH13 -> 14102 | G11: =Seremban!F13+Seremban!L13+Seremban!R13+Seremban!X13+Seremban!AD13+Seremban!AJ13 -> 14569 | H11: =Seremban!H13 -> 1467 | I11: =Seremban!N13 -> 3269 | J11: =Seremban!T13 -> 9987 | K11: =Seremban!Z13 -> 8530 | L11: =Seremban!AF13 -> 5418 | M11: =Seremban!AL13 -> 0 | N11: =Seremban!AN9 -> 22814 | O11: =Seremban!AN10 -> 4457 | P11: =Seremban!AN11 -> 1400 | Q11: =Seremban!AN12 -> 0
B12: N10 | C12: =INDEX('[1](2) Pengundi & % Melayu'!$C$5:$C$40,MATCH($D12,'[1](2) Pengundi & % Melayu'!$B$5:$B$40,0)) -> Nilai | D12: =INDEX('[1](2) Pengundi & % Melayu'!$D$5:$D$40,MATCH($D12,'[1](2) Pengundi & % Melayu'!$B$5:$B$40,0)) -> 45487 | E12: =INDEX('[1](1) Majoriti'!$I$4:$I$39,MATCH($D12,'[1](1) Majoriti'!$B$4:$B$39,0)) -> -10889 | F12: =Seremban!D27+Seremban!J27+Seremban!P27+Seremban!V27+Seremban!AB27+Seremban!AH27 -> 23107 | G12: =Seremban!F27+Seremban!L27+Seremban!R27+Seremban!X27+Seremban!AD27+Seremban!AJ27 -> 22380 | H12: =Seremban!H27 -> 3635 | I12: =Seremban!N27 -> 6582 | J12: =Seremban!T27 -> 14783 | K12: =Seremban!Z27 -> 13688 | L12: =Seremban!AF27 -> 6799 | M12: =Seremban!AL27 -> 0 | N12: =Seremban!AN23 -> 22213 | O12: =Seremban!AN24 -> 14350 | P12: =Seremban!AN25 -> 8918 | Q12: =Seremban!AN26 -> 6
B13: N11 | C13: =INDEX('[1](2) Pengundi & % Melayu'!$C$5:$C$40,MATCH($D13,'[1](2) Pengundi & % Melayu'!$B$5:$B$40,0)) -> Lobak | D13: =INDEX('[1](2) Pengundi & % Melayu'!$D$5:$D$40,MATCH($D13,'[1](2) Pengundi & % Melayu'!$B$5:$B$40,0)) -> 23141 | E13: =INDEX('[1](1) Majoriti'!$I$4:$I$39,MATCH($D13,'[1](1) Majoriti'!$B$4:$B$39,0)) -> -13504 | F13: =Seremban!D41+Seremban!J41+Seremban!P41+Seremban!V41+Seremban!AB41+Seremban!AH41 -> 11099 | G13: =Seremban!F41+Seremban!L41+Seremban!R41+Seremban!X41+Seremban!AD41+Seremban!AJ41 -> 12042 | H13: =Seremban!H41 -> 703 | I13: =Seremban!N41 -> 1492 | J13: =Seremban!T41 -> 5797 | K13: =Seremban!Z41 -> 8069 | L13: =Seremban!AF41 -> 7080 | M13: =Seremban!AL41 -> 0 | N13: =Seremban!AN37 -> 1555 | O13: =Seremban!AN38 -> 16793 | P13: =Seremban!AN39 -> 4789 | Q13: =Seremban!AN40 -> 4
B14: N12 | C14: =INDEX('[1](2) Pengundi & % Melayu'!$C$5:$C$40,MATCH($D14,'[1](2) Pengundi & % Melayu'!$B$5:$B$40,0)) -> Temiang | D14: =INDEX('[1](2) Pengundi & % Melayu'!$D$5:$D$40,MATCH($D14,'[1](2) Pengundi & % Melayu'!$B$5:$B$40,0)) -> 12975 | E14: =INDEX('[1](1) Majoriti'!$I$4:$I$39,MATCH($D14,'[1](1) Majoriti'!$B$4:$B$39,0)) -> -3068 | F14: =Seremban!D55+Seremban!J55+Seremban!P55+Seremban!V55+Seremban!AB55+Seremban!AH55 -> 6803 | G14: =Seremban!F55+Seremban!L55+Seremban!R55+Seremban!X55+Seremban!AD55+Seremban!AJ55 -> 6172 | H14: =Seremban!H55 -> 457 | I14: =Seremban!N55 -> 813 | J14: =Seremban!T55 -> 3554 | K14: =Seremban!Z55 -> 4224 | L14: =Seremban!AF55 -> 3927 | M14: =Seremban!AL55 -> 0 | N14: =Seremban!AN51 -> 5473 | O14: =Seremban!AN52 -> 5800 | P14: =Seremban!AN53 -> 1695 | Q14: =Seremban!AN54 -> 7
B15: N13 | C15: =INDEX('[1](2) Pengundi & % Melayu'!$C$5:$C$40,MATCH($D15,'[1](2) Pengundi & % Melayu'!$B$5:$B$40,0)) -> Sikamat | D15: =INDEX('[1](2) Pengundi & % Melayu'!$D$5:$D$40,MATCH($D15,'[1](2) Pengundi & % Melayu'!$B$5:$B$40,0)) -> 33885 | E15: =INDEX('[1](1) Majoriti'!$I$4:$I$39,MATCH($D15,'[1](1) Majoriti'!$B$4:$B$39,0)) -> -2662 | F15: =Seremban!D69+Seremban!J69+Seremban!P69+Seremban!V69+Seremban!AB69+Seremban!AH69 -> 16567 | G15: =Seremban!F69+Seremban!L69+Seremban!R69+Seremban!X69+Seremban!AD69+Seremban!AJ69 -> 17318 | H15: =Seremban!H69 -> 1960 | I15: =Seremban!N69 -> 4028 | J15: =Seremban!T69 -> 11959 | K15: =Seremban!Z69 -> 10001 | L15: =Seremban!AF69 -> 5937 | M15: =Seremban!AL69 -> 0 | N15: =Seremban!AN65 -> 24814 | O15: =Seremban!AN66 -> 6773 | P15: =Seremban!AN67 -> 2282 | Q15: =Seremban!AN68 -> 16
B16: N14 | C16: =INDEX('[1](2) Pengundi & % Melayu'!$C$5:$C$40,MATCH($D16,'[1](2) Pengundi & % Melayu'!$B$5:$B$40,0)) -> Ampangan | D16: =INDEX('[1](2) Pengundi & % Melayu'!$D$5:$D$40,MATCH($D16,'[1](2) Pengundi & % Melayu'!$B$5:$B$40,0)) -> 21338 | E16: =INDEX('[1](1) Majoriti'!$I$4:$I$39,MATCH($D16,'[1](1) Majoriti'!$B$4:$B$39,0)) -> -329 | F16: =Seremban!D83+Seremban!J83+Seremban!P83+Seremban!V83+Seremban!AB83+Seremban!AH83 -> 10460 | G16: =Seremban!F83+Seremban!L83+Seremban!R83+Seremban!X83+Seremban!AD83+Seremban!AJ83 -> 10878 | H16: =Seremban!H83 -> 859 | I16: =Seremban!N83 -> 1847 | J16: =Seremban!T83 -> 6486 | K16: =Seremban!Z83 -> 6920 | L16: =Seremban!AF83 -> 5226 | M16: =Seremban!AL83 -> 0 | N16: =Seremban!AN79 -> 16314 | O16: =Seremban!AN80 -> 3572 | P16: =Seremban!AN81 -> 1440 | Q16: =Seremban!AN82 -> 12
B17: N15 | C17: =INDEX('[1](2) Pengundi & % Melayu'!$C$5:$C$40,MATCH($D17,'[1](2) Pengundi & % Melayu'!$B$5:$B$40,0)) -> Juasseh | D17: =INDEX('[1](2) Pengundi & % Melayu'!$D$5:$D$40,MATCH($D17,'[1](2) Pengundi & % Melayu'!$B$5:$B$40,0)) -> 13669 | E17: =INDEX('[1](1) Majoriti'!$I$4:$I$39,MATCH($D17,'[1](1) Majoriti'!$B$4:$B$39,0)) -> -78 | F17: ='Kuala Pilah'!D13+'Kuala Pilah'!J13+'Kuala Pilah'!P13+'Kuala Pilah'!V13+'Kuala Pilah'!AB13+'Kuala Pilah'!AH13 -> 6676 | G17: ='Kuala Pilah'!F13+'Kuala Pilah'!L13+'Kuala Pilah'!R13+'Kuala Pilah'!X13+'Kuala Pilah'!AD13+'Kuala Pilah'!AJ13 -> 6993 | H17: ='Kuala Pilah'!H13 -> 596 | I17: ='Kuala Pilah'!N13 -> 1264 | J17: ='Kuala Pilah'!T13 -> 4385 | K17: ='Kuala Pilah'!Z13 -> 4309 | L17: ='Kuala Pilah'!AF13 -> 3115 | M17: ='Kuala Pilah'!AL13 -> 0 | N17: ='Kuala Pilah'!AN9 -> 11310 | O17: ='Kuala Pilah'!AN10 -> 1676 | P17: ='Kuala Pilah'!AN11 -> 681 | Q17: ='Kuala Pilah'!AN12 -> 2
B18: N16 | C18: =INDEX('[1](2) Pengundi & % Melayu'!$C$5:$C$40,MATCH($D18,'[1](2) Pengundi & % Melayu'!$B$5:$B$40,0)) -> Seri Menanti | D18: =INDEX('[1](2) Pengundi & % Melayu'!$D$5:$D$40,MATCH($D18,'[1](2) Pengundi & % Melayu'!$B$5:$B$40,0)) -> 10100 | E18: =INDEX('[1](1) Majoriti'!$I$4:$I$39,MATCH($D18,'[1](1) Majoriti'!$B$4:$B$39,0)) -> -370 | F18: ='Kuala Pilah'!D27+'Kuala Pilah'!J27+'Kuala Pilah'!P27+'Kuala Pilah'!V27+'Kuala Pilah'!AB27+'Kuala Pilah'!AH27 -> 4959 | G18: ='Kuala Pilah'!F27+'Kuala Pilah'!L27+'Kuala Pilah'!R27+'Kuala Pilah'!X27+'Kuala Pilah'!AD27+'Kuala Pilah'!AJ27 -> 5141 | H18: ='Kuala Pilah'!H27 -> 389 | I18: ='Kuala Pilah'!N27 -> 876 | J18: ='Kuala Pilah'!T27 -> 2783 | K18: ='Kuala Pilah'!Z27 -> 3455 | L18: ='Kuala Pilah'!AF27 -> 2597 | M18: ='Kuala Pilah'!AL27 -> 0 | N18: ='Kuala Pilah'!AN23 -> 9665 | O18: ='Kuala Pilah'!AN24 -> 379 | P18: ='Kuala Pilah'!AN25 -> 56 | Q18: ='Kuala Pilah'!AN26 -> 0
B19: N17 | C19: =INDEX('[1](2) Pengundi & % Melayu'!$C$5:$C$40,MATCH($D19,'[1](2) Pengundi & % Melayu'!$B$5:$B$40,0)) -> Senaling | D19: =INDEX('[1](2) Pengundi & % Melayu'!$D$5:$D$40,MATCH($D19,'[1](2) Pengundi & % Melayu'!$B$5:$B$40,0)) -> 9914 | E19: =INDEX('[1](1) Majoriti'!$I$4:$I$39,MATCH($D19,'[1](1) Majoriti'!$B$4:$B$39,0)) -> -662 | F19: ='Kuala Pilah'!D41+'Kuala Pilah'!J41+'Kuala Pilah'!P41+'Kuala Pilah'!V41+'Kuala Pilah'!AB41+'Kuala Pilah'!AH41 -> 4906 | G19: ='Kuala Pilah'!F41+'Kuala Pilah'!L41+'Kuala Pilah'!R41+'Kuala Pilah'!X41+'Kuala Pilah'!AD41+'Kuala Pilah'!AJ41 -> 5008 | H19: ='Kuala Pilah'!H41 -> 421 | I19: ='Kuala Pilah'!N41 -> 734 | J19: ='Kuala Pilah'!T41 -> 2881 | K19: ='Kuala Pilah'!Z41 -> 3247 | L19: ='Kuala Pilah'!AF41 -> 2631 | M19: ='Kuala Pilah'!AL41 -> 0 | N19: ='Kuala Pilah'!AN37 -> 8117 | O19: ='Kuala Pilah'!AN38 -> 1514 | P19: ='Kuala Pilah'!AN39 -> 283 | Q19: ='Kuala Pilah'!AN40 -> 0
B20: N18 | C20: =INDEX('[1](2) Pengundi & % Melayu'!$C$5:$C$40,MATCH($D20,'[1](2) Pengundi & % Melayu'!$B$5:$B$40,0)) -> Pilah | D20: =INDEX('[1](2) Pengundi & % Melayu'!$D$5:$D$40,MATCH($D20,'[1](2) Pengundi & % Melayu'!$B$5:$B$40,0)) -> 17963 | E20: =INDEX('[1](1) Majoriti'!$I$4:$I$39,MATCH($D20,'[1](1) Majoriti'!$B$4:$B$39,0)) -> -1079 | F20: ='Kuala Pilah'!D55+'Kuala Pilah'!J55+'Kuala Pilah'!P55+'Kuala Pilah'!V55+'Kuala Pilah'!AB55+'Kuala Pilah'!AH55 -> 8902 | G20: ='Kuala Pilah'!F55+'Kuala Pilah'!L55+'Kuala Pilah'!R55+'Kuala Pilah'!X55+'Kuala Pilah'!AD55+'Kuala Pilah'!AJ55 -> 9061 | H20: ='Kuala Pilah'!H55 -> 741 | I20: ='Kuala Pilah'!N55 -> 1512 | J20: ='Kuala Pilah'!T55 -> 5823 | K20: ='Kuala Pilah'!Z55 -> 5527 | L20: ='Kuala Pilah'!AF55 -> 4360 | M20: ='Kuala Pilah'!AL55 -> 0 | N20: ='Kuala Pilah'!AN51 -> 11974 | O20: ='Kuala Pilah'!AN52 -> 4585 | P20: ='Kuala Pilah'!AN53 -> 1403 | Q20: ='Kuala Pilah'!AN54 -> 1
B21: N19 | C21: =INDEX('[1](2) Pengundi & % Melayu'!$C$5:$C$40,MATCH($D21,'[1](2) Pengundi & % Melayu'!$B$5:$B$40,0)) -> Johol | D21: =INDEX('[1](2) Pengundi & % Melayu'!$D$5:$D$40,MATCH($D21,'[1](2) Pengundi & % Melayu'!$B$5:$B$40,0)) -> 12359 | E21: =INDEX('[1](1) Majoriti'!$I$4:$I$39,MATCH($D21,'[1](1) Majoriti'!$B$4:$B$39,0)) -> -2117 | F21: ='Kuala Pilah'!D69+'Kuala Pilah'!J69+'Kuala Pilah'!P69+'Kuala Pilah'!V69+'Kuala Pilah'!AB69+'Kuala Pilah'!AH69 -> 6206 | G21: ='Kuala Pilah'!F69+'Kuala Pilah'!L69+'Kuala Pilah'!R69+'Kuala Pilah'!X69+'Kuala Pilah'!AD69+'Kuala Pilah'!AJ69 -> 6153 | H21: ='Kuala Pilah'!H69 -> 463 | I21: ='Kuala Pilah'!N69 -> 1070 | J21: ='Kuala Pilah'!T69 -> 3624 | K21: ='Kuala Pilah'!Z69 -> 4283 | L21: ='Kuala Pilah'!AF69 -> 2919 | M21: ='Kuala Pilah'!AL69 -> 0 | N21: ='Kuala Pilah'!AN65 -> 9710 | O21: ='Kuala Pilah'!AN66 -> 1999 | P21: ='Kuala Pilah'!AN67 -> 650 | Q21: ='Kuala Pilah'!AN68 -> 0
B22: N20 | C22: =INDEX('[1](2) Pengundi & % Melayu'!$C$5:$C$40,MATCH($D22,'[1](2) Pengundi & % Melayu'!$B$5:$B$40,0)) -> Labu | D22: =INDEX('[1](2) Pengundi & % Melayu'!$D$5:$D$40,MATCH($D22,'[1](2) Pengundi & % Melayu'!$B$5:$B$40,0)) -> 32575 | E22: =INDEX('[1](1) Majoriti'!$I$4:$I$39,MATCH($D22,'[1](1) Majoriti'!$B$4:$B$39,0)) -> 1640 | F22: =Rasah!D13+Rasah!J13+Rasah!P13+Rasah!V13+Rasah!AB13+Rasah!AH13 -> 16182 | G22: =Rasah!F13+Rasah!L13+Rasah!R13+Rasah!X13+Rasah!AD13+Rasah!AJ13 -> 16393 | H22: =Rasah!H13 -> 2320 | I22: =Rasah!N13 -> 4856 | J22: =Rasah!T13 -> 10995 | K22: =Rasah!Z13 -> 9648 | L22: =Rasah!AF13 -> 4756 | M22: =Rasah!AL13 -> 0 | N22: =Rasah!AN9 -> 25804 | O22: =Rasah!AN10 -> 2789 | P22: =Rasah!AN11 -> 3982 | Q22: =Rasah!AN12 -> 0
B23: N21 | C23: =INDEX('[1](2) Pengundi & % Melayu'!$C$5:$C$40,MATCH($D23,'[1](2) Pengundi & % Melayu'!$B$5:$B$40,0)) -> Bukit Kepayang | D23: =INDEX('[1](2) Pengundi & % Melayu'!$D$5:$D$40,MATCH($D23,'[1](2) Pengundi & % Melayu'!$B$5:$B$40,0)) -> 49248 | E23: =INDEX('[1](1) Majoriti'!$I$4:$I$39,MATCH($D23,'[1](1) Majoriti'!$B$4:$B$39,0)) -> -19684 | F23: =Rasah!D27+Rasah!J27+Rasah!P27+Rasah!V27+Rasah!AB27+Rasah!AH27 -> 24343 | G23: =Rasah!F27+Rasah!L27+Rasah!R27+Rasah!X27+Rasah!AD27+Rasah!AJ27 -> 24905 | H23: =Rasah!H27 -> 3379 | I23: =Rasah!N27 -> 6555 | J23: =Rasah!T27 -> 16240 | K23: =Rasah!Z27 -> 13636 | L23: =Rasah!AF27 -> 9438 | M23: =Rasah!AL27 -> 0 | N23: =Rasah!AN23 -> 14655 | O23: =Rasah!AN24 -> 24973 | P23: =Rasah!AN25 -> 9573 | Q23: =Rasah!AN26 -> 47
B24: N22 | C24: =INDEX('[1](2) Pengundi & % Melayu'!$C$5:$C$40,MATCH($D24,'[1](2) Pengundi & % Melayu'!$B$5:$B$40,0)) -> Rahang | D24: =INDEX('[1](2) Pengundi & % Melayu'!$D$5:$D$40,MATCH($D24,'[1](2) Pengundi & % Melayu'!$B$5:$B$40,0)) -> 19608 | E24: =INDEX('[1](1) Majoriti'!$I$4:$I$39,MATCH($D24,'[1](1) Majoriti'!$B$4:$B$39,0)) -> -6432 | F24: =Rasah!D41+Rasah!J41+Rasah!P41+Rasah!V41+Rasah!AB41+Rasah!AH41 -> 9835 | G24: =Rasah!F41+Rasah!L41+Rasah!R41+Rasah!X41+Rasah!AD41+Rasah!AJ41 -> 9773 | H24: =Rasah!H41 -> 484 | I24: =Rasah!N41 -> 1119 | J24: =Rasah!T41 -> 5053 | K24: =Rasah!Z41 -> 6541 | L24: =Rasah!AF41 -> 6411 | M24: =Rasah!AL41 -> 0 | N24: =Rasah!AN37 -> 6476 | O24: =Rasah!AN38 -> 9103 | P24: =Rasah!AN39 -> 4019 | Q24: =Rasah!AN40 -> 10
B25: N23 | C25: =INDEX('[1](2) Pengundi & % Melayu'!$C$5:$C$40,MATCH($D25,'[1](2) Pengundi & % Melayu'!$B$5:$B$40,0)) -> Mambau | D25: =INDEX('[1](2) Pengundi & % Melayu'!$D$5:$D$40,MATCH($D25,'[1](2) Pengundi & % Melayu'!$B$5:$B$40,0)) -> 30316 | E25: =INDEX('[1](1) Majoriti'!$I$4:$I$39,MATCH($D25,'[1](1) Majoriti'!$B$4:$B$39,0)) -> -14940 | F25: =Rasah!D55+Rasah!J55+Rasah!P55+Rasah!V55+Rasah!AB55+Rasah!AH55 -> 14760 | G25: =Rasah!F55+Rasah!L55+Rasah!R55+Rasah!X55+Rasah!AD55+Rasah!AJ55 -> 15556 | H25: =Rasah!H55 -> 1202 | I25: =Rasah!N55 -> 2442 | J25: =Rasah!T55 -> 9325 | K25: =Rasah!Z55 -> 10415 | L25: =Rasah!AF55 -> 6932 | M25: =Rasah!AL55 -> 0 | N25: =Rasah!AN51 -> 4581 | O25: =Rasah!AN52 -> 18457 | P25: =Rasah!AN53 -> 7256 | Q25: =Rasah!AN54 -> 22
B26: N24 | C26: =INDEX('[1](2) Pengundi & % Melayu'!$C$5:$C$40,MATCH($D26,'[1](2) Pengundi & % Melayu'!$B$5:$B$40,0)) -> Seremban Jaya | D26: =INDEX('[1](2) Pengundi & % Melayu'!$D$5:$D$40,MATCH($D26,'[1](2) Pengundi & % Melayu'!$B$5:$B$40,0)) -> 32899 | E26: =INDEX('[1](1) Majoriti'!$I$4:$I$39,MATCH($D26,'[1](1) Majoriti'!$B$4:$B$39,0)) -> -12703 | F26: =Rasah!D69+Rasah!J69+Rasah!P69+Rasah!V69+Rasah!AB69+Rasah!AH69 -> 16018 | G26: =Rasah!F69+Rasah!L69+Rasah!R69+Rasah!X69+Rasah!AD69+Rasah!AJ69 -> 16881 | H26: =Rasah!H69 -> 1713 | I26: =Rasah!N69 -> 3840 | J26: =Rasah!T69 -> 11340 | K26: =Rasah!Z69 -> 10250 | L26: =Rasah!AF69 -> 5756 | M26: =Rasah!AL69 -> 0 | N26: =Rasah!AN65 -> 8781 | O26: =Rasah!AN66 -> 15456 | P26: =Rasah!AN67 -> 8654 | Q26: =Rasah!AN68 -> 8
B27: N25 | C27: =INDEX('[1](2) Pengundi & % Melayu'!$C$5:$C$40,MATCH($D27,'[1](2) Pengundi & % Melayu'!$B$5:$B$40,0)) -> Paroi | D27: =INDEX('[1](2) Pengundi & % Melayu'!$D$5:$D$40,MATCH($D27,'[1](2) Pengundi & % Melayu'!$B$5:$B$40,0)) -> 64582 | E27: =INDEX('[1](1) Majoriti'!$I$4:$I$39,MATCH($D27,'[1](1) Majoriti'!$B$4:$B$39,0)) -> 5539 | F27: =Rembau!D13+Rembau!J13+Rembau!P13+Rembau!V13+Rembau!AB13+Rembau!AH13 -> 31646 | G27: =Rembau!F13+Rembau!L13+Rembau!R13+Rembau!X13+Rembau!AD13+Rembau!AJ13 -> 32936 | H27: =Rembau!H13 -> 4342 | I27: =Rembau!N13 -> 9142 | J27: =Rembau!T13 -> 24101 | K27: =Rembau!Z13 -> 17835 | L27: =Rembau!AF13 -> 9162 | M27: =Rembau!AL13 -> 0 | N27: =Rembau!AN9 -> 51602 | O27: =Rembau!AN10 -> 4406 | P27: =Rembau!AN11 -> 8570 | Q27: =Rembau!AN12 -> 4
B28: N26 | C28: =INDEX('[1](2) Pengundi & % Melayu'!$C$5:$C$40,MATCH($D28,'[1](2) Pengundi & % Melayu'!$B$5:$B$40,0)) -> Chembong | D28: =INDEX('[1](2) Pengundi & % Melayu'!$D$5:$D$40,MATCH($D28,'[1](2) Pengundi & % Melayu'!$B$5:$B$40,0)) -> 26440 | E28: =INDEX('[1](1) Majoriti'!$I$4:$I$39,MATCH($D28,'[1](1) Majoriti'!$B$4:$B$39,0)) -> -4335 | F28: =Rembau!D27+Rembau!J27+Rembau!P27+Rembau!V27+Rembau!AB27+Rembau!AH27 -> 12843 | G28: =Rembau!F27+Rembau!L27+Rembau!R27+Rembau!X27+Rembau!AD27+Rembau!AJ27 -> 13597 | H28: =Rembau!H27 -> 1368 | I28: =Rembau!N27 -> 2989 | J28: =Rembau!T27 -> 9108 | K28: =Rembau!Z27 -> 7781 | L28: =Rembau!AF27 -> 5194 | M28: =Rembau!AL27 -> 0 | N28: =Rembau!AN23 -> 22157 | O28: =Rembau!AN24 -> 1868 | P28: =Rembau!AN25 -> 2414 | Q28: =Rembau!AN26 -> 1
B29: N27 | C29: =INDEX('[1](2) Pengundi & % Melayu'!$C$5:$C$40,MATCH($D29,'[1](2) Pengundi & % Melayu'!$B$5:$B$40,0)) -> Rantau | D29: =INDEX('[1](2) Pengundi & % Melayu'!$D$5:$D$40,MATCH($D29,'[1](2) Pengundi & % Melayu'!$B$5:$B$40,0)) -> 34636 | E29: =INDEX('[1](1) Majoriti'!$I$4:$I$39,MATCH($D29,'[1](1) Majoriti'!$B$4:$B$39,0)) -> -10280 | F29: =Rembau!D41+Rembau!J41+Rembau!P41+Rembau!V41+Rembau!AB41+Rembau!AH41 -> 17303 | G29: =Rembau!F41+Rembau!L41+Rembau!R41+Rembau!X41+Rembau!AD41+Rembau!AJ41 -> 17333 | H29: =Rembau!H41 -> 2004 | I29: =Rembau!N41 -> 3731 | J29: =Rembau!T41 -> 11604 | K29: =Rembau!Z41 -> 11279 | L29: =Rembau!AF41 -> 6018 | M29: =Rembau!AL41 -> 0 | N29: =Rembau!AN37 -> 20086 | O29: =Rembau!AN38 -> 5690 | P29: =Rembau!AN39 -> 8852 | Q29: =Rembau!AN40 -> 8
B30: N28 | C30: =INDEX('[1](2) Pengundi & % Melayu'!$C$5:$C$40,MATCH($D30,'[1](2) Pengundi & % Melayu'!$B$5:$B$40,0)) -> Kota | D30: =INDEX('[1](2) Pengundi & % Melayu'!$D$5:$D$40,MATCH($D30,'[1](2) Pengundi & % Melayu'!$B$5:$B$40,0)) -> 16730 | E30: =INDEX('[1](1) Majoriti'!$I$4:$I$39,MATCH($D30,'[1](1) Majoriti'!$B$4:$B$39,0)) -> -135 | F30: =Rembau!D55+Rembau!J55+Rembau!P55+Rembau!V55+Rembau!AB55+Rembau!AH55 -> 8186 | G30: =Rembau!F55+Rembau!L55+Rembau!R55+Rembau!X55+Rembau!AD55+Rembau!AJ55 -> 8544 | H30: =Rembau!H55 -> 706 | I30: =Rembau!N55 -> 1343 | J30: =Rembau!T55 -> 4978 | K30: =Rembau!Z55 -> 5587 | L30: =Rembau!AF55 -> 4116 | M30: =Rembau!AL55 -> 0 | N30: =Rembau!AN51 -> 14821 | O30: =Rembau!AN52 -> 1167 | P30: =Rembau!AN53 -> 742 | Q30: =Rembau!AN54 -> 0
B31: N29 | C31: =INDEX('[1](2) Pengundi & % Melayu'!$C$5:$C$40,MATCH($D31,'[1](2) Pengundi & % Melayu'!$B$5:$B$40,0)) -> Chuah | D31: =INDEX('[1](2) Pengundi & % Melayu'!$D$5:$D$40,MATCH($D31,'[1](2) Pengundi & % Melayu'!$B$5:$B$40,0)) -> 15141 | E31: =INDEX('[1](1) Majoriti'!$I$4:$I$39,MATCH($D31,'[1](1) Majoriti'!$B$4:$B$39,0)) -> -6298 | F31: ='Port Dickson'!D13+'Port Dickson'!J13+'Port Dickson'!P13+'Port Dickson'!V13+'Port Dickson'!AB13+'Port Dickson'!AH13 -> 7703 | G31: ='Port Dickson'!F13+'Port Dickson'!L13+'Port Dickson'!R13+'Port Dickson'!X13+'Port Dickson'!AD13+'Port Dickson'!AJ13 -> 7438 | H31: ='Port Dickson'!H13 -> 598 | I31: ='Port Dickson'!N13 -> 1212 | J31: ='Port Dickson'!T13 -> 4324 | K31: ='Port Dickson'!Z13 -> 5450 | L31: ='Port Dickson'!AF13 -> 3557 | M31: ='Port Dickson'!AL13 -> 0 | N31: ='Port Dickson'!AN9 -> 3831 | O31: ='Port Dickson'!AN10 -> 8186 | P31: ='Port Dickson'!AN11 -> 3123 | Q31: ='Port Dickson'!AN12 -> 1
B32: N30 | C32: =INDEX('[1](2) Pengundi & % Melayu'!$C$5:$C$40,MATCH($D32,'[1](2) Pengundi & % Melayu'!$B$5:$B$40,0)) -> Lukut | D32: =INDEX('[1](2) Pengundi & % Melayu'!$D$5:$D$40,MATCH($D32,'[1](2) Pengundi & % Melayu'!$B$5:$B$40,0)) -> 28010 | E32: =INDEX('[1](1) Majoriti'!$I$4:$I$39,MATCH($D32,'[1](1) Majoriti'!$B$4:$B$39,0)) -> -10135 | F32: ='Port Dickson'!D27+'Port Dickson'!J27+'Port Dickson'!P27+'Port Dickson'!V27+'Port Dickson'!AB27+'Port Dickson'!AH27 -> 13919 | G32: ='Port Dickson'!F27+'Port Dickson'!L27+'Port Dickson'!R27+'Port Dickson'!X27+'Port Dickson'!AD27+'Port Dickson'!AJ27 -> 14091 | H32: ='Port Dickson'!H27 -> 1522 | I32: ='Port Dickson'!N27 -> 3222 | J32: ='Port Dickson'!T27 -> 9589 | K32: ='Port Dickson'!Z27 -> 8970 | L32: ='Port Dickson'!AF27 -> 4707 | M32: ='Port Dickson'!AL27 -> 0 | N32: ='Port Dickson'!AN23 -> 7292 | O32: ='Port Dickson'!AN24 -> 13762 | P32: ='Port Dickson'!AN25 -> 6949 | Q32: ='Port Dickson'!AN26 -> 7
B33: N31 | C33: =INDEX('[1](2) Pengundi & % Melayu'!$C$5:$C$40,MATCH($D33,'[1](2) Pengundi & % Melayu'!$B$5:$B$40,0)) -> Bagan Pinang | D33: =INDEX('[1](2) Pengundi & % Melayu'!$D$5:$D$40,MATCH($D33,'[1](2) Pengundi & % Melayu'!$B$5:$B$40,0)) -> 27926 | E33: =INDEX('[1](1) Majoriti'!$I$4:$I$39,MATCH($D33,'[1](1) Majoriti'!$B$4:$B$39,0)) -> 3426 | F33: ='Port Dickson'!D41+'Port Dickson'!J41+'Port Dickson'!P41+'Port Dickson'!V41+'Port Dickson'!AB41+'Port Dickson'!AH41 -> 16389 | G33: ='Port Dickson'!F41+'Port Dickson'!L41+'Port Dickson'!R41+'Port Dickson'!X41+'Port Dickson'!AD41+'Port Dickson'!AJ41 -> 11537 | H33: ='Port Dickson'!H41 -> 2637 | I33: ='Port Dickson'!N41 -> 5842 | J33: ='Port Dickson'!T41 -> 9444 | K33: ='Port Dickson'!Z41 -> 6643 | L33: ='Port Dickson'!AF41 -> 3360 | M33: ='Port Dickson'!AL41 -> 0 | N33: ='Port Dickson'!AN37 -> 22064 | O33: ='Port Dickson'!AN38 -> 3373 | P33: ='Port Dickson'!AN39 -> 2488 | Q33: ='Port Dickson'!AN40 -> 1
B34: N32 | C34: =INDEX('[1](2) Pengundi & % Melayu'!$C$5:$C$40,MATCH($D34,'[1](2) Pengundi & % Melayu'!$B$5:$B$40,0)) -> Linggi | D34: =INDEX('[1](2) Pengundi & % Melayu'!$D$5:$D$40,MATCH($D34,'[1](2) Pengundi & % Melayu'!$B$5:$B$40,0)) -> 20768 | E34: =INDEX('[1](1) Majoriti'!$I$4:$I$39,MATCH($D34,'[1](1) Majoriti'!$B$4:$B$39,0)) -> -1461 | F34: ='Port Dickson'!D55+'Port Dickson'!J55+'Port Dickson'!P55+'Port Dickson'!V55+'Port Dickson'!AB55+'Port Dickson'!AH55 -> 10582 | G34: ='Port Dickson'!F55+'Port Dickson'!L55+'Port Dickson'!R55+'Port Dickson'!X55+'Port Dickson'!AD55+'Port Dickson'!AJ55 -> 10186 | H34: ='Port Dickson'!H55 -> 735 | I34: ='Port Dickson'!N55 -> 1736 | J34: ='Port Dickson'!T55 -> 7351 | K34: ='Port Dickson'!Z55 -> 6934 | L34: ='Port Dickson'!AF55 -> 4012 | M34: ='Port Dickson'!AL55 -> 0 | N34: ='Port Dickson'!AN51 -> 13537 | O34: ='Port Dickson'!AN52 -> 3784 | P34: ='Port Dickson'!AN53 -> 3447 | Q34: ='Port Dickson'!AN54 -> 0
B35: N33 | C35: =INDEX('[1](2) Pengundi & % Melayu'!$C$5:$C$40,MATCH($D35,'[1](2) Pengundi & % Melayu'!$B$5:$B$40,0)) -> Sri Tanjung | D35: =INDEX('[1](2) Pengundi & % Melayu'!$D$5:$D$40,MATCH($D35,'[1](2) Pengundi & % Melayu'!$B$5:$B$40,0)) -> 19585 | E35: =INDEX('[1](1) Majoriti'!$I$4:$I$39,MATCH($D35,'[1](1) Majoriti'!$B$4:$B$39,0)) -> -3996 | F35: ='Port Dickson'!D69+'Port Dickson'!J69+'Port Dickson'!P69+'Port Dickson'!V69+'Port Dickson'!AB69+'Port Dickson'!AH69 -> 9706 | G35: ='Port Dickson'!F69+'Port Dickson'!L69+'Port Dickson'!R69+'Port Dickson'!X69+'Port Dickson'!AD69+'Port Dickson'!AJ69 -> 9879 | H35: ='Port Dickson'!H69 -> 774 | I35: ='Port Dickson'!N69 -> 1722 | J35: ='Port Dickson'!T69 -> 6097 | K35: ='Port Dickson'!Z69 -> 6214 | L35: ='Port Dickson'!AF69 -> 4778 | M35: ='Port Dickson'!AL69 -> 0 | N35: ='Port Dickson'!AN65 -> 8316 | O35: ='Port Dickson'!AN66 -> 6453 | P35: ='Port Dickson'!AN67 -> 4810 | Q35: ='Port Dickson'!AN68 -> 6
B36: N34 | C36: =INDEX('[1](2) Pengundi & % Melayu'!$C$5:$C$40,MATCH($D36,'[1](2) Pengundi & % Melayu'!$B$5:$B$40,0)) -> Gemas | D36: =INDEX('[1](2) Pengundi & % Melayu'!$D$5:$D$40,MATCH($D36,'[1](2) Pengundi & % Melayu'!$B$5:$B$40,0)) -> 29235 | E36: =INDEX('[1](1) Majoriti'!$I$4:$I$39,MATCH($D36,'[1](1) Majoriti'!$B$4:$B$39,0)) -> 3120 | F36: =Tampin!D13+Tampin!J13+Tampin!P13+Tampin!V13+Tampin!AB13+Tampin!AH13 -> 15101 | G36: =Tampin!F13+Tampin!L13+Tampin!R13+Tampin!X13+Tampin!AD13+Tampin!AJ13 -> 14134 | H36: =Tampin!H13 -> 1097 | I36: =Tampin!N13 -> 2550 | J36: =Tampin!T13 -> 11858 | K36: =Tampin!Z13 -> 8919 | L36: =Tampin!AF13 -> 4811 | M36: =Tampin!AL13 -> 0 | N36: =Tampin!AN9 -> 24851 | O36: =Tampin!AN10 -> 3038 | P36: =Tampin!AN11 -> 1346 | Q36: =Tampin!AN12 -> 0
B37: N35 | C37: =INDEX('[1](2) Pengundi & % Melayu'!$C$5:$C$40,MATCH($D37,'[1](2) Pengundi & % Melayu'!$B$5:$B$40,0)) -> Gemencheh | D37: =INDEX('[1](2) Pengundi & % Melayu'!$D$5:$D$40,MATCH($D37,'[1](2) Pengundi & % Melayu'!$B$5:$B$40,0)) -> 24878 | E37: =INDEX('[1](1) Majoriti'!$I$4:$I$39,MATCH($D37,'[1](1) Majoriti'!$B$4:$B$39,0)) -> -2434 | F37: =Tampin!D27+Tampin!J27+Tampin!P27+Tampin!V27+Tampin!AB27+Tampin!AH27 -> 12464 | G37: =Tampin!F27+Tampin!L27+Tampin!R27+Tampin!X27+Tampin!AD27+Tampin!AJ27 -> 12414 | H37: =Tampin!H27 -> 1111 | I37: =Tampin!N27 -> 2179 | J37: =Tampin!T27 -> 7774 | K37: =Tampin!Z27 -> 8558 | L37: =Tampin!AF27 -> 5256 | M37: =Tampin!AL27 -> 0 | N37: =Tampin!AN23 -> 15768 | O37: =Tampin!AN24 -> 5510 | P37: =Tampin!AN25 -> 3600 | Q37: =Tampin!AN26 -> 0
B38: N36 | C38: =INDEX('[1](2) Pengundi & % Melayu'!$C$5:$C$40,MATCH($D38,'[1](2) Pengundi & % Melayu'!$B$5:$B$40,0)) -> Repah | D38: =INDEX('[1](2) Pengundi & % Melayu'!$D$5:$D$40,MATCH($D38,'[1](2) Pengundi & % Melayu'!$B$5:$B$40,0)) -> 27830 | E38: =INDEX('[1](1) Majoriti'!$I$4:$I$39,MATCH($D38,'[1](1) Majoriti'!$B$4:$B$39,0)) -> -5950 | F38: =Tampin!D41+Tampin!J41+Tampin!P41+Tampin!V41+Tampin!AB41+Tampin!AH41 -> 13734 | G38: =Tampin!F41+Tampin!L41+Tampin!R41+Tampin!X41+Tampin!AD41+Tampin!AJ41 -> 14096 | H38: =Tampin!H41 -> 1119 | I38: =Tampin!N41 -> 2570 | J38: =Tampin!T41 -> 9461 | K38: =Tampin!Z41 -> 8598 | L38: =Tampin!AF41 -> 6082 | M38: =Tampin!AL41 -> 0 | N38: =Tampin!AN37 -> 11630 | O38: =Tampin!AN38 -> 11633 | P38: =Tampin!AN39 -> 4560 | Q38: =Tampin!AN40 -> 7

Sheet Jelebu
B2: Negeri | C2: : | D2: 05 - NEGERI SEMBILAN
B3: Parlimen | C3: : | D3: 126 - JELEBU
B4: DUN | C4: : | D4: 01 - CHENNAH
B5: Umur Pada | C5: : | D5: 46184
B6: Bil. | C6: Bangsa | D6: 18-20 Thn | J6: 21-25 Thn | P6: 26-40 Thn | V6: 41-60 Thn | AB6: 61-999 Thn | AH6: Tak Diketahui | AN6: Jumlah
D7: Lelaki | F7: Wanita | H7: Jumlah | J7: Lelaki | L7: Wanita | N7: Jumlah | P7: Lelaki | R7: Wanita | T7: Jumlah | V7: Lelaki | X7: Wanita | Z7: Jumlah | AB7: Lelaki | AD7: Wanita | AF7: Jumlah | AH7: Lelaki | AJ7: Wanita | AL7: Jumlah
D8: Bil | E8: % | F8: Bil | G8: % | H8: Bil | I8: % | J8: Bil | K8: % | L8: Bil | M8: % | N8: Bil | O8: % | P8: Bil | Q8: % | R8: Bil | S8: % | T8: Bil | U8: % | V8: Bil | W8: % | X8: Bil | Y8: % | Z8: Bil | AA8: % | AB8: Bil | AC8: % | AD8: Bil | AE8: % | AF8: Bil | AG8: % | AH8: Bil | AI8: % | AJ8: Bil | AK8: % | AL8: Bil | AM8: %
B9: 1 | C9: M - MELAYU | D9: 181 | E9: 50.84 | F9: 175 | G9: 49.16 | H9: 356 | I9: 4.76 | J9: 360 | K9: 51.72 | L9: 336 | M9: 48.28 | N9: 696 | O9: 9.31 | P9: 1286 | Q9: 51.96 | R9: 1189 | S9: 48.04 | T9: 2475 | U9: 33.09 | V9: 1304 | W9: 51.64 | X9: 1221 | Y9: 48.36 | Z9: 2525 | AA9: 33.76 | AB9: 615 | AC9: 43.1 | AD9: 812 | AE9: 56.9 | AF9: 1427 | AG9: 19.08 | AH9: 0 | AI9: 0 | AJ9: 0 | AK9: 0 | AL9: 0 | AM9: 0 | AN9: 7479
B10: 2 | C10: C - CINA | D10: 107 | E10: 53.23 | F10: 94 | G10: 46.77 | H10: 201 | I10: 3.03 | J10: 201 | K10: 51.94 | L10: 186 | M10: 48.06 | N10: 387 | O10: 5.84 | P10: 825 | Q10: 56.28 | R10: 641 | S10: 43.72 | T10: 1466 | U10: 22.11 | V10: 1305 | W10: 55.44 | X10: 1049 | Y10: 44.56 | Z10: 2354 | AA10: 35.51 | AB10: 1082 | AC10: 48.69 | AD10: 1140 | AE10: 51.31 | AF10: 2222 | AG10: 33.51 | AH10: 0 | AI10: 0 | AJ10: 0 | AK10: 0 | AL10: 0 | AM10: 0 | AN10: 6630
B11: 3 | C11: I - INDIA | D11: 9 | E11: 60 | F11: 6 | G11: 40 | H11: 15 | I11: 4.72 | J11: 12 | K11: 54.55 | L11: 10 | M11: 45.45 | N11: 22 | O11: 6.92 | P11: 52 | Q11: 52.53 | R11: 47 | S11: 47.47 | T11: 99 | U11: 31.13 | V11: 53 | W11: 49.07 | X11: 55 | Y11: 50.93 | Z11: 108 | AA11: 33.96 | AB11: 30 | AC11: 40.54 | AD11: 44 | AE11: 59.46 | AF11: 74 | AG11: 23.27 | AH11: 0 | AI11: 0 | AJ11: 0 | AK11: 0 | AL11: 0 | AM11: 0 | AN11: 318
B12: 4 | C12: L - LAIN-LAIN | D12: 0 | E12: 0 | F12: 0 | G12: 0 | H12: 0 | I12: 0 | J12: 0 | K12: 0 | L12: 0 | M12: 0 | N12: 0 | O12: 0 | P12: 0 | Q12: 0 | R12: 0 | S12: 0 | T12: 0 | U12: 0 | V12: 0 | W12: 0 | X12: 0 | Y12: 0 | Z12: 0 | AA12: 0 | AB12: 0 | AC12: 0 | AD12: 0 | AE12: 0 | AF12: 0 | AG12: 0 | AH12: 0 | AI12: 0 | AJ12: 0 | AK12: 0 | AL12: 0 | AM12: 0 | AN12: 0
B13: Jumlah | D13: 297 | E13: 51.92 | F13: 275 | G13: 48.08 | H13: 572 | I13: 3.96 | J13: 573 | K13: 51.86 | L13: 532 | M13: 48.14 | N13: 1105 | O13: 7.66 | P13: 2163 | Q13: 53.54 | R13: 1877 | S13: 46.46 | T13: 4040 | U13: 28 | V13: 2662 | W13: 53.38 | X13: 2325 | Y13: 46.62 | Z13: 4987 | AA13: 34.57 | AB13: 1727 | AC13: 46.39 | AD13: 1996 | AE13: 53.61 | AF13: 3723 | AG13: 25.81 | AH13: 0 | AI13: 0 | AJ13: 0 | AK13: 0 | AL13: 0 | AM13: 0 | AN13: 14427
B16: Negeri | C16: : | D16: 05 - NEGERI SEMBILAN
B17: Parlimen | C17: : | D17: 126 - JELEBU
B18: DUN | C18: : | D18: 02 - PERTANG
B19: Umur Pada | C19: : | D19: 46184
B20: Bil. | C20: Bangsa | D20: 18-20 Thn | J20: 21-25 Thn | P20: 26-40 Thn | V20: 41-60 Thn | AB20: 61-999 Thn | AH20: Tak Diketahui | AN20: Jumlah
D21: Lelaki | F21: Wanita | H21: Jumlah | J21: Lelaki | L21: Wanita | N21: Jumlah | P21: Lelaki | R21: Wanita | T21: Jumlah | V21: Lelaki | X21: Wanita | Z21: Jumlah | AB21: Lelaki | AD21: Wanita | AF21: Jumlah | AH21: Lelaki | AJ21: Wanita | AL21: Jumlah
D22: Bil | E22: % | F22: Bil | G22: % | H22: Bil | I22: % | J22: Bil | K22: % | L22: Bil | M22: % | N22: Bil | O22: % | P22: Bil | Q22: % | R22: Bil | S22: % | T22: Bil | U22: % | V22: Bil | W22: % | X22: Bil | Y22: % | Z22: Bil | AA22: % | AB22: Bil | AC22: % | AD22: Bil | AE22: % | AF22: Bil | AG22: % | AH22: Bil | AI22: % | AJ22: Bil | AK22: % | AL22: Bil | AM22: %
B23: 1 | C23: M - MELAYU | D23: 202 | E23: 52.47 | F23: 183 | G23: 47.53 | H23: 385 | I23: 4.18 | J23: 367 | K23: 49.46 | L23: 375 | M23: 50.54 | N23: 742 | O23: 8.06 | P23: 1458 | Q23: 51.03 | R23: 1399 | S23: 48.97 | T23: 2857 | U23: 31.05 | V23: 1812 | W23: 51.68 | X23: 1694 | Y23: 48.32 | Z23: 3506 | AA23: 38.1 | AB23: 761 | AC23: 44.48 | AD23: 950 | AE23: 55.52 | AF23: 1711 | AG23: 18.6 | AH23: 0 | AI23: 0 | AJ23: 0 | AK23: 0 | AL23: 0 | AM23: 0 | AN23: 9201
B24: 2 | C24: C - CINA | D24: 51 | E24: 57.95 | F24: 37 | G24: 42.05 | H24: 88 | I24: 3.1 | J24: 115 | K24: 53.99 | L24: 98 | M24: 46.01 | N24: 213 | O24: 7.49 | P24: 391 | Q24: 54.69 | R24: 324 | S24: 45.31 | T24: 715 | U24: 25.16 | V24: 550 | W24: 56.53 | X24: 423 | Y24: 43.47 | Z24: 973 | AA24: 34.24 | AB24: 413 | AC24: 48.42 | AD24: 440 | AE24: 51.58 | AF24: 853 | AG24: 30.01 | AH24: 0 | AI24: 0 | AJ24: 0 | AK24: 0 | AL24: 0 | AM24: 0 | AN24: 2842
B25: 3 | C25: I - INDIA | D25: 18 | E25: 60 | F25: 12 | G25: 40 | H25: 30 | I25: 3.58 | J25: 37 | K25: 46.25 | L25: 43 | M25: 53.75 | N25: 80 | O25: 9.56 | P25: 132 | Q25: 50.38 | R25: 130 | S25: 49.62 | T25: 262 | U25: 31.3 | V25: 141 | W25: 48.96 | X25: 147 | Y25: 51.04 | Z25: 288 | AA25: 34.41 | AB25: 75 | AC25: 42.37 | AD25: 102 | AE25: 57.63 | AF25: 177 | AG25: 21.15 | AH25: 0 | AI25: 0 | AJ25: 0 | AK25: 0 | AL25: 0 | AM25: 0 | AN25: 837
B26: 4 | C26: L - LAIN-LAIN | D26: 0 | E26: 0 | F26: 0 | G26: 0 | H26: 0 | I26: 0 | J26: 0 | K26: 0 | L26: 0 | M26: 0 | N26: 0 | O26: 0 | P26: 0 | Q26: 0 | R26: 0 | S26: 0 | T26: 0 | U26: 0 | V26: 0 | W26: 0 | X26: 0 | Y26: 0 | Z26: 0 | AA26: 0 | AB26: 0 | AC26: 0 | AD26: 0 | AE26: 0 | AF26: 0 | AG26: 0 | AH26: 0 | AI26: 0 | AJ26: 0 | AK26: 0 | AL26: 0 | AM26: 0 | AN26: 0
B27: Jumlah | D27: 271 | E27: 53.88 | F27: 232 | G27: 46.12 | H27: 503 | I27: 3.91 | J27: 519 | K27: 50.14 | L27: 516 | M27: 49.86 | N27: 1035 | O27: 8.04 | P27: 1981 | Q27: 51.67 | R27: 1853 | S27: 48.33 | T27: 3834 | U27: 29.77 | V27: 2503 | W27: 52.51 | X27: 2264 | Y27: 47.49 | Z27: 4767 | AA27: 37.01 | AB27: 1249 | AC27: 45.57 | AD27: 1492 | AE27: 54.43 | AF27: 2741 | AG27: 21.28 | AH27: 0 | AI27: 0 | AJ27: 0 | AK27: 0 | AL27: 0 | AM27: 0 | AN27: 12880
B30: Negeri | C30: : | D30: 05 - NEGERI SEMBILAN
B31: Parlimen | C31: : | D31: 126 - JELEBU
B32: DUN | C32: : | D32: 03 - SUNGAI LUI
B33: Umur Pada | C33: : | D33: 46184
B34: Bil. | C34: Bangsa | D34: 18-20 Thn | J34: 21-25 Thn | P34: 26-40 Thn | V34: 41-60 Thn | AB34: 61-999 Thn | AH34: Tak Diketahui | AN34: Jumlah
D35: Lelaki | F35: Wanita | H35: Jumlah | J35: Lelaki | L35: Wanita | N35: Jumlah | P35: Lelaki | R35: Wanita | T35: Jumlah | V35: Lelaki | X35: Wanita | Z35: Jumlah | AB35: Lelaki | AD35: Wanita | AF35: Jumlah | AH35: Lelaki | AJ35: Wanita | AL35: Jumlah
D36: Bil | E36: % | F36: Bil | G36: % | H36: Bil | I36: % | J36: Bil | K36: % | L36: Bil | M36: % | N36: Bil | O36: % | P36: Bil | Q36: % | R36: Bil | S36: % | T36: Bil | U36: % | V36: Bil | W36: % | X36: Bil | Y36: % | Z36: Bil | AA36: % | AB36: Bil | AC36: % | AD36: Bil | AE36: % | AF36: Bil | AG36: % | AH36: Bil | AI36: % | AJ36: Bil | AK36: % | AL36: Bil | AM36: %
B37: 1 | C37: M - MELAYU | D37: 380 | E37: 50.46 | F37: 373 | G37: 49.54 | H37: 753 | I37: 4.5 | J37: 674 | K37: 49.89 | L37: 677 | M37: 50.11 | N37: 1351 | O37: 8.08 | P37: 3135 | Q37: 52.89 | R37: 2792 | S37: 47.11 | T37: 5927 | U37: 35.45 | V37: 2933 | W37: 51.39 | X37: 2774 | Y37: 48.61 | Z37: 5707 | AA37: 34.13 | AB37: 1239 | AC37: 41.54 | AD37: 1744 | AE37: 58.46 | AF37: 2983 | AG37: 17.84 | AH37: 0 | AI37: 0 | AJ37: 0 | AK37: 0 | AL37: 0 | AM37: 0 | AN37: 16721
B38: 2 | C38: C - CINA | D38: 29 | E38: 51.79 | F38: 27 | G38: 48.21 | H38: 56 | I38: 3.95 | J38: 67 | K38: 51.15 | L38: 64 | M38: 48.85 | N38: 131 | O38: 9.24 | P38: 269 | Q38: 55.81 | R38: 213 | S38: 44.19 | T38: 482 | U38: 34.02 | V38: 223 | W38: 58.07 | X38: 161 | Y38: 41.93 | Z38: 384 | AA38: 27.1 | AB38: 162 | AC38: 44.51 | AD38: 202 | AE38: 55.49 | AF38: 364 | AG38: 25.69 | AH38: 0 | AI38: 0 | AJ38: 0 | AK38: 0 | AL38: 0 | AM38: 0 | AN38: 1417
B39: 3 | C39: I - INDIA | D39: 31 | E39: 56.36 | F39: 24 | G39: 43.64 | H39: 55 | I39: 3.5 | J39: 71 | K39: 43.29 | L39: 93 | M39: 56.71 | N39: 164 | O39: 10.43 | P39: 241 | Q39: 47.25 | R39: 269 | S39: 52.75 | T39: 510 | U39: 32.42 | V39: 238 | W39: 50.11 | X39: 237 | Y39: 49.89 | Z39: 475 | AA39: 30.2 | AB39: 159 | AC39: 43.09 | AD39: 210 | AE39: 56.91 | AF39: 369 | AG39: 23.46 | AH39: 0 | AI39: 0 | AJ39: 0 | AK39: 0 | AL39: 0 | AM39: 0 | AN39: 1573
B40: 4 | C40: L - LAIN-LAIN | D40: 0 | E40: 0 | F40: 0 | G40: 0 | H40: 0 | I40: 0 | J40: 0 | K40: 0 | L40: 0 | M40: 0 | N40: 0 | O40: 0 | P40: 0 | Q40: 0 | R40: 0 | S40: 0 | T40: 0 | U40: 0 | V40: 0 | W40: 0 | X40: 0 | Y40: 0 | Z40: 0 | AA40: 0 | AB40: 0 | AC40: 0 | AD40: 0 | AE40: 0 | AF40: 0 | AG40: 0 | AH40: 0 | AI40: 0 | AJ40: 0 | AK40: 0 | AL40: 0 | AM40: 0 | AN40: 0
B41: Jumlah | D41: 440 | E41: 50.93 | F41: 424 | G41: 49.07 | H41: 864 | I41: 4.38 | J41: 812 | K41: 49.33 | L41: 834 | M41: 50.67 | N41: 1646 | O41: 8.35 | P41: 3645 | Q41: 52.68 | R41: 3274 | S41: 47.32 | T41: 6919 | U41: 35.1 | V41: 3394 | W41: 51.69 | X41: 3172 | Y41: 48.31 | Z41: 6566 | AA41: 33.31 | AB41: 1560 | AC41: 41.98 | AD41: 2156 | AE41: 58.02 | AF41: 3716 | AG41: 18.85 | AH41: 0 | AI41: 0 | AJ41: 0 | AK41: 0 | AL41: 0 | AM41: 0 | AN41: 19711
B44: Negeri | C44: : | D44: 05 - NEGERI SEMBILAN
B45: Parlimen | C45: : | D45: 126 - JELEBU
B46: DUN | C46: : | D46: 04 - KLAWANG
B47: Umur Pada | C47: : | D47: 46184
...

Sheet Jempol
B2: Negeri | C2: : | D2: 05 - NEGERI SEMBILAN
B3: Parlimen | C3: : | D3: 127 - JEMPOL
B4: DUN | C4: : | D4: 05 - SERTING
B5: Umur Pada | C5: : | D5: 46184
B6: Bil. | C6: Bangsa | D6: 18-20 Thn | J6: 21-25 Thn | P6: 26-40 Thn | V6: 41-60 Thn | AB6: 61-999 Thn | AH6: Tak Diketahui | AN6: Jumlah
D7: Lelaki | F7: Wanita | H7: Jumlah | J7: Lelaki | L7: Wanita | N7: Jumlah | P7: Lelaki | R7: Wanita | T7: Jumlah | V7: Lelaki | X7: Wanita | Z7: Jumlah | AB7: Lelaki | AD7: Wanita | AF7: Jumlah | AH7: Lelaki | AJ7: Wanita | AL7: Jumlah
D8: Bil | E8: % | F8: Bil | G8: % | H8: Bil | I8: % | J8: Bil | K8: % | L8: Bil | M8: % | N8: Bil | O8: % | P8: Bil | Q8: % | R8: Bil | S8: % | T8: Bil | U8: % | V8: Bil | W8: % | X8: Bil | Y8: % | Z8: Bil | AA8: % | AB8: Bil | AC8: % | AD8: Bil | AE8: % | AF8: Bil | AG8: % | AH8: Bil | AI8: % | AJ8: Bil | AK8: % | AL8: Bil | AM8: %
B9: 1 | C9: M - MELAYU | D9: 508 | E9: 49.56 | F9: 517 | G9: 50.44 | H9: 1025 | I9: 4.21 | J9: 1061 | K9: 50.64 | L9: 1034 | M9: 49.36 | N9: 2095 | O9: 8.61 | P9: 5293 | Q9: 49.84 | R9: 5328 | S9: 50.16 | T9: 10621 | U9: 43.67 | V9: 2850 | W9: 46.74 | X9: 3247 | Y9: 53.26 | Z9: 6097 | AA9: 25.07 | AB9: 2050 | AC9: 45.72 | AD9: 2434 | AE9: 54.28 | AF9: 4484 | AG9: 18.44 | AH9: 0 | AI9: 0 | AJ9: 0 | AK9: 0 | AL9: 0 | AM9: 0 | AN9: 24322
B10: 2 | C10: C - CINA | D10: 74 | E10: 55.64 | F10: 59 | G10: 44.36 | H10: 133 | I10: 3.46 | J10: 172 | K10: 55.13 | L10: 140 | M10: 44.87 | N10: 312 | O10: 8.11 | P10: 605 | Q10: 52.07 | R10: 557 | S10: 47.93 | T10: 1162 | U10: 30.22 | V10: 715 | W10: 57.11 | X10: 537 | Y10: 42.89 | Z10: 1252 | AA10: 32.56 | AB10: 479 | AC10: 48.58 | AD10: 507 | AE10: 51.42 | AF10: 986 | AG10: 25.64 | AH10: 0 | AI10: 0 | AJ10: 0 | AK10: 0 | AL10: 0 | AM10: 0 | AN10: 3845
B11: 3 | C11: I - INDIA | D11: 45 | E11: 48.39 | F11: 48 | G11: 51.61 | H11: 93 | I11: 3.83 | J11: 109 | K11: 49.77 | L11: 110 | M11: 50.23 | N11: 219 | O11: 9.03 | P11: 445 | Q11: 49.17 | R11: 460 | S11: 50.83 | T11: 905 | U11: 37.3 | V11: 344 | W11: 46.87 | X11: 390 | Y11: 53.13 | Z11: 734 | AA11: 30.26 | AB11: 199 | AC11: 41.89 | AD11: 276 | AE11: 58.11 | AF11: 475 | AG11: 19.58 | AH11: 0 | AI11: 0 | AJ11: 0 | AK11: 0 | AL11: 0 | AM11: 0 | AN11: 2426
B12: 4 | C12: L - LAIN-LAIN | D12: 0 | E12: 0 | F12: 0 | G12: 0 | H12: 0 | I12: 0 | J12: 0 | K12: 0 | L12: 0 | M12: 0 | N12: 0 | O12: 0 | P12: 0 | Q12: 0 | R12: 0 | S12: 0 | T12: 0 | U12: 0 | V12: 0 | W12: 0 | X12: 0 | Y12: 0 | Z12: 0 | AA12: 0 | AB12: 0 | AC12: 0 | AD12: 0 | AE12: 0 | AF12: 0 | AG12: 0 | AH12: 0 | AI12: 0 | AJ12: 0 | AK12: 0 | AL12: 0 | AM12: 0 | AN12: 0
B13: Jumlah | D13: 627 | E13: 50.12 | F13: 624 | G13: 49.88 | H13: 1251 | I13: 4.09 | J13: 1342 | K13: 51.1 | L13: 1284 | M13: 48.9 | N13: 2626 | O13: 8.58 | P13: 6343 | Q13: 49.99 | R13: 6345 | S13: 50.01 | T13: 12688 | U13: 41.47 | V13: 3909 | W13: 48.36 | X13: 4174 | Y13: 51.64 | Z13: 8083 | AA13: 26.42 | AB13: 2728 | AC13: 45.89 | AD13: 3217 | AE13: 54.11 | AF13: 5945 | AG13: 19.43 | AH13: 0 | AI13: 0 | AJ13: 0 | AK13: 0 | AL13: 0 | AM13: 0 | AN13: 30593
B16: Negeri | C16: : | D16: 05 - NEGERI SEMBILAN
B17: Parlimen | C17: : | D17: 127 - JEMPOL
B18: DUN | C18: : | D18: 06 - PALONG
B19: Umur Pada | C19: : | D19: 46184
B20: Bil. | C20: Bangsa | D20: 18-20 Thn | J20: 21-25 Thn | P20: 26-40 Thn | V20: 41-60 Thn | AB20: 61-999 Thn | AH20: Tak Diketahui | AN20: Jumlah
D21: Lelaki | F21: Wanita | H21: Jumlah | J21: Lelaki | L21: Wanita | N21: Jumlah | P21: Lelaki | R21: Wanita | T21: Jumlah | V21: Lelaki | X21: Wanita | Z21: Jumlah | AB21: Lelaki | AD21: Wanita | AF21: Jumlah | AH21: Lelaki | AJ21: Wanita | AL21: Jumlah
D22: Bil | E22: % | F22: Bil | G22: % | H22: Bil | I22: % | J22: Bil | K22: % | L22: Bil | M22: % | N22: Bil | O22: % | P22: Bil | Q22: % | R22: Bil | S22: % | T22: Bil | U22: % | V22: Bil | W22: % | X22: Bil | Y22: % | Z22: Bil | AA22: % | AB22: Bil | AC22: % | AD22: Bil | AE22: % | AF22: Bil | AG22: % | AH22: Bil | AI22: % | AJ22: Bil | AK22: % | AL22: Bil | AM22: %
B23: 1 | C23: M - MELAYU | D23: 423 | E23: 51.59 | F23: 397 | G23: 48.41 | H23: 820 | I23: 3.75 | J23: 719 | K23: 50.39 | L23: 708 | M23: 49.61 | N23: 1427 | O23: 6.52 | P23: 4179 | Q23: 49.76 | R23: 4219 | S23: 50.24 | T23: 8398 | U23: 38.36 | V23: 3297 | W23: 50.45 | X23: 3238 | Y23: 49.55 | Z23: 6535 | AA23: 29.85 | AB23: 2002 | AC23: 42.5 | AD23: 2709 | AE23: 57.5 | AF23: 4711 | AG23: 21.52 | AH23: 0 | AI23: 0 | AJ23: 0 | AK23: 0 | AL23: 0 | AM23: 0 | AN23: 21891
B24: 2 | C24: C - CINA | D24: 23 | E24: 63.89 | F24: 13 | G24: 36.11 | H24: 36 | I24: 7.95 | J24: 28 | K24: 50 | L24: 28 | M24: 50 | N24: 56 | O24: 12.36 | P24: 44 | Q24: 47.31 | R24: 49 | S24: 52.69 | T24: 93 | U24: 20.53 | V24: 97 | W24: 62.58 | X24: 58 | Y24: 37.42 | Z24: 155 | AA24: 34.22 | AB24: 42 | AC24: 37.17 | AD24: 71 | AE24: 62.83 | AF24: 113 | AG24: 24.94 | AH24: 0 | AI24: 0 | AJ24: 0 | AK24: 0 | AL24: 0 | AM24: 0 | AN24: 453
B25: 3 | C25: I - INDIA | D25: 28 | E25: 50 | F25: 28 | G25: 50 | H25: 56 | I25: 4.65 | J25: 47 | K25: 42.34 | L25: 64 | M25: 57.66 | N25: 111 | O25: 9.22 | P25: 164 | Q25: 50.93 | R25: 158 | S25: 49.07 | T25: 322 | U25: 26.74 | V25: 215 | W25: 47.78 | X25: 235 | Y25: 52.22 | Z25: 450 | AA25: 37.38 | AB25: 88 | AC25: 33.21 | AD25: 177 | AE25: 66.79 | AF25: 265 | AG25: 22.01 | AH25: 0 | AI25: 0 | AJ25: 0 | AK25: 0 | AL25: 0 | AM25: 0 | AN25: 1204
B26: 4 | C26: L - LAIN-LAIN | D26: 0 | E26: 0 | F26: 0 | G26: 0 | H26: 0 | I26: 0 | J26: 0 | K26: 0 | L26: 0 | M26: 0 | N26: 0 | O26: 0 | P26: 0 | Q26: 0 | R26: 0 | S26: 0 | T26: 0 | U26: 0 | V26: 0 | W26: 0 | X26: 0 | Y26: 0 | Z26: 0 | AA26: 0 | AB26: 0 | AC26: 0 | AD26: 0 | AE26: 0 | AF26: 0 | AG26: 0 | AH26: 0 | AI26: 0 | AJ26: 0 | AK26: 0 | AL26: 0 | AM26: 0 | AN26: 0
B27: Jumlah | D27: 474 | E27: 51.97 | F27: 438 | G27: 48.03 | H27: 912 | I27: 3.87 | J27: 794 | K27: 49.81 | L27: 800 | M27: 50.19 | N27: 1594 | O27: 6.77 | P27: 4387 | Q27: 49.78 | R27: 4426 | S27: 50.22 | T27: 8813 | U27: 37.43 | V27: 3609 | W27: 50.55 | X27: 3531 | Y27: 49.45 | Z27: 7140 | AA27: 30.32 | AB27: 2132 | AC27: 41.89 | AD27: 2957 | AE27: 58.11 | AF27: 5089 | AG27: 21.61 | AH27: 0 | AI27: 0 | AJ27: 0 | AK27: 0 | AL27: 0 | AM27: 0 | AN27: 23548
B30: Negeri | C30: : | D30: 05 - NEGERI SEMBILAN
B31: Parlimen | C31: : | D31: 127 - JEMPOL
B32: DUN | C32: : | D32: 07 - JERAM PADANG
B33: Umur Pada | C33: : | D33: 46184
B34: Bil. | C34: Bangsa | D34: 18-20 Thn | J34: 21-25 Thn | P34: 26-40 Thn | V34: 41-60 Thn | AB34: 61-999 Thn | AH34: Tak Diketahui | AN34: Jumlah
D35: Lelaki | F35: Wanita | H35: Jumlah | J35: Lelaki | L35: Wanita | N35: Jumlah | P35: Lelaki | R35: Wanita | T35: Jumlah | V35: Lelaki | X35: Wanita | Z35: Jumlah | AB35: Lelaki | AD35: Wanita | AF35: Jumlah | AH35: Lelaki | AJ35: Wanita | AL35: Jumlah
D36: Bil | E36: % | F36: Bil | G36: % | H36: Bil | I36: % | J36: Bil | K36: % | L36: Bil | M36: % | N36: Bil | O36: % | P36: Bil | Q36: % | R36: Bil | S36: % | T36: Bil | U36: % | V36: Bil | W36: % | X36: Bil | Y36: % | Z36: Bil | AA36: % | AB36: Bil | AC36: % | AD36: Bil | AE36: % | AF36: Bil | AG36: % | AH36: Bil | AI36: % | AJ36: Bil | AK36: % | AL36: Bil | AM36: %
B37: 1 | C37: M - MELAYU | D37: 267 | E37: 49.17 | F37: 276 | G37: 50.83 | H37: 543 | I37: 5.7 | J37: 497 | K37: 49.4 | L37: 509 | M37: 50.6 | N37: 1006 | O37: 10.57 | P37: 1549 | Q37: 48.63 | R37: 1636 | S37: 51.37 | T37: 3185 | U37: 33.46 | V37: 1552 | W37: 48.42 | X37: 1653 | Y37: 51.58 | Z37: 3205 | AA37: 33.67 | AB37: 702 | AC37: 44.46 | AD37: 877 | AE37: 55.54 | AF37: 1579 | AG37: 16.59 | AH37: 0 | AI37: 0 | AJ37: 0 | AK37: 0 | AL37: 0 | AM37: 0 | AN37: 9518
B38: 2 | C38: C - CINA | D38: 52 | E38: 55.91 | F38: 41 | G38: 44.09 | H38: 93 | I38: 5.48 | J38: 84 | K38: 46.93 | L38: 95 | M38: 53.07 | N38: 179 | O38: 10.55 | P38: 220 | Q38: 52.51 | R38: 199 | S38: 47.49 | T38: 419 | U38: 24.71 | V38: 302 | W38: 56.34 | X38: 234 | Y38: 43.66 | Z38: 536 | AA38: 31.6 | AB38: 210 | AC38: 44.78 | AD38: 259 | AE38: 55.22 | AF38: 469 | AG38: 27.65 | AH38: 0 | AI38: 0 | AJ38: 0 | AK38: 0 | AL38: 0 | AM38: 0 | AN38: 1696
B39: 3 | C39: I - INDIA | D39: 138 | E39: 55.65 | F39: 110 | G39: 44.35 | H39: 248 | I39: 4.66 | J39: 246 | K39: 50 | L39: 246 | M39: 50 | N39: 492 | O39: 9.24 | P39: 846 | Q39: 50.54 | R39: 828 | S39: 49.46 | T39: 1674 | U39: 31.44 | V39: 841 | W39: 46.93 | X39: 951 | Y39: 53.07 | Z39: 1792 | AA39: 33.66 | AB39: 432 | AC39: 38.64 | AD39: 686 | AE39: 61.36 | AF39: 1118 | AG39: 21 | AH39: 0 | AI39: 0 | AJ39: 0 | AK39: 0 | AL39: 0 | AM39: 0 | AN39: 5324
B40: 4 | C40: L - LAIN-LAIN | D40: 0 | E40: 0 | F40: 0 | G40: 0 | H40: 0 | I40: 0 | J40: 0 | K40: 0 | L40: 0 | M40: 0 | N40: 0 | O40: 0 | P40: 0 | Q40: 0 | R40: 0 | S40: 0 | T40: 0 | U40: 0 | V40: 0 | W40: 0 | X40: 1 | Y40: 100 | Z40: 1 | AA40: 100 | AB40: 0 | AC40: 0 | AD40: 0 | AE40: 0 | AF40: 0 | AG40: 0 | AH40: 0 | AI40: 0 | AJ40: 0 | AK40: 0 | AL40: 0 | AM40: 0 | AN40: 1
B41: Jumlah | D41: 457 | E41: 51.7 | F41: 427 | G41: 48.3 | H41: 884 | I41: 5.34 | J41: 827 | K41: 49.31 | L41: 850 | M41: 50.69 | N41: 1677 | O41: 10.14 | P41: 2615 | Q41: 49.55 | R41: 2663 | S41: 50.45 | T41: 5278 | U41: 31.91 | V41: 2695 | W41: 48.7 | X41: 2839 | Y41: 51.3 | Z41: 5534 | AA41: 33.46 | AB41: 1344 | AC41: 42.45 | AD41: 1822 | AE41: 57.55 | AF41: 3166 | AG41: 19.14 | AH41: 0 | AI41: 0 | AJ41: 0 | AK41: 0 | AL41: 0 | AM41: 0 | AN41: 16539
B44: Negeri | C44: : | D44: 05 - NEGERI SEMBILAN
B45: Parlimen | C45: : | D45: 127 - JEMPOL
B46: DUN | C46: : | D46: 08 - BAHAU
B47: Umur Pada | C47: : | D47: 46184
...

Sheet Seremban
B2: Negeri | C2: : | D2: 05 - NEGERI SEMBILAN
B3: Parlimen | C3: : | D3: 128 - SEREMBAN
B4: DUN | C4: : | D4: 09 - LENGGENG
B5: Umur Pada | C5: : | D5: 46184
B6: Bil. | C6: Bangsa | D6: 18-20 Thn | J6: 21-25 Thn | P6: 26-40 Thn | V6: 41-60 Thn | AB6: 61-999 Thn | AH6: Tak Diketahui | AN6: Jumlah
D7: Lelaki | F7: Wanita | H7: Jumlah | J7: Lelaki | L7: Wanita | N7: Jumlah | P7: Lelaki | R7: Wanita | T7: Jumlah | V7: Lelaki | X7: Wanita | Z7: Jumlah | AB7: Lelaki | AD7: Wanita | AF7: Jumlah | AH7: Lelaki | AJ7: Wanita | AL7: Jumlah
D8: Bil | E8: % | F8: Bil | G8: % | H8: Bil | I8: % | J8: Bil | K8: % | L8: Bil | M8: % | N8: Bil | O8: % | P8: Bil | Q8: % | R8: Bil | S8: % | T8: Bil | U8: % | V8: Bil | W8: % | X8: Bil | Y8: % | Z8: Bil | AA8: % | AB8: Bil | AC8: % | AD8: Bil | AE8: % | AF8: Bil | AG8: % | AH8: Bil | AI8: % | AJ8: Bil | AK8: % | AL8: Bil | AM8: %
B9: 1 | C9: M - MELAYU | D9: 624 | E9: 50.53 | F9: 611 | G9: 49.47 | H9: 1235 | I9: 5.41 | J9: 1390 | K9: 50.18 | L9: 1380 | M9: 49.82 | N9: 2770 | O9: 12.14 | P9: 4197 | Q9: 49.9 | R9: 4213 | S9: 50.1 | T9: 8410 | U9: 36.86 | V9: 3076 | W9: 47.62 | X9: 3384 | Y9: 52.38 | Z9: 6460 | AA9: 28.32 | AB9: 1843 | AC9: 46.79 | AD9: 2096 | AE9: 53.21 | AF9: 3939 | AG9: 17.27 | AH9: 0 | AI9: 0 | AJ9: 0 | AK9: 0 | AL9: 0 | AM9: 0 | AN9: 22814
B10: 2 | C10: C - CINA | D10: 88 | E10: 50 | F10: 88 | G10: 50 | H10: 176 | I10: 3.95 | J10: 189 | K10: 49.22 | L10: 195 | M10: 50.78 | N10: 384 | O10: 8.62 | P10: 636 | Q10: 54.5 | R10: 531 | S10: 45.5 | T10: 1167 | U10: 26.18 | V10: 843 | W10: 53.39 | X10: 736 | Y10: 46.61 | Z10: 1579 | AA10: 35.43 | AB10: 556 | AC10: 48.31 | AD10: 595 | AE10: 51.69 | AF10: 1151 | AG10: 25.82 | AH10: 0 | AI10: 0 | AJ10: 0 | AK10: 0 | AL10: 0 | AM10: 0 | AN10: 4457
B11: 3 | C11: I - INDIA | D11: 30 | E11: 53.57 | F11: 26 | G11: 46.43 | H11: 56 | I11: 4 | J11: 53 | K11: 46.09 | L11: 62 | M11: 53.91 | N11: 115 | O11: 8.21 | P11: 197 | Q11: 48.05 | R11: 213 | S11: 51.95 | T11: 410 | U11: 29.29 | V11: 234 | W11: 47.66 | X11: 257 | Y11: 52.34 | Z11: 491 | AA11: 35.07 | AB11: 146 | AC11: 44.51 | AD11: 182 | AE11: 55.49 | AF11: 328 | AG11: 23.43 | AH11: 0 | AI11: 0 | AJ11: 0 | AK11: 0 | AL11: 0 | AM11: 0 | AN11: 1400
B12: 4 | C12: L - LAIN-LAIN | D12: 0 | E12: 0 | F12: 0 | G12: 0 | H12: 0 | I12: 0 | J12: 0 | K12: 0 | L12: 0 | M12: 0 | N12: 0 | O12: 0 | P12: 0 | Q12: 0 | R12: 0 | S12: 0 | T12: 0 | U12: 0 | V12: 0 | W12: 0 | X12: 0 | Y12: 0 | Z12: 0 | AA12: 0 | AB12: 0 | AC12: 0 | AD12: 0 | AE12: 0 | AF12: 0 | AG12: 0 | AH12: 0 | AI12: 0 | AJ12: 0 | AK12: 0 | AL12: 0 | AM12: 0 | AN12: 0
B13: Jumlah | D13: 742 | E13: 50.58 | F13: 725 | G13: 49.42 | H13: 1467 | I13: 5.12 | J13: 1632 | K13: 49.92 | L13: 1637 | M13: 50.08 | N13: 3269 | O13: 11.4 | P13: 5030 | Q13: 50.37 | R13: 4957 | S13: 49.63 | T13: 9987 | U13: 34.83 | V13: 4153 | W13: 48.69 | X13: 4377 | Y13: 51.31 | Z13: 8530 | AA13: 29.75 | AB13: 2545 | AC13: 46.97 | AD13: 2873 | AE13: 53.03 | AF13: 5418 | AG13: 18.9 | AH13: 0 | AI13: 0 | AJ13: 0 | AK13: 0 | AL13: 0 | AM13: 0 | AN13: 28671
B16: Negeri | C16: : | D16: 05 - NEGERI SEMBILAN
B17: Parlimen | C17: : | D17: 128 - SEREMBAN
B18: DUN | C18: : | D18: 10 - NILAI
B19: Umur Pada | C19: : | D19: 46184
B20: Bil. | C20: Bangsa | D20: 18-20 Thn | J20: 21-25 Thn | P20: 26-40 Thn | V20: 41-60 Thn | AB20: 61-999 Thn | AH20: Tak Diketahui | AN20: Jumlah
D21: Lelaki | F21: Wanita | H21: Jumlah | J21: Lelaki | L21: Wanita | N21: Jumlah | P21: Lelaki | R21: Wanita | T21: Jumlah | V21: Lelaki | X21: Wanita | Z21: Jumlah | AB21: Lelaki | AD21: Wanita | AF21: Jumlah | AH21: Lelaki | AJ21: Wanita | AL21: Jumlah
D22: Bil | E22: % | F22: Bil | G22: % | H22: Bil | I22: % | J22: Bil | K22: % | L22: Bil | M22: % | N22: Bil | O22: % | P22: Bil | Q22: % | R22: Bil | S22: % | T22: Bil | U22: % | V22: Bil | W22: % | X22: Bil | Y22: % | Z22: Bil | AA22: % | AB22: Bil | AC22: % | AD22: Bil | AE22: % | AF22: Bil | AG22: % | AH22: Bil | AI22: % | AJ22: Bil | AK22: % | AL22: Bil | AM22: %
B23: 1 | C23: M - MELAYU | D23: 1252 | E23: 51.8 | F23: 1165 | G23: 48.2 | H23: 2417 | I23: 10.88 | J23: 2185 | K23: 52.5 | L23: 1977 | M23: 47.5 | N23: 4162 | O23: 18.74 | P23: 4082 | Q23: 51.22 | R23: 3887 | S23: 48.78 | T23: 7969 | U23: 35.88 | V23: 2844 | W23: 50.22 | X23: 2819 | Y23: 49.78 | Z23: 5663 | AA23: 25.49 | AB23: 997 | AC23: 49.8 | AD23: 1005 | AE23: 50.2 | AF23: 2002 | AG23: 9.01 | AH23: 0 | AI23: 0 | AJ23: 0 | AK23: 0 | AL23: 0 | AM23: 0 | AN23: 22213
B24: 2 | C24: C - CINA | D24: 381 | E24: 54.04 | F24: 324 | G24: 45.96 | H24: 705 | I24: 4.91 | J24: 681 | K24: 50.78 | L24: 660 | M24: 49.22 | N24: 1341 | O24: 9.34 | P24: 1997 | Q24: 53.07 | R24: 1766 | S24: 46.93 | T24: 3763 | U24: 26.22 | V24: 2626 | W24: 52.06 | X24: 2418 | Y24: 47.94 | Z24: 5044 | AA24: 35.15 | AB24: 1727 | AC24: 49.39 | AD24: 1770 | AE24: 50.61 | AF24: 3497 | AG24: 24.37 | AH24: 0 | AI24: 0 | AJ24: 0 | AK24: 0 | AL24: 0 | AM24: 0 | AN24: 14350
B25: 3 | C25: I - INDIA | D25: 269 | E25: 52.44 | F25: 244 | G25: 47.56 | H25: 513 | I25: 5.75 | J25: 552 | K25: 51.21 | L25: 526 | M25: 48.79 | N25: 1078 | O25: 12.09 | P25: 1481 | Q25: 48.59 | R25: 1567 | S25: 51.41 | T25: 3048 | U25: 34.18 | V25: 1456 | W25: 48.86 | X25: 1524 | Y25: 51.14 | Z25: 2980 | AA25: 33.42 | AB25: 574 | AC25: 44.19 | AD25: 725 | AE25: 55.81 | AF25: 1299 | AG25: 14.57 | AH25: 0 | AI25: 0 | AJ25: 0 | AK25: 0 | AL25: 0 | AM25: 0 | AN25: 8918
B26: 4 | C26: L - LAIN-LAIN | D26: 0 | E26: 0 | F26: 0 | G26: 0 | H26: 0 | I26: 0 | J26: 1 | K26: 100 | L26: 0 | M26: 0 | N26: 1 | O26: 16.67 | P26: 2 | Q26: 66.67 | R26: 1 | S26: 33.33 | T26: 3 | U26: 50 | V26: 0 | W26: 0 | X26: 1 | Y26: 100 | Z26: 1 | AA26: 16.67 | AB26: 0 | AC26: 0 | AD26: 1 | AE26: 100 | AF26: 1 | AG26: 16.67 | AH26: 0 | AI26: 0 | AJ26: 0 | AK26: 0 | AL26: 0 | AM26: 0 | AN26: 6
B27: Jumlah | D27: 1902 | E27: 52.32 | F27: 1733 | G27: 47.68 | H27: 3635 | I27: 7.99 | J27: 3419 | K27: 51.94 | L27: 3163 | M27: 48.06 | N27: 6582 | O27: 14.47 | P27: 7562 | Q27: 51.15 | R27: 7221 | S27: 48.85 | T27: 14783 | U27: 32.5 | V27: 6926 | W27: 50.6 | X27: 6762 | Y27: 49.4 | Z27: 13688 | AA27: 30.09 | AB27: 3298 | AC27: 48.51 | AD27: 3501 | AE27: 51.49 | AF27: 6799 | AG27: 14.95 | AH27: 0 | AI27: 0 | AJ27: 0 | AK27: 0 | AL27: 0 | AM27: 0 | AN27: 45487
B30: Negeri | C30: : | D30: 05 - NEGERI SEMBILAN
B31: Parlimen | C31: : | D31: 128 - SEREMBAN
B32: DUN | C32: : | D32: 11 - LOBAK
B33: Umur Pada | C33: : | D33: 46184
B34: Bil. | C34: Bangsa | D34: 18-20 Thn | J34: 21-25 Thn | P34: 26-40 Thn | V34: 41-60 Thn | AB34: 61-999 Thn | AH34: Tak Diketahui | AN34: Jumlah
D35: Lelaki | F35: Wanita | H35: Jumlah | J35: Lelaki | L35: Wanita | N35: Jumlah | P35: Lelaki | R35: Wanita | T35: Jumlah | V35: Lelaki | X35: Wanita | Z35: Jumlah | AB35: Lelaki | AD35: Wanita | AF35: Jumlah | AH35: Lelaki | AJ35: Wanita | AL35: Jumlah
D36: Bil | E36: % | F36: Bil | G36: % | H36: Bil | I36: % | J36: Bil | K36: % | L36: Bil | M36: % | N36: Bil | O36: % | P36: Bil | Q36: % | R36: Bil | S36: % | T36: Bil | U36: % | V36: Bil | W36: % | X36: Bil | Y36: % | Z36: Bil | AA36: % | AB36: Bil | AC36: % | AD36: Bil | AE36: % | AF36: Bil | AG36: % | AH36: Bil | AI36: % | AJ36: Bil | AK36: % | AL36: Bil | AM36: %
B37: 1 | C37: M - MELAYU | D37: 37 | E37: 49.33 | F37: 38 | G37: 50.67 | H37: 75 | I37: 4.82 | J37: 72 | K37: 43.64 | L37: 93 | M37: 56.36 | N37: 165 | O37: 10.61 | P37: 251 | Q37: 46.4 | R37: 290 | S37: 53.6 | T37: 541 | U37: 34.79 | V37: 258 | W37: 48.22 | X37: 277 | Y37: 51.78 | Z37: 535 | AA37: 34.41 | AB37: 107 | AC37: 44.77 | AD37: 132 | AE37: 55.23 | AF37: 239 | AG37: 15.37 | AH37: 0 | AI37: 0 | AJ37: 0 | AK37: 0 | AL37: 0 | AM37: 0 | AN37: 1555
B38: 2 | C38: C - CINA | D38: 223 | E38: 51.03 | F38: 214 | G38: 48.97 | H38: 437 | I38: 2.6 | J38: 482 | K38: 50.42 | L38: 474 | M38: 49.58 | N38: 956 | O38: 5.69 | P38: 1964 | Q38: 51.39 | R38: 1858 | S38: 48.61 | T38: 3822 | U38: 22.76 | V38: 2991 | W38: 51.4 | X38: 2828 | Y38: 48.6 | Z38: 5819 | AA38: 34.65 | AB38: 2524 | AC38: 43.83 | AD38: 3235 | AE38: 56.17 | AF38: 5759 | AG38: 34.29 | AH38: 0 | AI38: 0 | AJ38: 0 | AK38: 0 | AL38: 0 | AM38: 0 | AN38: 16793
B39: 3 | C39: I - INDIA | D39: 94 | E39: 49.21 | F39: 97 | G39: 50.79 | H39: 191 | I39: 3.99 | J39: 177 | K39: 47.71 | L39: 194 | M39: 52.29 | N39: 371 | O39: 7.75 | P39: 719 | Q39: 50.24 | R39: 712 | S39: 49.76 | T39: 1431 | U39: 29.88 | V39: 766 | W39: 44.69 | X39: 948 | Y39: 55.31 | Z39: 1714 | AA39: 35.79 | AB39: 431 | AC39: 39.83 | AD39: 651 | AE39: 60.17 | AF39: 1082 | AG39: 22.59 | AH39: 0 | AI39: 0 | AJ39: 0 | AK39: 0 | AL39: 0 | AM39: 0 | AN39: 4789
B40: 4 | C40: L - LAIN-LAIN | D40: 0 | E40: 0 | F40: 0 | G40: 0 | H40: 0 | I40: 0 | J40: 0 | K40: 0 | L40: 0 | M40: 0 | N40: 0 | O40: 0 | P40: 3 | Q40: 100 | R40: 0 | S40: 0 | T40: 3 | U40: 75 | V40: 0 | W40: 0 | X40: 1 | Y40: 100 | Z40: 1 | AA40: 25 | AB40: 0 | AC40: 0 | AD40: 0 | AE40: 0 | AF40: 0 | AG40: 0 | AH40: 0 | AI40: 0 | AJ40: 0 | AK40: 0 | AL40: 0 | AM40: 0 | AN40: 4
B41: Jumlah | D41: 354 | E41: 50.36 | F41: 349 | G41: 49.64 | H41: 703 | I41: 3.04 | J41: 731 | K41: 48.99 | L41: 761 | M41: 51.01 | N41: 1492 | O41: 6.45 | P41: 2937 | Q41: 50.66 | R41: 2860 | S41: 49.34 | T41: 5797 | U41: 25.05 | V41: 4015 | W41: 49.76 | X41: 4054 | Y41: 50.24 | Z41: 8069 | AA41: 34.87 | AB41: 3062 | AC41: 43.25 | AD41: 4018 | AE41: 56.75 | AF41: 7080 | AG41: 30.6 | AH41: 0 | AI41: 0 | AJ41: 0 | AK41: 0 | AL41: 0 | AM41: 0 | AN41: 23141
B44: Negeri | C44: : | D44: 05 - NEGERI SEMBILAN
B45: Parlimen | C45: : | D45: 128 - SEREMBAN
B46: DUN | C46: : | D46: 12 - TEMIANG
B47: Umur Pada | C47: : | D47: 46184
...

Sheet Kuala Pilah
B2: Negeri | C2: : | D2: 05 - NEGERI SEMBILAN
B3: Parlimen | C3: : | D3: 129 - KUALA PILAH
B4: DUN | C4: : | D4: 15 - JUASSEH
B5: Umur Pada | C5: : | D5: 46184
B6: Bil. | C6: Bangsa | D6: 18-20 Thn | J6: 21-25 Thn | P6: 26-40 Thn | V6: 41-60 Thn | AB6: 61-999 Thn | AH6: Tak Diketahui | AN6: Jumlah
D7: Lelaki | F7: Wanita | H7: Jumlah | J7: Lelaki | L7: Wanita | N7: Jumlah | P7: Lelaki | R7: Wanita | T7: Jumlah | V7: Lelaki | X7: Wanita | Z7: Jumlah | AB7: Lelaki | AD7: Wanita | AF7: Jumlah | AH7: Lelaki | AJ7: Wanita | AL7: Jumlah
D8: Bil | E8: % | F8: Bil | G8: % | H8: Bil | I8: % | J8: Bil | K8: % | L8: Bil | M8: % | N8: Bil | O8: % | P8: Bil | Q8: % | R8: Bil | S8: % | T8: Bil | U8: % | V8: Bil | W8: % | X8: Bil | Y8: % | Z8: Bil | AA8: % | AB8: Bil | AC8: % | AD8: Bil | AE8: % | AF8: Bil | AG8: % | AH8: Bil | AI8: % | AJ8: Bil | AK8: % | AL8: Bil | AM8: %
